Workbook

Sheet MT QUESTIONS
B2: 165 RANDOLPH - QUESTIONS ON THE 16 SEP MASTER DEVELOPMENT BUDGET
B3: Matthew Teper, 17 Sep 2026. Every question is written beside the line it refers to, in a new right-hand column on each of your sheets. Highlighted cells are the ones asked about. None of your cells have been changed.
B5: WHERE THE NUMBERS STAND
B6: Master Development Budget, 16 Sep | C6: 89084591 | D6: $1,202/SF on 74,100 SF; your sheet shows $655/SF on 135,953
B7: Our V3, rebuilt on the measured RFEM steel | C7: 77897555 | D7: $1,051/SF. Same programme, 997.2 short tons priced by the ton
B8: Yours after the corrections that survive the takeoff | C8: 77247828 | D8: 0.8% from ours
B9: Trade cost reconciliation, our extract vs your D25 | C9: 0 | D9: 309 lines, variance $0.00
B11: THE FIVE WE NEED FIRST
B12: -1. | C12: Budget Summary D67 - the contingency formula is 10% of the whole project, not of soft costs and FF&E as labelled.
B13: 0. | C13: Budget Summary D30 - escalation on the building is blank.
B14: 1. | C14: Budget Summary D26 - what is in the $12,000,000 and when is it priced? We expect it to go UP.
B15: 2. | C15: General Conditions tab vs Breakdown division 013000 - the same function in two places, $6,175,000 combined.
B16: 3. | C16: Breakdown 015800-1 - the $4,000,000 lump vs the $2,589,800 of backup beneath it.
B18: TWO THINGS WE HAD WRONG AND ARE WITHDRAWING
C19: The roof: we had assumed a lift. The RFEM model is a rebuild - 62.4% of column steel starts at grade, all 517 truss members are new at +56.5 to +64.5 ft. Your 74,000 SF of roof demolition is the method, not an error.
C20: The area: we had called 135,953 SF wrong. We can no longer prove that - the model carries 146,508 SF gross. We are now only asking where the number comes from, and for one agreed area schedule derived from the test fit.
B22: INDEX OF EVERY QUESTION
B23: Sheet | C23: Cell | D23: Your line | E23: Our question
B24: Budget Summary | C24: D21 | D24: Parking Garage - 260/spaces | E24: Formula is =86*25000 but the label says 260 spaces. Which is right? And is off-site parking in this deal at all? We carry none.
B25: Budget Summary | C25: D26 | D25: Trade Costs To Be Priced | E25: What scope is inside the $12,000,000, and when can it be priced? Our measured structure alone is $16,710,249 (997.2 short tons off the RFEM takeoff), and this plug also has to cover millwork, doors, glazing, tile, fireproofing and drywall. We expect it to go UP when priced.
B26: Budget Summary | C26: D27 | D26: General Conditions | E26: $3,141,000 here PLUS $3,034,000 of division 013000 inside the trade cost = $6,175,000, 12.36% of trade. Schimenti ran 7.80% and 8.90% at 555 Johnson. Which is the one we are paying? We hold 8.5%.
B27: Budget Summary | C27: D28 | D27: OH&P 9% | E27: =SUM(D25:D27)*0.09 charges the 9% on trade + the $12M plug + general conditions. Fee on your own GC is $555,750; fee on unpriced scope is $1,080,000. Can the fee be a fixed dollar amount, and come off both?
B28: Budget Summary | C28: D29 | D28: Contractor Contingency 10% | E28: =SUM(D25:D28)*0.1 is 10% on a base that already holds the 9% OH&P. Intentional? We hold ONE owner contingency of $5,000,000 below the line.
B29: Budget Summary | C29: D30 | D29: Escalation | E29: Blank in all three versions of this file, while the parking garage gets 5% on D22. On a 20-month programme what should the building carry? We hold 10%.
B30: Budget Summary | C30: I31 | D30: $/SF | E30: I31 divides by 135,953. On the 74,100 SF footprint this is $859/SF.
B31: Budget Summary | C31: D45 | D31: Project Management (Live Nation) | E31: This is our own team, not Live Nation. Same $520,000 in our budget - just the label.
B32: Budget Summary | C32: D67 | D32: Soft Costs & FFE Contingency 10% | E32: Label says Soft Costs & FFE. Formula is =(D23+D31+D47+D65)*0.1 = 10% of the WHOLE PROJECT, on top of the contractor contingency already inside D31. As labelled it would be $1,507,723. $578,648 of it is contingency on contingency. Which is intended?
B33: Budget Summary | C33: D69 | D33: Total Capital | E33: Ours: V3 $77,897,555 on the same programme, measured steel. Apply only the corrections that survive the takeoff and this cell becomes about $77,247,828 - 0.8% from ours.
B34: Budget Summary | C34: D71 | D34: $ PER SF | E34: Divides by 135,953 SF. Where does that number come from? We cannot find a schedule or calculation behind it. On 74,100 SF this total is $1,202/SF. Both are true; please label which.
B35: Budget Summary | C35: B8 | D35: SF: 135,953 | E35: 135,953 SF appears here and in 6 formula cells. Source? The RFEM model has 146,508 SF gross / 120,119 SF enclosed floor; the test fit governs at 74,100 SF footprint. 555 Johnson at $208.63/SF is 134,993 SF - please rule that out.
B36: Budget Summary | C36: A9 | E36: Dated 7 Sep; the Breakdown tab says 16 Sep. Which is current?
B37: General Conditions | C37: E13 | E37: This tab is the best-evidenced page in the file and we would rather build on it than argue with it. Is the $3,141,000 the ONLY place general conditions lives? Division 013000 on the Breakdown carries site office, field tech, safety, toilets, protection, clean-up, rubbish and final clean for another $3,034,000.
B38: General Conditions | C38: C4 | E38: 90 weeks - is that construction only, or does it include pre-con and closeout? Can we see it as a rate x duration so that shortening the programme visibly shortens the cost?
B39: General Conditions | C39: C9 | E39: Three superintendents for the full 90 weeks each - all three for the whole period, or overlapping phases?
B40: Building & Fit-out Breakdown | C40: F23 | D40: Project Labor $2,000,000 | E40: Crew, rate and weeks? The General Conditions tab already funds three supers + a general super for 90 weeks. No quantity behind this line.
B41: Building & Fit-out Breakdown | C41: F16 | E41: What is included in Field Technology at $200,000?
B42: Building & Fit-out Breakdown | C42: F27 | D42: 013000 subtotal $3,034,000 | E42: All of this division reads as general conditions. Is it meant to sit inside trade cost AND under the GC line on the summary? We think it is one function in two places.
B43: Building & Fit-out Breakdown | C43: F30 | D43: Sidewalk bridge $4,000,000 | E43: The lump says $4,000,000. The two rows beneath it - 1,126 LF @ $500 and 27,024 SF @ $75 - foot to $2,589,800. Which is right? And how many LF of PUBLIC sidewalk does the building front? A shed is only required where there is one; the alleys and lot lines have none. We carry 1,089 LF perimeter x $210 erected + 24 months rental.
B44: Building & Fit-out Breakdown | C44: F33 | D44: Interior scaffolding $2,000,000 | E44: What is being staged, at what rate, for how many weeks? The high roof is only 8.65 lb/SF of short-span W12/W6 framing - not a heavy erection. And the ground-supported stage and production towers are erected FIRST; can they carry the access instead of renting it twice?
B45: Building & Fit-out Breakdown | C45: F58 | D45: Demo pre-cast roof 74,000 SF | E45: Confirms the REBUILD method, which the RFEM model also uses and which we now accept. Separate question: is the existing roof genuinely pre-cast concrete? It decides whether a PARTIAL lift over the 27,393 SF high-roof zone is even possible.
...

Sheet Budget Summary
A1: 165 Randolph St. Brooklyn NY
A2: Warehouse Conversion / Add Second Level & Roof Deck
A3: Theater GA Standing: 7,440
A4: Theater GA Seated: 5,954
A5: Eating & Drinking : 769
A6: VIP Lounge
A8: SF: | B8: 135, 953 | J8: =130000*600 | L8: 135,953 SF appears here and in 6 formula cells. Source? The RFEM model has 146,508 SF gross / 120,119 SF enclosed floor; the test fit governs at 74,100 SF footprint. 555 Johnson at $208.63/SF is 134,993 SF - please rule that out.
A9: 46272 | L9: Dated 7 Sep; the Breakdown tab says 16 Sep. Which is current?
A10: Version #: 1
A13: Construction Duration: 20 Months
A14: Expected Certificate of Occupancy: TBD
A15: Expected Frist Show:
A16: Project Completion:
D19: Budget Total | F19: 2023 | G19: 2024 | H19: 2025 | L19: OUR QUESTION / ANALYSIS (MT, 17 Sep)
A20: 000 | B20: OFF SITE COSTS
B21: Parking Garage - 260/spaces | D21: =86*25000 | F21: 0 | G21: 0 | H21: 0 | L21: Formula is =86*25000 but the label says 260 spaces. Which is right? And is off-site parking in this deal at all? We carry none.
B22: Escalation (Calculated at 5%) | D22: =D21*0.05 | F22: 0 | G22: 0 | H22: 0
D23: =SUM(D21:D22) | F23: 0 | G23: 0 | H23: 0
A24: 100 | B24: Building & Fit-Out Costs
B25: Trade Costs | D25: ='Building & Fit-outBudget Detail'!C49-'Building & Fit-outBudget Detail'!C47 | F25: 0 | G25: 0 | H25: 0
B26: Trade Costs To Be Priced | D26: 12000000 | L26: What scope is inside the $12,000,000, and when can it be priced? Our measured structure alone is $16,710,249 (997.2 short tons off the RFEM takeoff), and this plug also has to cover millwork, doors, glazing, tile, fireproofing and drywall. We expect it to go UP when priced.
B27: General Conditions and General Requirements | D27: 3141000 | F27: 0 | G27: 0 | H27: 0 | I27: 90 wks | L27: $3,141,000 here PLUS $3,034,000 of division 013000 inside the trade cost = $6,175,000, 12.36% of trade. Schimenti ran 7.80% and 8.90% at 555 Johnson. Which is the one we are paying? We hold 8.5%.
B28: Overhead, Profit & Insurance (9% Combined) | D28: =SUM(D25:D27)*0.09 | F28: 0 | G28: 0 | H28: 0 | L28: =SUM(D25:D27)*0.09 charges the 9% on trade + the $12M plug + general conditions. Fee on your own GC is $555,750; fee on unpriced scope is $1,080,000. Can the fee be a fixed dollar amount, and come off both?
B29: Contractor Contingency 10% | D29: =SUM(D25:D28)*0.1 | F29: 0 | G29: 0 | H29: 0 | L29: =SUM(D25:D28)*0.1 is 10% on a base that already holds the 9% OH&P. Intentional? We hold ONE owner contingency of $5,000,000 below the line.
B30: Escalation (Calculated at 5%) | F30: 0 | G30: 0 | H30: 0 | L30: Blank in all three versions of this file, while the parking garage gets 5% on D22. On a 20-month programme what should the building carry? We hold 10%.
D31: =SUM(D25:D30) | F31: 0 | G31: 0 | H31: 0 | I31: =D31/135953 | L31: I31 divides by 135,953. On the 74,100 SF footprint this is $859/SF.
A32: 200 | B32: Soft Costs
B33: Abatement | D33: ='Soft Cost & FF&E Budget Detail'!E16 | F33: 0 | G33: 0 | H33: 0
B34: Feasibility Study | D34: ='Soft Cost & FF&E Budget Detail'!E21
B35: Architectural / Engineering / Consultant Fees | D35: ='Soft Cost & FF&E Budget Detail'!E38 | F35: 0 | G35: 0 | H35: 0
B36: Site & Civil | D36: ='Soft Cost & FF&E Budget Detail'!E43 | F36: 0 | G36: 0 | H36: 0
B37: Traffic Engineering | D37: ='Soft Cost & FF&E Budget Detail'!E51
B38: Acousticsl Engineering | D38: ='Soft Cost & FF&E Budget Detail'!E58
B39: Geotechnical Engineering | D39: ='Soft Cost & FF&E Budget Detail'!E66
B40: Enviromental Studies | D40: ='Soft Cost & FF&E Budget Detail'!E71
B41: Zoning/Permit Fees | D41: ='Soft Cost & FF&E Budget Detail'!E82 | F41: 0 | G41: 0 | H41: 0
B42: Utility Connection Fees | D42: ='Soft Cost & FF&E Budget Detail'!E90
B43: Attorney Fees | D43: ='Soft Cost & FF&E Budget Detail'!E98
B44: Testing / Quality Control | D44: ='Soft Cost & FF&E Budget Detail'!E103 | F44: ='Soft Cost & FF&E Budget Detail'!E103 | G44: 0 | H44: 0
B45: Project Management (Live Nation) | D45: ='Soft Cost & FF&E Budget Detail'!E109 | F45: 0 | G45: 0 | H45: 0 | L45: This is our own team, not Live Nation. Same $520,000 in our budget - just the label.
...

Sheet Soft Cost & FF&E Budget Detail
A1: 165 Randolph St Brooklyn NY
A2: Scope : | B2: Warehouse Conversion / Add Second Level & Roof Decks
A3: Capacity: | B3: ##
A4: SF: | B4: 135953
A5: Date:
A6: Version: | B6: 1
A10: 200 | B10: SOFT COSTS
A11: 201 | B11: DESCRIPTION | C11: QTY | D11: UNIT PRICE | E11: BUDGET TOTAL | F11: NOTES | G11: OUR QUESTION / ANALYSIS (MT, 17 Sep)
B12: Abatement
A13: 1 | B13: Pipe Insulation Abatement | C13: 190 | D13: 72 | E13: =C13*D13
A14: 2 | B14: Roof Abatement | C14: 70000 | D14: 21 | E14: =C14*D14 | G14: 70,000 SF @ $21 = $1,470,000. Where does $21/SF come from, and has anyone SAMPLED the roof? No ACP-5 exists. We carry $7.50/SF. Also: this sits in soft costs; we carry abatement as a trade.
B16: Total Abatement | E16: =SUM(E13:E15)
A17: 202 | B17: DESCRIPTION | C17: QTY | D17: UNIT PRICE | E17: BUDGET TOTAL | F17: NOTES
B18: Feasibility Study
A19: 1 | B19: Due Diligence & Feasibility Study | C19: 1 | D19: 342000 | E19: =C19*D19
B21: Total Feasibility Study | E21: =E19
A22: 203 | B22: DESCRIPTION | C22: QTY | D22: UNIT PRICE | E22: BUDGET TOTAL | F22: NOTES
B23: Architectural Fees
A24: 1 | B24: Conceptual & Brand Development | C24: 1 | D24: 45000 | E24: =C24*D24
A25: =A24+1 | B25: Interior Design | C25: 1 | D25: 90000 | E25: =C25*D25
A26: =A25+1 | B26: Architecture & Engineering | C26: 1 | D26: 3100000 | E26: =C26*D26 | G26: One $3,100,000 lump with architecture, MEP and structural all 'carried in line #3'. Can it be split? We cannot tell whether structural is funded at the level the RFEM model needs.
A27: =A26+1 | B27: Architecture | D27: 0 | E27: =C27*D27 | F27: Carried in line #3
A28: =A27+1 | B28: MEP Engineering | D28: 0 | E28: =C28*D28 | F28: Carried in line #3
A29: =A28+1 | B29: Structural Engineering | D29: 0 | E29: =C29*D29 | F29: Carried in line #3
A30: =A29+1 | B30: MEP Consultant | C30: 1 | D30: 30000 | E30: =C30*D30
A31: =A30+1 | B31: Lighting Design (Bandit) | C31: 1 | D31: 51000 | E31: =C31*D31
A32: =A31+1 | B32: Kitchen Equipment Design (TriMark) | C32: 1 | D32: 20000 | E32: =C32*D32
A33: =A32+1 | B33: LV/AV Design | C33: 1 | D33: 35000 | E33: =C33*D33
A34: =A33+1 | B34: Signage & Way Finding Design | C34: 1 | D34: 75000 | E34: =C34*D34
A35: =A34+1 | B35: Renderings | C35: 1 | D35: 50000 | E35: =C35*D35
A36: =A35+1 | B36: Reimbursables | C36: 1 | D36: 30000 | E36: =C36*D36
B38: Total Architectural Fees | E38: =SUM(E24:E37)
A39: 204 | B39: DESCRIPTION | C39: QTY | D39: UNIT PRICE | E39: BUDGET TOTAL | F39: NOTES
B40: Civil Engineering
A41: 1 | B41: Civil Engineering | C41: 1 | D41: 10000 | E41: =C41*D41 | F41: Exterior work: New Sidewalks, Street Work
B43: Total Civil Engineering | E43: =SUM(E41:E41)
A44: 205 | B44: DESCRIPTION | C44: QTY | D44: UNIT PRICE | E44: BUDGET TOTAL | F44: NOTES
B45: Traffic Engineering
A46: 1 | B46: Traffic Engineering | C46: 1 | D46: 10000 | E46: =C46*D46 | F46: Verify w/ Traffic Consultant Report
A47: 2 | D47: 0 | E47: =C47*D47
...

Sheet Building & Fit-outBudget Detail
A1: Venue
A2: Scope : | B2: ='Soft Cost & FF&E Budget Detail'!B2
A3: Capacity: | B3: 7440
A4: SF: | B4: ='Soft Cost & FF&E Budget Detail'!B4
A5: Date: | B5: 46281
A6: Version: | B6: ='Soft Cost & FF&E Budget Detail'!B6
A9: 100 | B9: BUILDING & FIT-OUT COSTS
A10: CSI # | B10: TRADE | C10: BUDGET | D10: COST/SF | E10: NOTES | G10: OUR QUESTION / ANALYSIS (MT, 17 Sep)
A11: 013000 | B11: PROJECT REQUIREMENTS | C11: ='Building & Fit-out Breakdown'!F27 | D11: =C11/$B$4
A12: 015800 | B12: SCAFFOLDING & STAGING | C12: ='Building & Fit-out Breakdown'!F37 | D12: =C12/$B$4
A13: 024100 | B13: DEMOLITION | C13: ='Building & Fit-out Breakdown'!F63 | D13: =C13/$B$4
A14: 033000 | B14: CONCRETE | C14: ='Building & Fit-out Breakdown'!F93 | D14: =C14/$B$4
A15: 042000 | B15: MASONRY | C15: ='Building & Fit-out Breakdown'!F119 | D15: =C15/$B$4
A16: 044000 | B16: STONE & CERAMICS | C16: ='Building & Fit-out Breakdown'!F127 | D16: =C16/$B$4
A17: 055100 | B17: STRUCTURAL STEEL & MISC METALS | C17: ='Building & Fit-out Breakdown'!F151 | D17: =C17/$B$4
A18: 061000 | B18: ROUGH CARPENTRY | C18: ='Building & Fit-out Breakdown'!F160 | D18: =C18/$B$4
A19: 064000 | B19: MILLWORK AND FURNITURE INSTALL | C19: ='Building & Fit-out Breakdown'!F182 | D19: =C19/$B$4
A20: 075000 | B20: ROOFING | C20: ='Building & Fit-out Breakdown'!F196 | D20: =C20/$B$4
A21: 078100 | B21: FIREPROOFING | C21: ='Building & Fit-out Breakdown'!F204 | D21: =C21/$B$4
A22: 081000 | B22: DOORS, FRAMES & HARDWARE | C22: ='Building & Fit-out Breakdown'!F213 | D22: =C22/$B$4
A23: 083000 | B23: SPECIAL DOORS | C23: ='Building & Fit-out Breakdown'!F219 | D23: =C23/$B$4
A24: 084100 | B24: STOREFRONT | C24: ='Building & Fit-out Breakdown'!F229 | D24: =C24/$B$4
A25: 088000 | B25: GLASS/GLAZING | C25: ='Building & Fit-out Breakdown'!F237 | D25: =C25/$B$4
A26: 092000 | B26: DRYWALL | C26: ='Building & Fit-out Breakdown'!F270 | D26: =C26/$B$4
A27: 092300 | B27: TILE/BRICK TILE | C27: ='Building & Fit-out Breakdown'!F279 | D27: =C27/$B$4
A28: 096000 | B28: CARPET/RESILIENT FLOORING | C28: ='Building & Fit-out Breakdown'!F294 | D28: =C28/$B$4
A29: 096050 | B29: FLOOR PREPARATION | C29: ='Building & Fit-out Breakdown'!F302 | D29: =C29/$B$4
A30: 096400 | B30: WOOD FLOORING | C30: ='Building & Fit-out Breakdown'!F308 | D30: =C30/$B$4
A31: 099000 | B31: PAINTING/PLASTER | C31: ='Building & Fit-out Breakdown'!F316 | D31: =C31/$B$4
A32: 100000 | B32: SPECIALITIES | C32: ='Building & Fit-out Breakdown'!F328 | D32: =C32/$B$4
A33: 100500 | B33: ACOUSTICAL PANELS/K13 | C33: ='Building & Fit-out Breakdown'!F334 | D33: =C33/$B$4
A34: 101400 | B34: SIGNAGE | C34: ='Building & Fit-out Breakdown'!F341 | D34: =C34/$B$4
A35: 120000 | B35: FF&E INSTALL | C35: ='Building & Fit-out Breakdown'!F346 | D35: =C35/$B$4
A36: 114000 | B36: FOOD SERVICE AND BAR EQUIPMENT | C36: ='Building & Fit-out Breakdown'!F354 | D36: =C36/$B$4
A37: 142000 | B37: ELEVATOR | C37: ='Building & Fit-out Breakdown'!F361 | D37: =C37/$B$4
A38: 210000 | B38: FIRE PROTECTION | C38: ='Building & Fit-out Breakdown'!F371 | D38: =C38/$B$4
A39: 220000 | B39: PLUMBING | C39: ='Building & Fit-out Breakdown'!F412 | D39: =C39/$B$4
A40: 230000 | B40: HVAC | C40: ='Building & Fit-out Breakdown'!F417 | D40: =C40/$B$4
A41: 260000 | B41: ELECTRIC | C41: ='Building & Fit-out Breakdown'!F456 | D41: =C41/$B$4
A42: 270000 | B42: LOW VOLTAGE CABLING | C42: ='Building & Fit-out Breakdown'!F464 | D42: =C42/$B$4
...

Sheet Building & Fit-out Breakdown
A1: Venue
A2: Scope: | B2: ='Building & Fit-outBudget Detail'!B2
A3: Capacity: | B3: 7440
A4: SF: | B4: =3500+69722+53379+9352
A5: Date: | B5: ='Building & Fit-outBudget Detail'!B5
A6: Architect: | B6: Wake
A7: Version: | B7: ='Building & Fit-outBudget Detail'!B6
A10: ITEM | B10: DESCRIPTION | C10: QTY | D10: UNIT | E10: UNIT PRICE | F10: TOTAL | G10: NOTES | K10: OUR QUESTION / ANALYSIS (MT, 17 Sep)
A12: 013000 | B12: PROJECT REQUIREMENTS
A13: 1 | B13: BIM Set Up & Coordination | C13: 1 | D13: LS | E13: 30000 | F13: =C13*E13
A14: =A13+1 | B14: Plans / Reprographics | C14: 1 | D14: LS | E14: 7500 | F14: =C14*E14
A15: =A14+1 | B15: Site Office & Equipment | C15: 1 | D15: LS | E15: 12000 | F15: =C15*E15
A16: =A15+1 | B16: Field Techonology | C16: 1 | D16: LS | E16: 200000 | F16: =C16*E16 | K16: What is included in Field Technology at $200,000?
A17: =A16+1 | B17: Construction Signage | C17: 1 | D17: LS | E17: 4500 | F17: =C17*E17
A18: =A17+1 | B18: Site Security | C18: 1 | D18: LS | E18: 13000 | F18: =C18*E18
A19: =A18+1 | B19: Site Safety Plan / First Aid / TPP / FE's / Safety Inspector | C19: 1 | D19: LS | E19: 400000 | F19: =C19*E19
A20: =A19+1 | B20: Portable Toilets | C20: 80 | D20: WK | E20: 400 | F20: =C20*E20
A21: =A20+1 | B21: Clean up Materials | C21: 1 | D21: LS | E21: 65000 | F21: =C21*E21
A22: =A21+1 | B22: Protection Materials | C22: 1 | D22: LS | E22: 50000 | F22: =C22*E22
A23: =A22+1 | B23: Project Labor | C23: 1 | D23: LS | E23: 2000000 | F23: =C23*E23 | K23: Crew, rate and weeks? The General Conditions tab already funds three supers + a general super for 90 weeks. No quantity behind this line.
A24: =A23+1 | B24: Project Rubbish Removals | C24: 1 | D24: LS | E24: 120000 | F24: =C24*E24
A25: =A24+1 | B25: Final Clean | C25: 1 | D25: LS | E25: 100000 | F25: =C25*E25
A27: Sub Total | B27: =B12 | F27: =SUM(F11:F26) | K27: All of this division reads as general conditions. Is it meant to sit inside trade cost AND under the GC line on the summary? We think it is one function in two places.
A29: 015800 | B29: SCAFFOLDING & HOARDING
A30: 1 | B30: Install sidewalk bridge and scaffolding around building | C30: 1 | D30: LS | E30: 4000000 | F30: =E30*C30 | I30: 500/LF bridge | K30: The lump says $4,000,000. The two rows beneath it - 1,126 LF @ $500 and 27,024 SF @ $75 - foot to $2,589,800. Which is right? And how many LF of PUBLIC sidewalk does the building front? A shed is only required where there is one; the alleys and lot lines have none. We carry 1,089 LF perimeter x $210 erected + 24 months rental.
C31: 1126 | D31: LF | E31: 500
C32: =(1126*6)*4 | D32: SF | E32: 75
A33: 2 | B33: Interior scaffolding | C33: 1 | D33: LS | E33: 2000000 | F33: =E33*C33 | I33: $75/SF for scaffolding | K33: What is being staged, at what rate, for how many weeks? The high roof is only 8.65 lb/SF of short-span W12/W6 framing - not a heavy erection. And the ground-supported stage and production towers are erected FIRST; can they carry the access instead of renting it twice?
A34: 3 | B34: Barricades | C34: 1 | D34: LS | E34: 150000 | F34: =E34*C34
B35: Site safety During Erection | C35: 1 | D35: LS | E35: 20000 | F35: =E35*C35
A36: 4
A37: Sub Total | B37: =B29 | F37: =SUM(F28:F36)
A39: 024100 | B39: DEMOLITION
A40: 1 | B40: Demo existing CMU/masonry walls at new Entry/Lobby area | C40: 2500 | D40: SF | E40: 12 | F40: =C40*E40
A41: =A40+1 | B41: Demo 8" CMU interior wall 20' tall | C41: 1975 | D41: SF | E41: 12 | F41: =C41*E41
A42: =A41+1 | B42: Demo 8" CMU interior wall 12' tall | C42: =628*12 | D42: SF | E42: 12 | F42: =C42*E42
A43: =A42+1 | B43: Demo office area partitions, ceilings, doors, flooring MEP's, (CMU walls line above) | C43: 6825 | D43: SF | E43: 5 | F43: =C43*E43
A44: =A43+1 | B44: Demo existing exterior roll up doors | C44: 8 | D44: EA | E44: 5000 | F44: =C44*E44
A45: =A44+1 | B45: Demo existing exterior doors | C45: 7 | D45: EA | E45: 250 | F45: =C45*E45
A46: =A45+1 | B46: Demo existing windows 1'x10' | C46: 34 | D46: EA | E46: 300 | F46: =C46*E46
...

Sheet General Conditions
G2: OUR QUESTION / ANALYSIS (MT, 17 Sep)
B3: Exec | C3: 10 | D3: 9200 | E3: =C3*D3 | G3: This tab is the best-evidenced page in the file and we would rather build on it than argue with it. Is the $3,141,000 the ONLY place general conditions lives? Division 013000 on the Breakdown carries site office, field tech, safety, toilets, protection, clean-up, rubbish and final clean for another $3,034,000.
B4: PM | C4: 90 | D4: 6400 | E4: =C4*D4 | G4: 90 weeks - is that construction only, or does it include pre-con and closeout? Can we see it as a rate x duration so that shortening the programme visibly shortens the cost?
B5: APM | C5: 90 | D5: 4600 | E5: =C5*D5
B6: Engineer | C6: 90 | D6: 3900 | E6: =C6*D6
B7: Accoutnant | C7: 10 | D7: 2800 | E7: =C7*D7
E8: =C8*D8
B9: Super | C9: 90 | D9: 6000 | E9: =C9*D9 | G9: Three superintendents for the full 90 weeks each - all three for the whole period, or overlapping phases?
B10: Super | C10: 90 | D10: 6000 | E10: =C10*D10
B11: Super | C11: 90 | D11: 6000 | E11: =C11*D11
B12: General Super | C12: 10 | D12: 6000 | E12: =C12*D12
E13: =SUM(E3:E12)

Sheet Project At-a-Glance
B8: Cost Report Date: | C8: 44957 | F8: Venue Capacity: | G8: TBD
B9: Project Name: | F9: Landlord Work Start Date: | G9: TBD
B10: Location: | F10: LNE Work Start Date: | G10: TBD
B11: Address: | F11: Certificate of Occupancy: | G11: TBD
B12: Project Number: | F12: First Show Date: | G12: TBD
B13: Budget: | C13: =C25 | F13: Project Completion Date: | G13: TBD
B14: Venue EVP: | C14: TBD | F14: Project Manager: | G14: TBD
B17: Description | C17: Budget | D17: Committed Costs Total | E17: Costs to Date Total | F17: Remaining Estimate | G17: Estimated Final Cost | H17: Budget vs EFC Variance
B19: ='Project Detail'!D4 | C19: ='Project Summary '!C9 | D19: ='Project Summary '!D9 | E19: ='Project Summary '!E9 | F19: ='Project Summary '!F9 | G19: ='Project Summary '!G9 | H19: ='Project Summary '!H9
B20: ='Project Detail'!D33 | C20: ='Project Summary '!C15 | D20: ='Project Summary '!D15 | E20: ='Project Summary '!E15 | F20: ='Project Summary '!F15 | G20: ='Project Summary '!G15 | H20: ='Project Summary '!H15
B21: FF&E Costs | C21: ='Project Summary '!C27 | D21: ='Project Summary '!D27 | E21: ='Project Summary '!E27 | F21: ='Project Summary '!F27 | G21: ='Project Summary '!G27 | H21: ='Project Summary '!H27
B23: ='Project Summary '!B29 | C23: =SUM(C19:C21) | D23: =SUM(D19:D21) | E23: =SUM(E19:E21) | F23: =SUM(F19:F21) | G23: =SUM(G19:G21) | H23: =SUM(H19:H21)
B24: Total Contingency | C24: ='Project Summary '!C30 | F24: =Contingency!G9 | G24: =Contingency!G9 | H24: =C24-G24
B25: TOTAL | C25: =SUM(C23:C24) | D25: =SUM(D23:D24) | E25: =SUM(E23:E24) | F25: =SUM(F23:F24) | G25: =SUM(G23:G24) | H25: =SUM(H23:H24)
B28: Risk Summary
B29: Risk Report Total | D29: ='Risk Report'!G15
B30: Remaining Contingency | D30: ='Risk Report'!G19
B31: Exposure | D31: ='Risk Report'!G23
B32: Estimated Final Cost (Including Risk Items) | D32: =G25+D31

Sheet Project Summary 
B2: Description | C2: Budget | D2: Committed Costs | E2: Costs to Date | F2: Remaining Estimate | G2: Estimated Final Cost | H2: Budget vs EFC Variance
D3: Total | E3: Total
B4: ='Project Detail'!D4
B5: ='Project Detail'!D5 | C5: ='Project Detail'!F10 | D5: ='Project Detail'!G10 | E5: ='Project Detail'!K10 | F5: ='Project Detail'!L10 | G5: ='Project Detail'!M10 | H5: ='Project Detail'!N10
B6: ='Project Detail'!D11 | C6: ='Project Detail'!F16 | D6: ='Project Detail'!G16 | E6: ='Project Detail'!K16 | F6: ='Project Detail'!L16 | G6: ='Project Detail'!M16 | H6: ='Project Detail'!N16
B7: ='Project Detail'!D17 | C7: ='Project Detail'!F22 | D7: ='Project Detail'!G22 | E7: ='Project Detail'!K22 | F7: ='Project Detail'!L22 | G7: ='Project Detail'!M22 | H7: ='Project Detail'!N22
B8: ='Project Detail'!D23 | C8: ='Project Detail'!F28 | D8: ='Project Detail'!G28 | E8: ='Project Detail'!K28 | F8: ='Project Detail'!L28 | G8: ='Project Detail'!M28 | H8: ='Project Detail'!N28
B9: Building Costs Total | C9: =SUM(C5:C8) | D9: =SUM(D5:D8) | E9: =SUM(E5:E8) | F9: =SUM(F5:F8) | G9: =SUM(G5:G8) | H9: =SUM(H5:H8)
B11: ='Project Detail'!D33
B12: ='Project Detail'!D34 | C12: ='Project Detail'!F39 | D12: ='Project Detail'!G39 | E12: ='Project Detail'!K39 | F12: ='Project Detail'!L39 | G12: ='Project Detail'!M39 | H12: ='Project Detail'!N39
B13: ='Project Detail'!D40 | C13: ='Project Detail'!F45 | D13: ='Project Detail'!G45 | E13: ='Project Detail'!K45 | F13: ='Project Detail'!L45 | G13: ='Project Detail'!M45 | H13: ='Project Detail'!N45
B14: ='Project Detail'!D46 | C14: ='Project Detail'!F57 | D14: ='Project Detail'!G57 | E14: ='Project Detail'!K57 | F14: ='Project Detail'!L57 | G14: ='Project Detail'!M57 | H14: ='Project Detail'!N57
B15: Soft Costs Total | C15: =SUM(C12:C14) | D15: =SUM(D12:D14) | E15: =SUM(E12:E14) | F15: =SUM(F12:F14) | G15: =SUM(G12:G14) | H15: =SUM(H12:H14)
B17: ='Project Detail'!D62
B18: ='Project Detail'!D63 | C18: ='Project Detail'!F82 | D18: ='Project Detail'!G82 | E18: ='Project Detail'!K82 | F18: ='Project Detail'!L82 | G18: ='Project Detail'!M82 | H18: ='Project Detail'!N82
B19: ='Project Detail'!D83 | C19: ='Project Detail'!F88 | D19: ='Project Detail'!G88 | E19: ='Project Detail'!K88 | F19: ='Project Detail'!L88 | G19: ='Project Detail'!M88 | H19: ='Project Detail'!N88
B20: ='Project Detail'!D89 | C20: ='Project Detail'!F92 | D20: ='Project Detail'!G92 | E20: ='Project Detail'!K92 | F20: ='Project Detail'!L92 | G20: ='Project Detail'!M92 | H20: ='Project Detail'!N92
B21: ='Project Detail'!D93 | C21: ='Project Detail'!F99 | D21: ='Project Detail'!G99 | E21: ='Project Detail'!K99 | F21: ='Project Detail'!L99 | G21: ='Project Detail'!M99 | H21: ='Project Detail'!N99
B22: ='Project Detail'!D100 | C22: ='Project Detail'!F118 | D22: ='Project Detail'!G118 | E22: ='Project Detail'!K118 | F22: ='Project Detail'!L118 | G22: ='Project Detail'!M118 | H22: ='Project Detail'!N118
B23: ='Project Detail'!D119 | C23: ='Project Detail'!F130 | D23: ='Project Detail'!G130 | E23: ='Project Detail'!K130 | F23: ='Project Detail'!L130 | G23: ='Project Detail'!M130 | H23: ='Project Detail'!N130
B24: ='Project Detail'!D131 | C24: ='Project Detail'!F138 | D24: ='Project Detail'!G138 | E24: ='Project Detail'!K138 | F24: ='Project Detail'!L138 | G24: ='Project Detail'!M138 | H24: ='Project Detail'!N138
B25: ='Project Detail'!D139 | C25: ='Project Detail'!F150 | D25: ='Project Detail'!G150 | E25: ='Project Detail'!K150 | F25: ='Project Detail'!L150 | G25: ='Project Detail'!M150 | H25: ='Project Detail'!N150
B26: ='Project Detail'!D151 | C26: ='Project Detail'!F166 | D26: ='Project Detail'!G166 | E26: ='Project Detail'!K166 | F26: ='Project Detail'!L166 | G26: ='Project Detail'!M166 | H26: ='Project Detail'!N166
B27: FF&E Costs Total | C27: =SUM(C18:C26) | D27: =SUM(D18:D26) | E27: =SUM(E18:E26) | F27: =SUM(F18:F26) | G27: =SUM(G18:G26) | H27: =SUM(H18:H26)
B29: Sub-Total | C29: =+C9+C15+C27 | D29: =+D9+D15+D27 | E29: =+E9+E15+E27 | F29: =+F9+F15+F27 | G29: =+G9+G15+G27 | H29: =+H9+H15+H27
B30: Contingency | C30: ='Project Detail'!F170 | F30: =Contingency!G9 | G30: =Contingency!G9 | H30: =C30-G30
B31: GRAND TOTAL | C31: =SUM(C29:C30) | D31: =SUM(D29:D30) | E31: =SUM(E29:E30) | F31: =SUM(F29:F30) | G31: =SUM(G29:G30) | H31: =SUM(H29:H30)

Sheet Project Detail
B2: Code | C2: Cost Code | D2: Vendor | E2: Description | F2: Budget | G2: Committed Costs | H2: Change Orders | I2: Costs to Date (Gross) | J2: Retention | K2: Costs to Date | L2: Remaining Estimate | M2: Estimated Final Cost | N2: Budget vs EFC Variance | O2: Notes | Q2: Remaining to Invoice | S2: P11-21 (Fcst) | T2: P12-21 (Fcst) | U2: Q4-21 TOTAL (Fcst) | W2: P01-22 (Fcst) | X2: P02-22 (Fcst) | Y2: P03-22 (Fcst) | Z2: Q1-22 TOTAL (Fcst) | AB2: Q4-21/Q1-22 TOTAL | AD2: Remaining to Allocate
B4: 100 | D4: Building Costs
B5: 101 | D5: Building & Fit-Out Costs
B6: 101-1 | D6: General Contractor | F6: ='Budget Summary'!D31 | G6: =SUMIF('Committed Costs '!C:C,B6,'Committed Costs '!G:G) | H6: =SUMIF('Change Orders'!F:F,'Project Detail'!B6,'Change Orders'!E:E) | I6: =SUMIF(Invoices!B:B,B6,Invoices!G:G) | J6: 0 | K6: =I6-J6 | L6: =+M6-G6 | M6: =IF((F6+H6)>G6,F6+H6,G6) | N6: =F6-M6
B7: 101-2 | F7: 0 | G7: =SUMIF('Committed Costs '!C:C,B7,'Committed Costs '!G:G) | H7: =SUMIF('Change Orders'!F:F,'Project Detail'!B7,'Change Orders'!E:E) | I7: =SUMIF(Invoices!B:B,B7,Invoices!G:G) | J7: 0 | K7: =I7-J7 | L7: =+M7-G7 | M7: =IF((F7+H7)>G7,F7+H7,G7) | N7: =F7-M7
B8: 101-3 | F8: 0 | G8: =SUMIF('Committed Costs '!C:C,B8,'Committed Costs '!G:G) | H8: =SUMIF('Change Orders'!F:F,'Project Detail'!B8,'Change Orders'!E:E) | I8: =SUMIF(Invoices!B:B,B8,Invoices!G:G) | J8: 0 | K8: =I8-J8 | L8: =+M8-G8 | M8: =IF((F8+H8)>G8,F8+H8,G8) | N8: =F8-M8
B9: 101-4 | F9: 0 | G9: =SUMIF('Committed Costs '!C:C,B9,'Committed Costs '!G:G) | H9: =SUMIF('Change Orders'!F:F,'Project Detail'!B9,'Change Orders'!E:E) | I9: =SUMIF(Invoices!B:B,B9,Invoices!G:G) | J9: 0 | K9: =I9-J9 | L9: =+M9-G9 | M9: =IF((F9+H9)>G9,F9+H9,G9) | N9: =F9-M9 | Q9: =M9-K9 | U9: =S9+T9 | Z9: =W9+X9+Y9 | AB9: =U9+Z9 | AD9: =Q9-AB9
C10: 101 | E10: Total Building & Fit-Out Costs | F10: =SUM(F6:F9) | G10: =SUM(G6:G9) | H10: =SUM(H6:H9) | I10: =SUM(I6:I9) | J10: =SUM(J6:J9) | K10: =SUM(K6:K9) | L10: =SUM(L6:L9) | M10: =SUM(M6:M9) | N10: =SUM(N6:N9) | Q10: =Q9 | S10: =S9 | T10: =T9 | U10: =U9 | W10: =W9 | X10: =X9 | Y10: =Y9 | Z10: =Z9 | AB10: =AB9 | AD10: =AD9
B11: 102 | D11: Secondary Contractors
B12: 102-1 | F12: 0 | G12: =SUMIF('Committed Costs '!C:C,B12,'Committed Costs '!G:G) | H12: =SUMIF('Change Orders'!F:F,'Project Detail'!B12,'Change Orders'!E:E) | I12: =SUMIF(Invoices!B:B,B12,Invoices!G:G) | J12: 0 | K12: =I12-J12 | L12: =+M12-G12 | M12: =IF((F12+H12)>G12,F12+H12,G12) | N12: =F12-M12
B13: 102-2 | F13: 0 | G13: =SUMIF('Committed Costs '!C:C,B13,'Committed Costs '!G:G) | H13: =SUMIF('Change Orders'!F:F,'Project Detail'!B13,'Change Orders'!E:E) | I13: =SUMIF(Invoices!B:B,B13,Invoices!G:G) | J13: 0 | K13: =I13-J13 | L13: =+M13-G13 | M13: =IF((F13+H13)>G13,F13+H13,G13) | N13: =F13-M13
B14: 102-3 | F14: 0 | G14: =SUMIF('Committed Costs '!C:C,B14,'Committed Costs '!G:G) | H14: =SUMIF('Change Orders'!F:F,'Project Detail'!B14,'Change Orders'!E:E) | I14: =SUMIF(Invoices!B:B,B14,Invoices!G:G) | J14: 0 | K14: =I14-J14 | L14: =+M14-G14 | M14: =IF((F14+H14)>G14,F14+H14,G14) | N14: =F14-M14
B15: 102-4 | F15: 0 | G15: =SUMIF('Committed Costs '!C:C,B15,'Committed Costs '!G:G) | H15: =SUMIF('Change Orders'!F:F,'Project Detail'!B15,'Change Orders'!E:E) | I15: =SUMIF(Invoices!B:B,B15,Invoices!G:G) | J15: 0 | K15: =I15-J15 | L15: =+M15-G15 | M15: =IF((F15+H15)>G15,F15+H15,G15) | N15: =F15-M15 | Q15: =M15-K15 | U15: =S15+T15 | Z15: =W15+X15+Y15 | AB15: =U15+Z15 | AD15: =Q15-AB15
C16: 102 | E16: Total Secondary Contractors | F16: =SUM(F12:F15) | G16: =SUM(G12:G15) | H16: =SUM(H12:H15) | I16: =SUM(I12:I15) | J16: =SUM(J12:J15) | K16: =SUM(K12:K15) | L16: =SUM(L12:L15) | M16: =SUM(M12:M15) | N16: =SUM(N12:N15) | Q16: =Q15 | S16: =S15 | T16: =T15 | U16: =U15 | W16: =W15 | X16: =X15 | Y16: =Y15 | Z16: =Z15 | AB16: =AB15 | AD16: =AD15
B17: 103 | D17: Miscellaneous
B18: 103-1 | F18: 0 | G18: =SUMIF('Committed Costs '!C:C,B18,'Committed Costs '!G:G) | H18: =SUMIF('Change Orders'!F:F,'Project Detail'!B18,'Change Orders'!E:E) | I18: =SUMIF(Invoices!B:B,B18,Invoices!G:G) | J18: 0 | K18: =I18-J18 | L18: =+M18-G18 | M18: =IF((F18+H18)>G18,F18+H18,G18) | N18: =F18-M18
B19: 103-2 | F19: 0 | G19: =SUMIF('Committed Costs '!C:C,B19,'Committed Costs '!G:G) | H19: =SUMIF('Change Orders'!F:F,'Project Detail'!B19,'Change Orders'!E:E) | I19: =SUMIF(Invoices!B:B,B19,Invoices!G:G) | J19: 0 | K19: =I19-J19 | L19: =+M19-G19 | M19: =IF((F19+H19)>G19,F19+H19,G19) | N19: =F19-M19
B20: 103-3 | F20: 0 | G20: =SUMIF('Committed Costs '!C:C,B20,'Committed Costs '!G:G) | H20: =SUMIF('Change Orders'!F:F,'Project Detail'!B20,'Change Orders'!E:E) | I20: =SUMIF(Invoices!B:B,B20,Invoices!G:G) | J20: 0 | K20: =I20-J20 | L20: =+M20-G20 | M20: =IF((F20+H20)>G20,F20+H20,G20) | N20: =F20-M20
B21: 103-4 | F21: 0 | G21: =SUMIF('Committed Costs '!C:C,B21,'Committed Costs '!G:G) | H21: =SUMIF('Change Orders'!F:F,'Project Detail'!B21,'Change Orders'!E:E) | I21: =SUMIF(Invoices!B:B,B21,Invoices!G:G) | J21: 0 | K21: =I21-J21 | L21: =+M21-G21 | M21: =IF((F21+H21)>G21,F21+H21,G21) | N21: =F21-M21 | Q21: =M21-K21 | U21: =S21+T21 | Z21: =W21+X21+Y21 | AB21: =U21+Z21 | AD21: =Q21-AB21
C22: 103 | E22: Total Mics. | F22: =SUM(F18:F21) | G22: =SUM(G18:G21) | H22: =SUM(H18:H21) | I22: =SUM(I18:I21) | J22: =SUM(J18:J21) | K22: =SUM(K18:K21) | L22: =SUM(L18:L21) | M22: =SUM(M18:M21) | N22: =SUM(N18:N21) | Q22: =Q21 | S22: =S21 | T22: =T21 | U22: =U21 | W22: =W21 | X22: =X21 | Y22: =Y21 | Z22: =Z21 | AB22: =AB21 | AD22: =AD21
B23: 104
B24: 104-1 | F24: 0 | G24: =SUMIF('Committed Costs '!C:C,B24,'Committed Costs '!G:G) | H24: =SUMIF('Change Orders'!F:F,'Project Detail'!B24,'Change Orders'!E:E) | I24: =SUMIF(Invoices!B:B,B24,Invoices!G:G) | J24: 0 | K24: =I24-J24 | L24: =+M24-G24 | M24: =K24 | N24: =F24-M24
B25: 104-2 | F25: 0 | G25: =SUMIF('Committed Costs '!C:C,B25,'Committed Costs '!G:G) | H25: =SUMIF('Change Orders'!F:F,'Project Detail'!B25,'Change Orders'!E:E) | I25: =SUMIF(Invoices!B:B,B25,Invoices!G:G) | J25: 0 | K25: =I25-J25 | L25: =+M25-G25 | M25: =IF((F25+H25)>G25,F25+H25,G25) | N25: =F25-M25
B26: 104-3 | F26: 0 | G26: =SUMIF('Committed Costs '!C:C,B26,'Committed Costs '!G:G) | H26: =SUMIF('Change Orders'!F:F,'Project Detail'!B26,'Change Orders'!E:E) | I26: =SUMIF(Invoices!B:B,B26,Invoices!G:G) | J26: 0 | K26: =I26-J26 | L26: =+M26-G26 | M26: =IF((F26+H26)>G26,F26+H26,G26) | N26: =F26-M26
B27: 104-4 | F27: 0 | G27: =SUMIF('Committed Costs '!C:C,B27,'Committed Costs '!G:G) | H27: =SUMIF('Change Orders'!F:F,'Project Detail'!B27,'Change Orders'!E:E) | I27: =SUMIF(Invoices!B:B,B27,Invoices!G:G) | J27: 0 | K27: =I27-J27 | L27: =+M27-G27 | M27: =IF((F27+H27)>G27,F27+H27,G27) | N27: =F27-M27 | Q27: =M27-K27 | U27: =S27+T27 | Z27: =W27+X27+Y27 | AB27: =U27+Z27 | AD27: =Q27-AB27
C28: 104 | E28: Total | F28: =SUM(F24:F27) | G28: =SUM(G24:G27) | H28: =SUM(H24:H27) | I28: =SUM(I24:I27) | J28: =SUM(J24:J27) | K28: =SUM(K24:K27) | L28: =SUM(L24:L27) | M28: =SUM(M24:M27) | N28: =SUM(N24:N27) | Q28: =Q27 | S28: =S27 | T28: =T27 | U28: =U27 | W28: =W27 | X28: =X27 | Y28: =Y27 | Z28: =Z27 | AB28: =AB27 | AD28: =AD27
E30: TOTAL BUILDING COSTS | F30: =SUM(F10,F16,F22,F28) | G30: =SUM(G10,G16,G22,G28) | H30: =SUM(H10,H16,H22,H28) | I30: =SUM(I10,I16,I22,I28) | J30: =SUM(J10,J16,J22,J28) | K30: =SUM(K10,K16,K22,K28) | L30: =SUM(L10,L16,L22,L28) | M30: =SUM(M10,M16,M22,M28) | N30: =SUM(N10,N16,N22,N28) | Q30: =SUM(Q10,Q16,Q22,Q28) | S30: =SUM(S10,S16,S22,S28) | T30: =SUM(T10,T16,T22,T28) | U30: =SUM(U10,U16,U22,U28) | W30: =SUM(W10,W16,W22,W28) | X30: =SUM(X10,X16,X22,X28) | Y30: =SUM(Y10,Y16,Y22,Y28) | Z30: =SUM(Z10,Z16,Z22,Z28) | AB30: =SUM(AB10,AB16,AB22,AB28) | AD30: =SUM(AD10,AD16,AD22,AD28)
B33: 200 | D33: Soft Costs
B34: 201 | D34: Project Management
B35: 201-1 | D35: LNE | E35: Project Management | F35: ='Budget Summary'!D45 | G35: =SUMIF('Committed Costs '!C:C,B35,'Committed Costs '!G:G) | H35: =SUMIF('Change Orders'!F:F,'Project Detail'!B35,'Change Orders'!E:E) | I35: =SUMIF(Invoices!B:B,B35,Invoices!G:G) | J35: 0 | K35: =I35-J35 | L35: =+M35-G35 | M35: =G35 | N35: =F35-M35 | Q35: =M35-K35 | U35: =S35+T35 | Z35: =W35+X35+Y35 | AB35: =U35+Z35 | AD35: =Q35-AB35
B36: 201-2 | D36: TBD | E36: Project Management (3rd Party) | F36: ='Budget Summary'!#REF! | G36: =SUMIF('Committed Costs '!C:C,B36,'Committed Costs '!G:G) | H36: =SUMIF('Change Orders'!F:F,'Project Detail'!B36,'Change Orders'!E:E) | I36: =SUMIF(Invoices!B:B,B36,Invoices!G:G) | J36: 0 | K36: =I36-J36 | L36: =+M36-G36 | M36: =IF((F36+H36)>G36,F36+H36,G36) | N36: =F36-M36
B37: 201-3 | F37: 0 | G37: =SUMIF('Committed Costs '!C:C,B37,'Committed Costs '!G:G) | H37: =SUMIF('Change Orders'!F:F,'Project Detail'!B37,'Change Orders'!E:E) | I37: =SUMIF(Invoices!B:B,B37,Invoices!G:G) | J37: 0 | K37: =I37-J37 | L37: =+M37-G37 | M37: =IF((F37+H37)>G37,F37+H37,G37) | N37: =F37-M37
B38: 201-4 | F38: 0 | G38: =SUMIF('Committed Costs '!C:C,B38,'Committed Costs '!G:G) | H38: =SUMIF('Change Orders'!F:F,'Project Detail'!B38,'Change Orders'!E:E) | I38: =SUMIF(Invoices!B:B,B38,Invoices!G:G) | J38: 0 | K38: =I38-J38 | L38: =+M38-G38 | M38: =IF((F38+H38)>G38,F38+H38,G38) | N38: =F38-M38
C39: 201 | E39: Total Project Management | F39: =SUM(F35:F38) | G39: =SUM(G35:G38) | H39: =SUM(H35:H38) | I39: =SUM(I35:I38) | J39: =SUM(J35:J38) | K39: =SUM(K35:K38) | L39: =SUM(L35:L38) | M39: =SUM(M35:M38) | N39: =SUM(N35:N38) | Q39: =Q35 | S39: =S35 | T39: =T35 | U39: =U35 | W39: =W35 | X39: =X35 | Y39: =Y35 | Z39: =Z35 | AB39: =AB35 | AD39: =AD35
B40: 202 | D40: Architectural Fees
B41: 202-1 | D41: TBD | E41: Architectural Fees | F41: ='Budget Summary'!D35 | G41: =SUMIF('Committed Costs '!C:C,B41,'Committed Costs '!G:G) | H41: =SUMIF('Change Orders'!F:F,'Project Detail'!B41,'Change Orders'!E:E) | I41: =SUMIF(Invoices!B:B,B41,Invoices!G:G) | J41: 0 | K41: =I41-J41 | L41: =+M41-G41 | M41: =G41 | N41: =F41-M41 | Q41: =M41-K41 | U41: =S41+T41 | Z41: =W41+X41+Y41 | AB41: =U41+Z41 | AD41: =Q41-AB41
B42: 202-2 | F42: 0 | G42: =SUMIF('Committed Costs '!C:C,B42,'Committed Costs '!G:G) | H42: =SUMIF('Change Orders'!F:F,'Project Detail'!B42,'Change Orders'!E:E) | I42: =SUMIF(Invoices!B:B,B42,Invoices!G:G) | J42: 0 | K42: =I42-J42 | L42: =+M42-G42 | M42: =IF((F42+H42)>G42,F42+H42,G42) | N42: =F42-M42 | Q42: =M42-K42 | U42: =S42+T42 | Z42: =W42+X42+Y42 | AB42: =U42+Z42 | AD42: =Q42-AB42
B43: 202-3 | F43: 0 | G43: =SUMIF('Committed Costs '!C:C,B43,'Committed Costs '!G:G) | H43: =SUMIF('Change Orders'!F:F,'Project Detail'!B43,'Change Orders'!E:E) | I43: =SUMIF(Invoices!B:B,B43,Invoices!G:G) | J43: 0 | K43: =I43-J43 | L43: =+M43-G43 | M43: 0 | N43: =F43-M43 | Q43: =M43-K43 | U43: =S43+T43 | Z43: =W43+X43+Y43 | AB43: =U43+Z43 | AD43: =Q43-AB43
B44: 202-4 | F44: 0 | G44: =SUMIF('Committed Costs '!C:C,B44,'Committed Costs '!G:G) | H44: =SUMIF('Change Orders'!F:F,'Project Detail'!B44,'Change Orders'!E:E) | I44: =SUMIF(Invoices!B:B,B44,Invoices!G:G) | J44: 0 | K44: =I44-J44 | L44: =+M44-G44 | M44: =IF((F44+H44)>G44,F44+H44,G44) | N44: =F44-M44
C45: 202 | E45: Total Architectural Fees | F45: =SUM(F41:F44) | G45: =SUM(G41:G44) | H45: =SUM(H41:H44) | I45: =SUM(I41:I44) | J45: =SUM(J41:J44) | K45: =SUM(K41:K44) | L45: =SUM(L41:L44) | M45: =SUM(M41:M44) | N45: =SUM(N41:N44) | Q45: =SUM(Q41:Q43) | S45: =SUM(S41:S43) | T45: =SUM(T41:T43) | U45: =SUM(U41:U43) | W45: =SUM(W41:W43) | X45: =SUM(X41:X43) | Y45: =SUM(Y41:Y43) | Z45: =SUM(Z41:Z43) | AB45: =SUM(AB41:AB43) | AD45: =SUM(AD41:AD43)
...

Sheet Committed Costs 
B2: Committed Costs
B3: Executed Date | C3: Cost Code | D3: Vendor | E3: Description | F3: P.O. Number | G3: Contract Value | H3: Notes
F9: Total Commitments | G9: =SUBTOTAL(9,G4:G6)
G10: =G9='Project At-a-Glance'!D25

Sheet Invoices
B2: Invoices
B3: Cost Code | C3: Vendor | D3: Description | E3: Invoice # | F3: Invoice Date | G3: Invoice Amount | H3: GL Period | I3: Notes | J3: Payment Status
B5: 2022 Invoices
F10: March Invoices Total | G10: =SUBTOTAL(9,G6:G9)
F13: INVOICES GRAND TOTAL | G13: =SUM(G10)
G14: =G13='Project At-a-Glance'!E25

Sheet Change Orders
B2: Date Issued | C2: C.O. Number | D2: Vendor | E2: Amount | F2: Cost Code | G2: Description | H2: Notes
D29: Total Change Orders | E29: =SUM(E3:E28)

Sheet Contingency
B2: Date | C2: Cost Code | D2: Vendor | E2: Description | F2: Amount Applied | G2: Remaining Balance | H2: Notes
B4: March 2020 Contingency | J4: Contingency
B5: 43921 | C5: N/A | D5: N/A | E5: Initial Contingency Amount | F5: 0 | G5: =+J5-F5 | J5: ='Project Detail'!F170
E6: March Contingency Totals | F6: =SUBTOTAL(9,F5) | G6: =G5
E9: CONTINGENCY TOTALS | F9: =SUM(F6) | G9: =G6

Sheet Risk Report
A1: Risk Report
A3: Requestor | C3: Item | E3: High | G3: Expected Settlement Value | I3: Low | K3: Notes
A4: Project Team
A5: Project Team
A6: Project Team
A7: Project Team
A8: Project Team
A9: Project Team
A10: Project Team
A11: Project Team
A12: Project Team
A13: Project Team
A14: Project Team
E15: =SUM(E4:E14) | G15: =SUM(G4:G14) | I15: =SUM(I4:I14)
C19: Current Sources (as of 01/31/2023) | E19: Remaining Contingency | G19: =Contingency!G9
E21: Contingency Balance | G21: =G19-G15
E23: Exposure | G23: =IF(G15>G19,G19-G15,0)
C26: *Sources reflect over budget items pending resolution.
