Workbook

Sheet Detailed Budget
B2: 165 RANDOLPH STREET
B3: DETAILED DEVELOPMENT BUDGET — V2, DILIGENCE REVIEWED
B4: Brooklyn NY 11237 · Developer: owner’s team · Co-pro: Live Nation / Insomniac · Landlord: Eric Cohen · CONSTRUCTION CAPEX ONLY · CONFIDENTIAL
B6: Building SF | E6: 74100 | G6: THE basis. Mezzanine adds capacity inside this envelope, not area. Alleys carry no cost.
B7: Theatre seat rate ($/seat) | E7: 25 | G7: TOGGLE: 25 = MT sourcing, 125 = as filed in the dev budget. Drives the removable seating line in division 600.
B8: Mezzanine SF | E8: 14000 | G8: Inside the 74,100. Derived from the Wake test-fit occupancy loads.
B9: Perimeter LF | E9: 1089 | G9: Approximated as square. Replace with the survey.
B10: New wall band SF | E10: 32670 | G10: 1,089 LF perimeter x 30 ft lift.
B11: Capacity | E11: 7440 | G11: Wake PD04 Rev 4.4.
B12: General conditions basis | E12: 1 | G12: TOGGLE: 1 = the 11% percentage. 0 = Thomas’s own 013000 + 015800 line items ($1,696,000) instead. NEVER BOTH — they are the same site cost.
B13: Kitchen scope (0 / 1 / 2) | E13: 1 | G13: TOGGLE for division 800. 0 = concessions only, no kitchen. 1 = warming / finishing kitchen. 2 = full production kitchen with a grease hood. Each level includes the one below it.
B15: Item | C15: Qty | D15: Unit | E15: Rate | F15: Amount | G15: Rate source / basis
B16: 000 SITE & ENABLING
B17: Sidewalk shed / bridge
B18: Sidewalk shed, erect & dismantle | C18: 1089 | D18: LF | E18: 210 | F18: =C18*E18 | G18: NYC shed ~$180-240/LF erected
B19: Shed rental, 24 months | C19: 26136 | D19: LF-mo | E19: 22 | F19: =C19*E19 | G19: SCHEDULE-DRIVEN. Rented monthly — every month of programme costs $23,958. Reduced from 30 to 24 months; confirm against the real construction schedule
B20: DOT permit & renewals | C20: 1 | D20: LS | E20: 45000 | F20: =C20*E20 | G20: Sidewalk shed permit, renewed periodically
B21: Lighting & signage on shed | C21: 1089 | D21: LF | E21: 18 | F21: =C21*E21 | G21: Required by DOT
B22: Netting & debris containment | C22: 32670 | D22: SF | E22: 1.1 | F22: =C22*E22 | G22: Facade protection during the lift
B23: Sidewalk shed / bridge — subtotal | F23: =SUM(F18:F22)
B24: Interior protection & containment
B25: Slab protection, hardboard & poly | C25: 74100 | D25: SF | E25: 1.35 | F25: =C25*E25 | G25: Protecting the existing slab
B26: Dust partitions & negative air | C26: 1 | D26: LS | E26: 65000 | F26: =C26*E26 | G26: Containment during demo and abatement
B27: Protection of retained equipment | C27: 1 | D27: LS | E27: 22000 | F27: =C27*E27
B28: Interior protection & containment — subtotal | F28: =SUM(F25:F27)
B29: Temporary weather protection
B30: Temporary roof membrane at open areas | C30: 18525 | D30: SF | E30: 8.5 | F30: =C30*E30 | G30: Only ~25% of roof open at any stage on a lift
B31: Perimeter tarping at the lift band | C31: 32670 | D31: SF | E31: 3.2 | F31: =C31*E31
B32: Temporary heat & dehumidification | C32: 1 | D32: LS | E32: 85000 | F32: =C32*E32 | G32: Winter work
B33: Temporary weather protection — subtotal | F33: =SUM(F30:F32)
B34: Asbestos / hazmat abatement
B35: ACP-5 / ACP-7 filing & asbestos investigator | C35: 1 | D35: LS | E35: 45000 | F35: =C35*E35 | G35: NYC required on a 1948 building
B36: Roofing felt & mastic abatement | C36: 74100 | D36: SF | E36: 7.5 | F36: =C36*E36 | G36: SURVEY-DEPENDENT. PRESUMED ACM on a 1948 precast roof — nobody has sampled it. If the roof is clean this line goes to near zero. Get the ACP-5 survey done early; it is worth $555,750
B37: Pipe & boiler insulation abatement | C37: 1 | D37: LS | E37: 120000 | F37: =C37*E37 | G37: Dev budget notes a 5,250 MBH boiler and steam piping
B38: Lead paint abatement at steel | C38: 1 | D38: LS | E38: 95000 | F38: =C38*E38
B39: Air monitoring & clearance | C39: 1 | D39: LS | E39: 55000 | F39: =C39*E39
B40: Hazmat disposal & manifesting | C40: 1 | D40: LS | E40: 130000 | F40: =C40*E40
B41: Asbestos / hazmat abatement — subtotal | F41: =SUM(F35:F40)
B42: Demolition — interior
B43: Demo masonry walls at new entry/lobby | C43: 2500 | D43: SF | E43: 12 | F43: =C43*E43 | G43: Dev budget 024100-1 rate & qty
...

Sheet Diligence Review
B2: DILIGENCE REVIEW
B3: The 165 Randolph diligence folder, 26 files, uploaded 10 September 2026 — read against this budget.
B5: THE HEADLINE. Two files in the folder are readable cost documents, and they are the best third-party evidence in the whole exercise: Schimenti Construction’s conceptual budgets for 555 Johnson Avenue, addressed to Eric Cohen at EBC Capital. Our own landlord, the next block over, open-shop labour, priced by a real NYC general contractor. That gives us actual percentages to hold our estimator against instead of my benchmarks. It moved general conditions from 11% to 8.5%. Everything else in the folder is a scanned drawing, a CAD plot or a custom-font PDF with no recoverable text — the inventory at the bottom says which is which, and which unread files are worth someone opening by hand.
B7: FINDINGS
B8: Finding | C8: What the diligence says | D8: What we carried | E8: So what | F8: Action
B9: GENERAL CONDITIONS IS THE ONE HARD NUMBER WE NOW HAVE | C9: Schimenti priced general conditions at $2,198,000 on a $28,165,000 construction subtotal = 7.80% on the full 555 Johnson scheme, and $989,100 on $11,110,174 = 8.90% on the partial-reuse option. Both open shop, both for Eric Cohen, both in this submarket. | D9: 11.0%, which was my own benchmark rather than a quote. | E9: Two real data points from our own landlord's general contractor average 8.35%. My 11% was too high. Changed to 8.5%. | F9: APPLIED — rate moved from 11% to 8.5%. Worth $954,153 at the current trade cost. Push the estimator to justify anything above 8.5% with a staffing chart and a duration, not a percentage.
B10: OVERHEAD, PROFIT & INSURANCE IS ABOUT RIGHT — DO NOT CUT IT | C10: Schimenti's insurance/fees/bonds line is 7.11% (full) and 8.98% (partial reuse). CRITICALLY, both lines say 'Construction Contingency — Excluded' and 'Builder's Risk Insurance — Excluded'. | D10: 9.0%, described as including insurance. | E10: Comparing like with like, 9% including builder's risk against ~8% excluding it is consistent. This rate is NOT the soft one. The soft one was general conditions. | F10: NO CHANGE. Stop arguing about this line and spend the leverage on general conditions and the roof.
B11: CONTINGENCY BELONGS TO YOU, NOT THE CONTRACTOR — CONFIRMED | C11: Schimenti explicitly EXCLUDES construction contingency from both budgets. | D11: One $5,000,000 owner-held contingency below the line. | E11: A real NYC GC pricing for your own landlord excluded contractor contingency entirely. The restructure you asked for matches how this market actually quotes. | F11: NO CHANGE — this validates the structure. If our estimator insists on a 10% contractor contingency he holds and keeps, ask him why Schimenti didn't.
B12: THE 135,953 SF ERROR HAS A TRACEABLE ORIGIN | C12: 555 Johnson is ~135,000 SF: $28,165,000 divided by $208.63/SF = 134,993 SF. | D12: Thomas's Master Development Budget header states SF: 135,953. The building is 74,100 SF. | E12: The wrong area almost certainly came across from the 555 Johnson job. It is not a typo, it is a template carried over from a different building on the next block. | F12: ASK. This makes the correction much easier to land: you are not telling him he cannot count, you are showing him which file it came from. Every SF-driven line in his schedule needs re-running at 74,100.
B13: OPEN SHOP IS THE NORM ON ERIC'S PROJECTS | C13: Schimenti qualification 1.1: 'Labor Type — Open Shop'. Work hours 7am-3:30pm, single shift. A NYC licensed superintendent is required. | D13: The Rooflifters 2022 rate card, whose union status we flagged as unknown. | E13: Open shop is what got priced across the street. It supports non-union pricing as the base case and it means the Rooflifters card is probably the right basis, not a low one. | F13: ASK Rooflifters to confirm open shop, and hold the estimator to a single-shift 7am-3:30pm assumption unless he is pricing overtime for a reason he can name.
B14: THE CONSTRUCTION WINDOW COMP IS 60 WEEKS, NOT 24 MONTHS | C14: Schimenti: '70 week active project schedule and 60 weeks of construction.' Their timeline runs design kick-off Feb 2019 to TCO Feb 2021, with foundation 2 months, core and shell 6-8 months, interior fit 4 months. | D14: 24 months of sidewalk shed rental at $23,958/month. | E14: 60 weeks is 13.8 months of construction. Our roof lift genuinely extends the programme beyond their case, so I have NOT cut the duration — but 24 months now needs defending against a real comp rather than being assumed. | F14: VERIFY with the estimator. Every month you take out of the programme is $23,958 of shed alone, before general conditions. An 18-month shed saves $143,748.
B15: MEP IS 3.4x THE COMP AND THAT IS THE SECOND-BIGGEST QUESTION AFTER THE ROOF | C15: 555 Johnson mechanical + electrical = $31.54 + $24.15 = $55.69/SF. Elevators $3.16/SF. | D15: Our division 500 excluding conveying is $191.58/SF. Conveying at $4.05/SF is a near-perfect match to their $3.16. | E15: The elevator match tells us the comparison is meaningful. A 7,440-occupant assembly venue legitimately carries far more MEP than production studios — ventilation alone for 7,440 people is 110,000-150,000 CFM, and body heat is over 300 tons before a single fixture. But 3.4x is a big number to accept on trust, and it is the same doubt as the HVAC basis question. | F15: ASK. This is now the strongest reason to get a written answer on whether HVAC was priced on a load calculation or a rate per square foot.
B16: RENOVATION AND FIT-OUT OF AN EXISTING BUILDING NEARBY RAN $120-135/SF | C16: Schimenti's partial-reuse option prices Lots 25 & 37 renovation and fit-out at $2,760,000 over 23,000 SF = $120/SF, and Lot 42 at $4,050,000 over 30,000 SF = $135/SF. | D16: Not directly comparable — those are light industrial and office fit-outs, not an 8,000-cap venue. | E16: Useful as a floor, not a target. It tells you what ordinary warehouse conversion costs on this block, so any line in our budget that is just ordinary construction should sit near that band. | F16: Use it to sanity-check the non-venue-specific parts: BOH, offices, circulation, restroom blocks.
B17: GEOTECHNICAL WORK BEFORE FOUNDATION PRICING — THEIR FIRST RECOMMENDATION | C17: Schimenti's recommended next steps lead with: 'Conduct a GeoTechnical Survey of Existing Soil Conditions, Probes and Test Pits. Better information on the existing conditions will allow a targeted foundation and sub grade approach.' Their timeline puts test pits and additional borings before CDs are issued for foundations. | D17: $150,000 for 13 borings 50 ft deep, plus $85,000 existing-conditions survey and scan. | E17: We carry borings but not test pits and probes as a separate item, and their sequencing point is the real one: the survey comes BEFORE foundation pricing, not alongside it. | F17: SEQUENCE IT FIRST. This is also the strongest single argument for holding the $5,000,000 contingency: their own GC says foundation cost is unknowable until this is done.
B18: ADD ALTERNATE PRICING EXISTS FOR ADDING A FLOOR — RELEVANT TO THE BALCONY QUESTION | C18: Schimenti priced 'Add 1 Floor to Lot 25 & 37' at $9,450,000, noted as reinforce plus core and shell. | D18: Thomas carries steel framing at an upper balcony at QTY 0 — a third level that is not in our model at all. | E18: Adding a floor to an existing building is a nine-figure-per-acre proposition, not a line item. It is a reminder that the upper balcony is a scope decision with real money behind it, not a detail. | F18: DECIDE. If the test fit keeps a balcony above the mezzanine, it needs pricing as a structural addition — new steel, new egress, new sprinkler, new seating.
B19: ACOUSTIC WALLS APPEAR AS THEIR OWN DIVISION IN THE PRODUCTION STUDIO BUDGET | C19: The Production Studios budget carries 'Acoustic Walls' as a top-level trade line alongside Concrete, Masonry and Metals. | D19: Acoustic treatment is grouped under division 400 as a licence-to-operate item. | E19: Confirms that acoustic scope is treated as a major trade on this kind of building rather than a finish, which is how we treat it. | F19: NO CHANGE — but the Acoustical Data.pdf in this folder is a scanned document nobody has read. It may contain the actual STC targets, which would let us price the treatment instead of allowing for it.
B22: THE COMP — SCHIMENTI CONSTRUCTION, 555 JOHNSON AVENUE, FOR ERIC COHEN / EBC CAPITAL
B23: Full scheme 8 Jan 2019 over ~135,000 SF, and the partial site re-use option 11 Jan 2019. Note that 555 Johnson is ~135,000 SF — which is almost certainly where the 135,953 SF in Thomas’s header came from.
B24: Division | C24: Full scheme | D24: $/SF | E24: Partial re-use | F24: $/SF
B25: 2-000 Existing conditions | C25: 3128000 | D25: 23.17 | E25: 1525000 | F25: 25
B26: 3-000 Concrete / precast | C26: 6973000 | D26: 51.65 | E26: 2078519 | F26: 34.07
B27: 4-000 Masonry | C27: 3996000 | D27: 29.6 | E27: 765000 | F27: 12.54
B28: 5-000 Steel | C28: 2105000 | D28: 15.59 | E28: 1905000 | F28: 31.23
B29: 6-000 Wood & plastics | C29: 168000 | D29: 1.24 | E29: 77156 | F29: 1.26
B30: 7-000 Thermal, moisture & fireproofing | C30: 3062000 | D30: 22.68 | E30: 1860000 | F30: 30.49
B31: 8-000 Doors & windows | C31: 460000 | D31: 3.41 | E31: 36000 | F31: 0.59
B32: 9-000 Finishes | C32: 303000 | D32: 2.24 | E32: 108500 | F32: 1.78
B33: 10-000 Specialties | C33: 25000 | D33: 0.19 | E33: 25000 | F33: 0.41
B34: 14-000 Elevators & lifts | C34: 427000 | D34: 3.16 | E34: 0 | F34: 0
B35: 15-000 Mechanical (FP + plumbing + HVAC) | C35: 4258000 | D35: 31.54 | E35: 1200000 | F35: 19.67
B36: 16-000 Electrical (service, power, alarm) | C36: 3260000 | D36: 24.15 | E36: 1530000 | F36: 25.08
... B42: GRAND TOTAL | C42: 40979000 | D42: 303.55 | E42: 24055464 | F42: 178.19
B44: General conditions as % of construction subtotal | C44: 7.80% | E44: 8.90%
B45: Insurance, fees & bonds as % of construction subtotal | C45: 7.11% | E45: 8.98%
B46: Construction contingency | C46: EXCLUDED | E46: EXCLUDED
B47: Builder’s risk insurance | C47: EXCLUDED | E47: EXCLUDED
B48: Labour basis | C48: Open shop, 7am-3:30pm single shift | E48: Open shop
B49: Construction duration | C49: 60 weeks of construction, 70-week active programme | E49: same
B52: WORTH SOMEONE OPENING BY HAND — SCANNED, NO TEXT CAME OUT
B53: 537 Johnson Av_Assessment of Work (09.14.16).pdf | C53: A structural assessment of an existing building on the same block. This is the closest thing to a roof-lift precedent in the folder and it is scanned, so no text came out. Reading it could confirm or kill the whole lift approach.
...

Sheet Markups Explained
B2: THE MARKUPS, EXPLAINED
B3: What each one is, who gets it, whether it is necessary, and what is actually negotiable.
B5: RESTRUCTURED. Trade cost now stands alone at $37.5M and everything else sits BELOW THE LINE as a separate cost. The three markup rates are each applied to trade cost only — they no longer compound on each other. Contractor contingency and owner contingency have been replaced by ONE $5.0M contingency, so no contingency is charged twice. A dollar of trade scope removed now saves $1.30.
B7: Line | C7: Carried | D7: Target | E7: What it is / who gets it / is it necessary | F7: What is actually negotiable
B8: Escalation | C8: 10% | D8: 6-8% | E8: WHAT IT IS: A reserve for the fact that steel, copper, switchgear and labour cost more on the day you BUY them than on the day the estimator PRICED them. It is not work. It is a bet on how much prices move between the estimate and buyout. WHO GETS IT: Nobody. You hold it. Whatever prices do not move, you keep. NECESSARY? PARTLY. It only has to cover the gap between today's estimate and the day each package is bought out. 10% implies a long gap. If you buy out the long-lead packages early it collapses. | F8: Buy out steel, switchgear, elevators and HVAC plant EARLY and lock the price. Every package you fix removes its share of this line. 6% is achievable on an early buyout.
B9: General conditions | C9: 11% | D9: 8-9% | E9: WHAT IT IS: The cost of RUNNING THE SITE, as opposed to building anything. Site superintendent, project engineer, the trailer, temporary power and water, hoisting, dumpsters, daily clean-up, scaffolding, temporary toilets, security, small tools, safety. Real people and real equipment that show up every day and put no material into the building. WHO GETS IT: The general contractor — but it is reimbursement of actual cost, not profit. On an open-book contract you can see the staffing chart behind it. NECESSARY? YES. This is cost, not margin. Somebody has to run the site. Refusing to pay it does not make it go away; it just moves into the trade prices where you cannot see it. | F9: It is DURATION-DRIVEN, not scope-driven. It is a monthly burn dressed up as a percentage. Cut three months off the programme and you cut three months of general conditions. Ask for it as a MONTHLY RATE plus a duration, not a percentage — then the number has to defend itself.
B10: Overhead, profit & insurance | C10: 9% | D10: 6-7% | E10: WHAT IT IS: Three different things bundled into one rate. OVERHEAD is the GC's head office — their estimators, accountants, rent, the people who never come to your site. PROFIT is their margin. INSURANCE is the builder's risk policy, general liability, and in New York the big one, Labor Law 240 'scaffold law' coverage, which is genuinely expensive here and is a real cost, not padding. WHO GETS IT: The general contractor. Profit is theirs to keep; insurance is a real premium they pay out; overhead funds the office. NECESSARY? YES, all three. A GC with no margin is a GC who makes it back on change orders, which is worse for you. The question is not whether, it is how much and in what form. | F10: Split it apart and price each piece. Ask for insurance as an ACTUAL PREMIUM (it is a quotable number from their broker), and overhead+profit as a FIXED FEE IN DOLLARS rather than a percentage. A fixed fee means that when scope grows, their fee does not automatically grow with it — which removes their incentive to let it grow.
B11: Contingency | C11: $5,000,000 | D11: hold it | E11: WHAT IT IS: One pot of money for what nobody can foresee yet: what is actually inside the walls and above the ceiling, what the DOB asks for on review, what the asbestos survey finds, what Con Ed says about the vault. It is NOT for scope you decide to add later — that is a budget increase, not a contingency draw. WHO GETS IT: YOU — the development entity, your team. Not Live Nation (co-pro partner, not developer) and not Eric (landlord). Unspent contingency stays yours. NECESSARY? ABSOLUTELY. This is the one line that is not optional. At $5,000,000 against $48.8M of construction cost you are carrying about 10%, which is thin for a design-stage number on a 1920s warehouse with no asbestos survey, no Con Ed feasibility letter and no structural analysis of whether the roof can be lifted at all. | F11: The RULE is negotiable, not the amount. Write down what a draw requires, who approves it, and what happens to what is left. Then draw it down deliberately as each unknown closes: the ACP-5 comes back, the Con Ed letter arrives, Rooflifters finishes Stage 3. Each one that closes clean releases money back to you.
B13: HOW IT STACKS NOW
B14: TRADE COST — the work itself | D14: ='Detailed Budget'!F473 | E14: divisions 000-500 plus 800
B15: + Escalation, 10% of trade | D15: ='Detailed Budget'!F478 | E15: on trade cost only
B16: + General conditions, 8.5% of trade | D16: ='Detailed Budget'!F479 | E16: CUT from 11% on the 555 Johnson evidence
B17: + Overhead, profit & insurance, 9% of trade | D17: ='Detailed Budget'!F480 | E17: on trade cost only
B18: CONSTRUCTION COST — the work plus its markups | D18: ='Detailed Budget'!F483 | E18: what it costs to build
B19: + Contingency | D19: ='Detailed Budget'!F485 | E19: ONE pot. Was two, stacked. Now a flat dollar figure you set
B20: + FF&E | D20: ='Detailed Budget'!F387 | E20: sound, lights, video, bars, seating, furniture
B21: + Soft costs | D21: ='Detailed Budget'!F437 | E21: design, permits, legal, project management
B22: TOTAL DEVELOPMENT COST | D22: ='Detailed Budget'!F491
B25: TWO THINGS TO UNDERSTAND BEFORE YOU CUT ANY OF THESE
B26: • | C26: CONTINGENCY IS THE ONE NOT TO CUT — and it matters MORE here than on a normal job. Eric owns the building; you are building it out and renting it. If you run out of money mid-construction you cannot pause, cannot walk away, and cannot refinance against the asset, because the improvement is already sunk into someone else's building. Every change order lands on you. $5,000,000 is about 10% of construction cost — thin for a design-stage number on a 1920s warehouse with no asbestos survey, no Con Ed feasibility letter and no structural analysis of whether the roof can be lifted at all. Do not draw it down for scope you choose to add; that is a budget increase, not a contingency draw.
B27: • | C27: THE ROOF LIFT IS THE MOST EXPENSIVE THING IN THE PROJECT. Division 100 is $7,146,288 before markups — 19% of trade cost, and roughly $9.3M of the final number once the markups are applied. $3.5M of that is your quoted lift contract; $3.6M is scope the lifter explicitly excludes. It is also mandatory, so the only two questions are whether it is a LIFT or a REPLACEMENT (a $4.9M difference) and how much of the surrounding scope is already inside the quote ($1.33M of swing). Both are answered by the same phone call.

Sheet Cut Analysis
B2: WHERE WE CAN CUT
B3: Sorted by how much it costs you to take the saving. Free money first.
B5: Read the TYPE column before the number. A FIX costs nothing. A VERIFY may vanish entirely once somebody checks. A SCOPE cut means the building is less than it was. Two rows are flagged SLA or CODE — those need a professional to sign off before they are banked.
B7: FIX — errors and overpricing. Nothing is lost.
B8: Div | C8: Item | D8: Carried | E8: Cut to | F8: Saving | G8: Gate | H8: Why, and what it costs you
B9: 500 | C9: Toilet accessories, 30 sets @ $7,500 | D9: 225000 | E9: 75000 | F9: =D9-E9 | G9: OK | H9: $7,500 per set is the dev budget's own rate but it reads as a per-RESTROOM allowance, not per fixture group. 189 fixtures across ~10 restroom groups is 10 sets, not 30. Recount off the drawings.
B10: 500 | C10: Combine existing services | D10: 200000 | E10: 0 | F10: =D10-E10 | G10: OK | H10: Only needed if you are retaining and merging the old service. With a new 5,000A service from a new vault this line is redundant. Confirm with the electrical engineer.
B11: 600 | C11: Freight & installation | D11: 375000 | E11: 250000 | F11: =D11-E11 | G11: OK | H11: Carried from FT/dev budget at $375k against a bar package now less than half the size. Scale it with the equipment.
C12: FIX subtotal | F12: =SUM(F9:F11)
B14: VERIFY — may vanish entirely once someone checks. Cheapest money on the sheet.
B15: Div | C15: Item | D15: Carried | E15: Cut to | F15: Saving | G15: Gate | H15: Why, and what it costs you
B16: 500 | C16: Generator for fire pump backup | D16: 185000 | E16: 0 | F16: =D16-E16 | G16: CODE | H16: Required only where the water supply cannot support the fire pump on utility power alone. A dedicated generator may not be needed. Ask the fire protection engineer.
B17: 000 | C17: Roofing felt & mastic abatement | D17: 555750 | E17: 0 | F17: =D17-E17 | G17: OK | H17: PRESUMED asbestos on a 1948 precast roof. Nobody has sampled it. An ACP-5 survey costs a few thousand and could delete this entire line. HIGHEST VALUE PER DOLLAR SPENT ON THIS SHEET.
B18: 100 | C18: Fire separation between zones | D18: 200000 | E18: 0 | F18: =D18-E18 | G18: CODE | H18: The lifter's own exclusion says 'if required'. A single-volume assembly space may need none. Architect to confirm.
B19: 500 | C19: HVAC — repriced on load rather than area | D19: 5205550 | E19: 4100000 | F19: =D19-E19 | G19: CODE | H19: The contractor priced $40/SF over 120,000 SF against a 74,100 SF building. Tonnage (400-500) looks right for 7,440 occupants but the COST basis does not. A real load calculation could take $1M+ out. Ask the mechanical engineer whether this was priced on load or on area.
B20: 500 | C20: Con Ed vault, conduit & feeders | D20: 850000 | E20: 850000 | F20: =D20-E20 | G20: OK | H20: My estimate with no utility quote behind it. Could go either way by several hundred thousand. Get the Con Ed feasibility letter early — it also drives the schedule.
B21: 300 | C21: Mezzanine steel at 20 lb/SF | D21: 840000 | E21: 700000 | F21: =D21-E21 | G21: CODE | H21: 20 lb/SF assumes 100 psf assembly loading throughout. If part of the mezzanine is seated rather than dense standing, the design load drops and so does the tonnage. Structural engineer to confirm.
B22: 200 | C22: Cross-span girders — bay spacing | D22: 325500 | E22: 232500 | F22: =D22-E22 | G22: ASK | H22: 7 girders at 25ft on centre. At 35ft on centre you need 5, not 7, and save $93,000. Ask the production designer whether the house plot actually needs a pick point every 25ft, or whether 35ft plus bridles covers every plot you will really hang.
B23: 200 | C23: Rigging grid vs. roof capacity | D23: 1363450 | E23: 1363450 | F23: =D23-E23 | G23: ASK | H23: DO NOT CUT THIS TO SAVE MONEY — check it against the ROOF instead. The grid is what lets the new roof stay at 15 lb/SF. If the estimator has ALSO priced a roof rated to carry rigging, you are paying twice. Confirm the roof steel is designed to carry itself and nothing else.
C24: VERIFY subtotal | F24: =SUM(F16:F23)
B26: ASK ROOFLIFTERS — may already sit inside the $3-4M quote.
B27: Div | C27: Item | D27: Carried | E27: Cut to | F27: Saving | G27: Gate | H27: Why, and what it costs you
B28: 100 | C28: Foundations for the new load path | D28: 1087650 | E28: 0 | F28: =D28-E28 | G28: ASK | H28: Ask Rooflifters whether footings and underpinning are inside the $3-4M quote. If yes, the whole group comes out.
B29: 100 | C29: Roof-to-wall closure | D29: 241643 | E29: 0 | F29: =D29-E29 | G29: ASK | H29: Ask whether the new roof/wall joint is theirs. Their scope includes 'external metal siding to enclose the building' which may already cover it.
C30: ASK ROOFLIFTERS subtotal | F30: =SUM(F28:F29)
B32: DEFER — pay later, little or no penalty.
B33: Div | C33: Item | D33: Carried | E33: Cut to | F33: Saving | G33: Gate | H33: Why, and what it costs you
B34: 600 | C34: Rent-to-buy the house PA | D34: 2200000 | E34: 0 | F34: =D34-E34 | G34: OK | H34: Defers the largest single FF&E line. NOT a saving — total cost is higher over the life of the kit. Use it for day-one cash only.
B35: 400 | C35: Entry mats & stair treads | D35: 32500 | E35: 0 | F35: =D35-E35 | G35: OK | H35: Fit-out item, no penalty for landing later.
B36: 600 | C36: Merchandise cases | D36: 26000 | E36: 0 | F36: =D36-E36 | G36: OK | H36: Furniture. Buy when the merch programme is set.
B37: 600 | C37: Office furniture | D37: 65000 | E37: 0 | F37: =D37-E37 | G37: OK | H37: Buy at fit-out, not at buyout.
B38: 500 | C38: House / architectural lighting BOH | D38: 185000 | E38: 120000 | F38: =D38-E38 | G38: OK | H38: Circulation and BOH lighting to a working standard now; decorative later.
B39: 200 | C39: Chain hoists at grid pick points | D39: 91200 | E39: 45600 | F39: =D39-E39 | G39: OK | H39: 32 motors is a full house complement. Buy 16 now, hang the rest of the points with dead-hangs, and add motors as programming demands. The STEEL is what you cannot add later; the motors you can.
C40: DEFER subtotal | F40: =SUM(F34:F39)
B42: SCOPE — real cuts. You lose something.
B43: Div | C43: Item | D43: Carried | E43: Cut to | F43: Saving | G43: Gate | H43: Why, and what it costs you
B44: 400 | C44: Decorative feature above each back bar | D44: 60000 | E44: 0 | F44: =D44-E44 | G44: OK | H44: Six decorative features at $10,000. Pure aesthetic in a room whose aesthetic is exposed structure.
B45: 400 | C45: CMU elevator tower at stage | D45: 104195 | E45: 0 | F45: =D45-E45 | G45: OK | H45: Second elevator tower. With one ADA car and a small BOH lift you do not need two masonry towers.
B46: 400 | C46: Acoustic panels — reduce coverage | D46: 1120000 | E46: 720000 | F46: =D46-E46 | G46: SLA | H46: 28,000 SF of wall panel at $40. Targeted treatment on first-reflection and rear surfaces rather than blanket coverage gets most of the acoustic benefit. RISK: this is the licence-to-operate item. Do not cut without the acoustician signing off, and do not cut the isolation or flanking control.
B47: 400 | C47: Polished concrete to sealed concrete | D47: 416000 | E47: 208000 | F47: =D47-E47 | G47: OK | H47: 52,000 SF at $8 polished vs $4 sealed. Sealed is the Infinity aesthetic anyway and it is what most of the room will be under foot traffic.
...

Sheet Options
B2: HOW TO GET THIS NUMBER DOWN
B3: Six options, stacked. Each one includes everything above it.
B5: FIRST — LOOK AT THE MARKUP STACK
B6: Trade cost is $37.5M. Below the line sits $27.2M more — $11.3M of markups, a $5.0M contingency, $5.6M of FF&E and $5.4M of soft costs. The three markup RATES total 30% of trade cost and buy you no work at all, so every point negotiated off them is free money. Nothing here costs you scope.
B8: Rate | C8: As carried | D8: Target | E8: Worth | G8: Why the target is reasonable
B9: Escalation | C9: 0.1 | D9: 0.06 | E9: 1500053 | G9: 10% assumes a long gap between estimate and buyout. Buy out steel, switchgear, elevators and HVAC plant early and lock the price.
B10: General conditions | C10: 0.085 | D10: 0.078 | E10: 286246 | G10: ALREADY CUT from 11% to 8.5% on the Schimenti evidence. 7.80% is what he actually charged Eric on the full 555 Johnson scheme, so there is one more point in it.
B11: Overhead, profit & insurance | C11: 0.09 | D11: 0.065 | E11: 937533 | G11: Split it apart: insurance as an actual broker premium, overhead and profit as a FIXED FEE IN DOLLARS so it does not grow when scope grows.
B12: Total available on rates alone | E12: =SUM(E9:E11)
B14: THE SIX OPTIONS
B15: Option | C15: Total | D15: $/SF | E15: $/cap | F15: Step | G15: What it costs you
B16: 0. As it stands | C16: 73962877 | D16: 998 | E16: 9941 | G16: —
B17: 1. Take the free cuts | C17: 67244411 | D17: 907 | E17: 9038 | F17: -6718466 | G17: Nothing. Asbestos survey, Rooflifters answers, HVAC load basis, two arithmetic errors.
B18: 2. + negotiate the markups | C18: 59130282 | D18: 798 | E18: 7948 | F18: -8114129 | G18: Nothing in scope. Open-book GMP with shared savings, earlier buyout, contingency to 12%. THIS IS THE TARGET.
B19: 3. + landlord funds the roof lift | C19: 48836545 | D19: 659 | E19: 6564 | F19: -10293737 | G19: Negotiating capital with Eric. The lift is a permanent improvement to his building that outlives a 20-year lease.
B20: 4. + drop the lift 50ft to 40ft | C20: 46900000 | D20: 633 | E20: 6304 | F20: -1936545 | G20: THE MOAT. Not recommended — shown only so the number is visible. At 40 ft you lose flown production and the positioning argument.
B21: 5. + defer the mezzanine | C21: 43900000 | D21: 592 | E21: 8442 | F21: -3000000 | G21: 2,240 capacity and the compliance seating location. Opens floor-only at ~5,200. Structure must still go in later at a premium.
B22: 6. + owner-furnish, direct trades | C22: 40300000 | D22: 544 | E22: 7750 | F22: -3600000 | G22: Delivery risk moves to you. Buy switchgear, HVAC plant and elevators direct; fewer trades under GC markup.
B24: RECOMMENDED: Option 2 at $59.1M. It costs nothing in scope — it is arithmetic corrections, evidence-gathering and contract structure. Options 3 through 6 all trade something real away, and Option 4 trades the moat.

Sheet Questions to Ask
B2: QUESTIONS
B3: 49 questions, by who to ask. Each carries the evidence that makes it hard to deflect.
B5: ESTIMATOR / GENERAL CONTRACTOR
B6: No. | C6: Question | D6: Why it is hard to deflect | E6: $ at stake
B7: 1 | C7: The $1,000,000 black steel mounting structure at the stage — does that number include ANY steel spanning out over the crowd, or does it stop at the stage line? | D7: It is a one-line lump sum with no take-off behind it. Either it covers the room or it does not, and he has to say which. We are now carrying a separate $1,363,450 rigging grid over the crowd; if his $1M already reaches out over the floor, one of those two numbers comes out. | E7: 1363450
B8: 2 | C8: Is the new roof steel designed to carry ITSELF ONLY, or have you rated it to carry rigging as well? | D8: The whole logic of the ground-supported grid is that nothing hangs from the building. If he has also rated the roof for rigging load he has bought the same capacity twice. At 74,100 SF the difference between 15 lb/SF and 20 lb/SF is 185 tons of steel. | E8: 1110000
B9: 3 | C9: Can the rigging grid be erected during the roof-off window, picked straight down through the opening? | D9: Erecting 74 tons of steel by chain hoist inside a closed, finished room is a different price from craning it in from above. This is a sequencing decision that has to be made before the roof closes — after that it is not available at any price. | E9: 185000
B10: 4 | C10: Roughly two-thirds of your trade schedule carries a unit price against a QUANTITY OF ZERO. When are those quantities going in, and what is your own estimate of the total once they are? | D10: Structural steel is $0 on a project whose scope line reads 'Add Second Level'. Acoustic panels are $0 in a music venue. Millwork, doors, painting, fireproofing, tile — all $0. | E10: the whole estimate
B11: 5 | C11: Roofing row 193 prices 1,592 SF of pavers at $3,312.50/SF. The lines directly above and below, same product, are $31/SF. Is that an error? | D11: One cell. Marked up through 9% OH&P, 10% contractor contingency and 10% owner contingency. | E11: $6,890,129
B12: 6 | C12: Your escalation line for Building & Fit-Out is blank. The off-site parking garage carries 5%. Why the difference? | D12: The line exists in your file and was left empty. | E12: $3,591,389
B13: 7 | C13: Your abatement line is $8,750. Your demolition schedule says 74,000 SF of precast roof, 'abatement by others'. Who is 'others', and what have they quoted? | D13: 1948 building. 'By others' is not a scope exclusion the owner gets to keep — someone pays it. | E13: $555,750
B14: 8 | C14: You price HVAC at $40/SF over 120,000 SF. The building is 74,100 SF. Was this priced from a load calculation or from an area assumption? | D14: The tonnage may well be right. The pricing BASIS is applied to 62% more area than exists. | E14: $1,100,000+
B15: 9 | C15: Your electrical division is $558,750 and contains two switchboards, temporary power and firestopping. Where are the panels, secondary distribution and branch wiring? | D15: Every distribution line in your file is quantity zero. Nothing can plug in. | E15: $3,400,000+
B16: 10 | C16: What construction duration are your general conditions priced for? | D16: The only duration stated anywhere in your file is 60 weeks of portable toilets — about 14 months. The underwriting assumes 24. | E16: $1,200,000
B17: 11 | C17: Your summary carries General Conditions at $2,000,000. Your own hidden General Conditions tab totals $2,082,000. Which is right? | D17: Both numbers are in the file you sent. | E17: $82,000
B18: 12 | C18: You carry 9% overhead, profit and insurance plus a 10% contractor contingency you keep. Will you go open-book with a shared-savings split on unspent contingency? | D18: A fixed OH&P plus a retained contingency gives you no reason to underspend it. | E18: $2,400,000
B19: 13 | C19: Committed Costs, Invoices and Change Orders are all zero. Nothing has been bought. What would a competitive three-bid process return against this estimate? | D19: 5-10% is normal against a first-pass estimate in this market. | E19: $1,800,000-3,600,000
B20: 14 | C20: Your Project At-a-Glance and Project Summary tabs are broken with #REF!, the cost report is dated 2023-01-31 and the contingency log says March 2020. Is this built on a template from another project? | D20: It matters because the cost-control apparatus is not actually wired to this job. | E20: governance
B21: 15 | C21: Your Risk Report is empty and exposure is $0. Where do you carry the pending Phase I, the pending structural and MEP assessment, the pending Certificate of Occupancy and the pending FDNY approval? | D21: Those are the four largest uncertainties on the project and none of them appear in your risk register. | E21: governance
... B23: 17 | C23: Owner's project management is $520,000 — 1.2% of project cost against a 2-4% norm. Is that a real number or a placeholder? | D23: Under-resourced PM is how change orders get approved without challenge. | E23: $600,000
B25: ARCHITECT (Wake)
B26: No. | C26: Question | D26: Why it is hard to deflect | E26: $ at stake
B27: 18 | C27: Does the theater use-classification require seating on a specific floor, fixed or removable, and at what count? | D27: It carries the liquor licence and the cabaret licence. Everything downstream depends on the answer. | E27: $3,156,738
B28: 19 | C28: Do we actually need four levels? What does the classification require, as opposed to what the test fit proposes? | D28: Every added level multiplies accessible routes, egress stairs, vertical circulation and fire separation. | E28: $1,800,000-2,000,000
B29: 20 | C29: What is the EGRESS-driven capacity, as distinct from the area-driven capacity? | D29: Egress caps the room, not floor area. The mezzanine is already egress-capped at 2,240. | E29: capacity
B30: 21 | C30: Your test fit shows 3,714 seated at 7 SF/occ and 5,200 standing at 5 SF/occ. Does that make the floor 26,000 SF and the mezzanine 14,000 SF? | D30: We derived those areas from your own occupancy loads. Confirm or correct them. | E30: $1,851,016
B31: 22 | C31: Is the roof-deck, restaurant and VIP-lounge programme a client requirement or a design proposal? | D31: It is priced as though it were a requirement. If it is a proposal it can be deferred or deleted. | E31: $1,300,000+
B32: 23 | C32: Do your drawings assume a roof LIFT or a roof REPLACEMENT? | D32: The development budget schedules 74,000 SF of precast roof for demolition, which is a replacement. A lift keeps the roof. | E32: $4,947,067
B33: 24 | C33: What is the filing critical path, and which approval gates the Temporary Certificate of Occupancy? | D33: We need the sequence, not a fee proposal. DOB structural approval alone is 12-18 months. | E33: schedule
B34: 25 | C34: What fire separation between zones is actually required? | D34: Rooflifters excludes it 'if required'. Nobody has said whether it is. | E34: $200,000
B35: 26 | C35: Confirm the plumbing fixture calculation. The budget carries 189; the underwriting assumed 100. | D35: It is set by occupant load and occupancy group, so there is a right answer. | E35: $489,500
B36: 27 | C36: Your fee is $2,200,000 with MEP and structural engineering folded into one line. Can we see the breakdown by discipline? | D36: Factory Town's architect ran 3.9x its approved budget. We would like to see the shape of this one. | E36: $2,200,000
B37: 28 | C37: Does the acoustic treatment need blanket coverage, or targeted treatment on first-reflection and rear surfaces? | D37: 28,000 SF of wall panel at $40/SF is the assumption. It is also the licence-to-operate item, so we will not cut it without you. | E37: $400,000
B39: MECHANICAL ENGINEER
B40: No. | C40: Question | D40: Why it is hard to deflect | E40: $ at stake
B41: 29 | C41: What is the calculated cooling load in tons, from a real load calculation? | D41: 7,440 occupants alone are roughly 250 tons. We need the number, not a $/SF proxy. | E41: $1,100,000+
B42: 30 | C42: Do we need a building management system at $500,000, or will simpler controls serve a single-volume assembly space? | D42: A BMS is sized for a building with many zones. This is one big room. | E42: $250,000
B43: 31 | C43: Is mechanical smoke control required at this volume and height, and what does it cost? | D43: We carry $420,000 as an estimate. It is a code question with a definite answer. | E43: $420,000
B44: 32 | C44: What is the heating strategy at a 50 ft ceiling, and is radiant the right call? | D44: There is NO heating scope in the contractor's budget at all. | E44: $815,100
B45: 33 | C45: Does the mezzanine add conditioned volume, or only occupants and air distribution? | D45: It sits inside the existing envelope. It should be a minimal uplift, not a new building. | E45: $638,120
...

Sheet Thomas Reconciliation
B2: THOMAS’S BUDGET — EVERY LINE, RECONCILED
B3: All 199 trade lines from the Master Development Budget dated 7 Sep 2026. Nothing dropped.
B5: GENERAL CONDITIONS — PICK ONE, NOT BOTH | F5: GC line items | G5: =SUMIF(I9:I238,"GC*",G9:G238) | I5: Thomas carries $1,696,000 of general conditions as TRADE LINES (013000 + 015800: site office, site security, safety plan, portable toilets, clean-up, rubbish, final clean, project labour, field technology). We also apply an 11%% general conditions markup on trade cost, which is $4,125,146. THAT IS THE SAME SITE COST TWICE. The toggle at the top of the Detailed Budget picks one: 1 = the percentage, 0 = his line items. His line items are $2,429,146 CHEAPER — but they are also incomplete, since all of 015800 sits at qty 0.
B6: ADD-BACKS TOGGLED ON | G6: =SUM(J9:J238) | I6: Live total of every non-GC line whose toggle is 1. Feeds the Detailed Budget below the line. Default is zero.
B8: CSI | C8: Description | D8: Qty | E8: Unit | F8: His rate | G8: His total | H8: ON=1 | I8: Status — where it lands in this model / why it is off
B9: 013000 PROJECT REQUIREMENTS
B10: 013000 | C10: 1. BIM Set Up & Coordination | D10: 1 | E10: LS | F10: 30000 | G10: 30000 | H10: 0 | I10: GC — GENERAL CONDITIONS CONTENT — see the master toggle above | J10: 0
B11: 013000 | C11: 2. Plans / Reprographics | D11: 1 | E11: LS | F11: 7500 | G11: 7500 | H11: 0 | I11: GC — GENERAL CONDITIONS CONTENT — see the master toggle above | J11: 0
B12: 013000 | C12: 3. Site Office & Equipment | D12: 1 | E12: LS | F12: 12000 | G12: 12000 | H12: 0 | I12: GC — GENERAL CONDITIONS CONTENT — see the master toggle above | J12: 0
B13: 013000 | C13: 4. Field Techonology | D13: 1 | E13: LS | F13: 200000 | G13: 200000 | H13: 0 | I13: GC — $200,000 of "field technology" is a general conditions item and a big one. Ask what it actually buys — Procore licences and a few tablets are not $200,000. | J13: 0
B14: 013000 | C14: 5. Construction Signage | D14: 1 | E14: LS | F14: 4500 | G14: 4500 | H14: 0 | I14: GC — GENERAL CONDITIONS CONTENT — see the master toggle above | J14: 0
B15: 013000 | C15: 6. Site Security | D15: 1 | E15: LS | F15: 13000 | G15: 13000 | H15: 0 | I15: GC — GENERAL CONDITIONS CONTENT — see the master toggle above | J15: 0
B16: 013000 | C16: 7. Site Safety Plan / First Aid / TPP / FE's / Safety Inspector | D16: 1 | E16: LS | F16: 250000 | G16: 250000 | H16: 0 | I16: GC — $250,000. NYC site safety is real and required, but it belongs in general conditions, not on top of a general conditions percentage. | J16: 0
B17: 013000 | C17: 8. Portable Toilets | D17: 60 | E17: WK | F17: 400 | G17: 24000 | H17: 0 | I17: GC — GENERAL CONDITIONS CONTENT — see the master toggle above | J17: 0
B18: 013000 | C18: 9. Clean up Materials | D18: 1 | E18: LS | F18: 45000 | G18: 45000 | H18: 0 | I18: GC — GENERAL CONDITIONS CONTENT — see the master toggle above | J18: 0
B19: 013000 | C19: 10. Protection Materials | D19: 1 | E19: LS | F19: 50000 | G19: 50000 | H19: 0 | I19: GC — GENERAL CONDITIONS CONTENT — see the master toggle above | J19: 0
B20: 013000 | C20: 11. Project Labor | D20: 1 | E20: LS | F20: 900000 | G20: 900000 | H20: 0 | I20: GC — $900,000 of "project labor" is the single largest general conditions line. This is GC labour on site. It is exactly what the 11% markup is for. Do not pay both. | J20: 0
B21: 013000 | C21: 12. Project Rubbish Removals | D21: 1 | E21: LS | F21: 60000 | G21: 60000 | H21: 0 | I21: GC — GENERAL CONDITIONS CONTENT — see the master toggle above | J21: 0
B22: 013000 | C22: 13. Final Clean | D22: 1 | E22: LS | F22: 100000 | G22: 100000 | H22: 0 | I22: GC — GENERAL CONDITIONS CONTENT — see the master toggle above | J22: 0
B23: 015800 SCAFFOLDING & HOARDING
B24: 015800 | C24: 1. Install sidewalk bridge around building | D24: 0 | E24: LS | F24: 250000 | G24: 0 | H24: 0 | I24: IN — Div 000 — we price the shed at $210/LF over 1,089 LF plus 24 months of rental, which is a build-up rather than his $250,000 lump. Ours is the more defensible number. | J24: =H24*G24
B25: 015800 | C25: 2. Roof Protection/Barriers after Demo of roof | D25: 0 | E25: LS | F25: 50000 | G25: 0 | H25: 0 | I25: GC — GENERAL CONDITIONS CONTENT — see the master toggle above | J25: 0
B26: 015800 | C26: 3. Site safety During Erection | D26: 0 | E26: LS | F26: 20000 | G26: 0 | H26: 0 | I26: GC — GENERAL CONDITIONS CONTENT — see the master toggle above | J26: 0
B27: 024100 DEMOLITION
B28: 024100 | C28: 1. Demo existing asonry walls at New Entry/Lobby area | D28: 2500 | E28: SF | F28: 12 | G28: 30000 | H28: 0 | I28: IN — Div 000 — Demolition, interior | J28: =H28*G28
B29: 024100 | C29: 1. Demo existing windows 1'x10' | D29: 34 | E29: EA | F29: 12 | G29: 408 | H29: 0 | I29: IN — Div 000 — Demolition, interior | J29: =H29*G29
B30: 024100 | C30: 2. Demo. Misc. Build out scattered thru out, e.g. piping, CMU, walls | D30: 0 | E30: SF | F30: 2 | G30: 0 | H30: 0 | I30: IN — Div 000 — Demolition, interior | J30: =H30*G30
B31: 024100 | C31: 3. Demo. Roofing, deck & framing to create new elevated roof area at Music Hall | D31: 0 | E31: SF | F31: 15 | G31: 0 | H31: 0 | I31: IN — Div 000 — Demolition, interior | J31: =H31*G31
B32: 024100 | C32: 4. Demo Floor for New Structural Columns/Footings | D32: 0 | E32: SF | F32: 10 | G32: 0 | H32: 0 | I32: IN — Div 000 — Demolition, interior | J32: =H32*G32
B33: 024100 | C33: 5. Allow for Floor trenching for MEPS | D33: 0 | E33: LS | F33: 50000 | G33: 0 | H33: 0 | I33: IN — Div 000 — Demolition, interior | J33: =H33*G33
B34: 024100 | C34: 6. Demo floor for Recessed floor - Include Excavation | D34: 0 | E34: SF | F34: 0 | G34: 0 | H34: 0 | I34: IN — Div 000 — Demolition, interior [his note: Included Above] | J34: =H34*G34
B35: 024100 | C35: 7. Misc Façade Demo Along Johnson Ave (Doors, Roll-ups, Windows, etc.) | D35: 0 | E35: LS | F35: 20000 | G35: 0 | H35: 0 | I35: IN — Div 000 — Demolition, interior | J35: =H35*G35
B36: 033000 CONCRETE
B37: 033000 | C37: 1. Excavation related to New Columns at Music hall | D37: 0 | E37: SF | F37: 6.5 | G37: 0 | H37: 0 | I37: IN — Div 200/300 foundations + Div 000 sitework [his note: Based on Footprint of New Roof] | J37: =H37*G37
B38: 033000 | C38: 2. CMU wall footing excavation allow 2' deep for new Load bearing wall at Music hall- East wall | D38: 0 | E38: LF | F38: 150 | G38: 0 | H38: 0 | I38: IN — Div 200/300 foundations + Div 000 sitework | J38: =H38*G38
B39: 033000 | C39: 3. Concrete at New footings | D39: 0 | E39: EA | F39: 7500 | G39: 0 | H39: 0 | I39: IN — Div 200/300 foundations + Div 000 sitework | J39: =H39*G39
B40: 033000 | C40: 4. Concrete at CMU footing | D40: 0 | E40: LF | F40: 100 | G40: 0 | H40: 0 | I40: IN — Div 200/300 foundations + Div 000 sitework | J40: =H40*G40
B41: 033000 | C41: 5. Patch slab due to New footing | D41: 0 | E41: SF | F41: 30 | G41: 0 | H41: 0 | I41: IN — Div 200/300 foundations + Div 000 sitework | J41: =H41*G41
B42: 033000 | C42: 6. Patch conc. At Trenching for MEPS | D42: 0 | E42: SF | F42: 30 | G42: 0 | H42: 0 | I42: IN — Div 200/300 foundations + Div 000 sitework | J42: =H42*G42
B43: 033000 | C43: 7. New slab Pour-back at Excavated Areas | D43: 0 | E43: SF | F43: 30 | G43: 0 | H43: 0 | I43: IN — Div 200/300 foundations + Div 000 sitework | J43: =H43*G43
...
