Workbook

Sheet Read Me
B2: 165 RANDOLPH STREET — COST TO BUILD & OPEN
B3: Brooklyn, NY 11237 · Live Nation / Insomniac · CONSTRUCTION ONLY · CONFIDENTIAL
B5: Scope of this model | C5: Construction only: building the building, the production systems, getting it coded, and getting the liquor licence. No revenue, no operating costs, no returns — 165 Randolph has its own revenue model and this does not duplicate it.
B6: The question it answers | C6: What is the least we can spend and still open the doors, and what does every additional item cost on top of that?
B7: Why the filed budget cannot answer it | C7: The Master Development Budget v1 totals $42,555,099. One cell overstates it by $5,224,148 — 3rd-floor VIP pavers at $3,312.50/SF where the lines above and below are $31/SF — which marks up four times to $6,890,129. Meanwhile roughly two-thirds of the trade schedule carries a unit price against a QUANTITY OF ZERO. The two errors point opposite ways and roughly cancel, which is why the total looked plausible next to the $45M underwriting case.
B8: How to use it | C8: Open Line Build. Every one of the 101 lines carries a TIER. Change a tier and all four scenarios on Scenario Summary recalculate. Blue cells are inputs you can edit, black cells are formulas, green cells pull from another sheet. The Reconciliation block at the bottom of Line Build proves the "As Filed" column ties to the source workbook to the dollar.
B10: THE TIERS
B11: Tier 0 — Shell & Life Safety | C11: No Certificate of Occupancy without it. Structure, egress, fire protection and alarm, MEP, ADA, abatement, code compliance.
B12: Tier 1 — Revenue Enabling | C12: Cannot sell a ticket or serve a drink without it. Stage and rigging steel, bars, audio, performance lighting, acoustic treatment, screening, IT.
B13: Tier R — Roof Raise — the fork | C13: The 20ft to 50ft lift. Priced at ZERO in the filed budget. Drives the production ceiling and the premium positioning. It does NOT drive capacity — 7,440 works at either height.
B14: Tier 2 — Positioning / Phase 2 | C14: The building opens and trades without it. Roof decks, restaurant, VIP fit-out, LED walls, architectural lighting, art, parking garage.
B16: THE FOUR SCENARIOS
B17: 1. Absolute Floor | C17: Tiers 0 + 1, roof left alone, and the three rent-or-free items deferred (house audio, performance lighting, POS). The lowest number that still opens the doors.
B18: 2. Open Minimum | C18: Tiers 0 + 1, roof left alone. Own the audio and lighting rig from day one rather than renting it.
B19: 3. Open + 50ft Raise | C19: Scenario 2 plus Tier R. This is the building the underwriting describes.
B20: 4. Full Scope | C20: Everything — roof decks, restaurant, VIP lounge, LED walls, architectural lighting and the parking garage.
B22: Basis of the Corrected column | C22: Where the source file supplies a unit price, the corrected cost uses THAT rate against a measured or reasoned quantity — so most of this is the estimator's own pricing, applied to quantities that were left at zero. Where the file gives no rate, the figure comes from NYC assembly-occupancy norms and the line note says so. Where MT supplied a better number in the annotated copy, MT's number is used and cited.
B23: Explicitly excluded | C23: Revenue of any kind. Operating costs. Returns and IRR. Rent, NNN and lease economics. Pre-opening hiring, training and launch marketing. Anything from the Miami takeover folder or the Ace Mission analysis — neither was available. The Wake PD04 Rev 4.4 test fit has not been reviewed directly.
B25: Prepared 9 Sep 2026 from Master Development Budget v1 (7 Sep 2026) and MT notes & questions.

Sheet Scenario Summary
B2: WHAT IT COSTS TO BUILD AND OPEN
B3: Construction, production, code and liquor licence. Driven entirely by the Tier column on Line Build.
B5: ASSUMPTIONS — edit the yellow cells
B6: General conditions, % of trade + escalation | C6: 0.11 | G6: Filed $2,000,000 against $18,175,108 of trade. The hidden GC tab totals $2,082,000 — an $82k break.
B7: Overhead, profit & insurance, % of trade + GC | C7: 0.09 | G7: As filed (9% combined).
B8: Contractor contingency, % | C8: 0.1 | G8: As filed.
B9: Owner contingency, % | C9: 0.1 | G9: As filed. 25-35% is the norm at this design stage with this much scope unpriced. Raise it to test.
B10: Escalation on trade cost, % | C10: 0.1 | G10: FILED AT ZERO — the line exists and was left blank while the parking garage got 5%. 5%/yr across a 2-year build.
B11: Building footprint (SF, under roof) | C11: 74100 | G11: YOUR CORRECTION. The rent basis, and what roofing, envelope and HVAC volume follow. The mezzanine sits inside this.
B12: Total floor area, all levels (SF) | C12: 135953 | G12: What sprinklers, fire alarm, partitions and flooring follow. The dev budget uses this as its headline SF, which is why it reports $313/SF.
B13: Capacity, GA standing | C13: 7440 | G13: Development budget and Wake test fit. Ground floor plus mezzanine, within the 74,100 SF footprint.
B15: THE LADDER
C16: SHELL & CODE tier 0 only, no lift | D16: BASE shell + revenue, no lift | E16: BASE + LIFT shell + revenue + lift | F16: ELEVATED full fit-out + lift | G16: PREMIUM everything
B17: Trade costs | C17: =SUMIFS('Line Build'!$I$2:$I$103,'Line Build'!$B$2:$B$103,$J17,'Line Build'!$D$2:$D$103,"0") | D17: =SUMIFS('Line Build'!$I$2:$I$103,'Line Build'!$B$2:$B$103,$J17,'Line Build'!$D$2:$D$103,"0")+SUMIFS('Line Build'!$I$2:$I$103,'Line Build'!$B$2:$B$103,$J17,'Line Build'!$D$2:$D$103,"1") | E17: =SUMIFS('Line Build'!$I$2:$I$103,'Line Build'!$B$2:$B$103,$J17,'Line Build'!$D$2:$D$103,"0")+SUMIFS('Line Build'!$I$2:$I$103,'Line Build'!$B$2:$B$103,$J17,'Line Build'!$D$2:$D$103,"1")+SUMIFS('Line Build'!$I$2:$I$103,'Line Build'!$B$2:$B$103,$J17,'Line Build'!$D$2:$D$103,"R") | F17: =SUMIFS('Line Build'!$H$2:$H$103,'Line Build'!$B$2:$B$103,$J17,'Line Build'!$D$2:$D$103,"0")+SUMIFS('Line Build'!$H$2:$H$103,'Line Build'!$B$2:$B$103,$J17,'Line Build'!$D$2:$D$103,"1")+SUMIFS('Line Build'!$H$2:$H$103,'Line Build'!$B$2:$B$103,$J17,'Line Build'!$D$2:$D$103,"R") | G17: =SUMIFS('Line Build'!$H$2:$H$103,'Line Build'!$B$2:$B$103,$J17,'Line Build'!$D$2:$D$103,"0")+SUMIFS('Line Build'!$H$2:$H$103,'Line Build'!$B$2:$B$103,$J17,'Line Build'!$D$2:$D$103,"1")+SUMIFS('Line Build'!$H$2:$H$103,'Line Build'!$B$2:$B$103,$J17,'Line Build'!$D$2:$D$103,"R")+SUMIFS('Line Build'!$H$2:$H$103,'Line Build'!$B$2:$B$103,$J17,'Line Build'!$D$2:$D$103,"2") | J17: TRADE
B18: Off-site costs | C18: =SUMIFS('Line Build'!$I$2:$I$103,'Line Build'!$B$2:$B$103,$J18,'Line Build'!$D$2:$D$103,"0") | D18: =SUMIFS('Line Build'!$I$2:$I$103,'Line Build'!$B$2:$B$103,$J18,'Line Build'!$D$2:$D$103,"0")+SUMIFS('Line Build'!$I$2:$I$103,'Line Build'!$B$2:$B$103,$J18,'Line Build'!$D$2:$D$103,"1") | E18: =SUMIFS('Line Build'!$I$2:$I$103,'Line Build'!$B$2:$B$103,$J18,'Line Build'!$D$2:$D$103,"0")+SUMIFS('Line Build'!$I$2:$I$103,'Line Build'!$B$2:$B$103,$J18,'Line Build'!$D$2:$D$103,"1")+SUMIFS('Line Build'!$I$2:$I$103,'Line Build'!$B$2:$B$103,$J18,'Line Build'!$D$2:$D$103,"R") | F18: =SUMIFS('Line Build'!$H$2:$H$103,'Line Build'!$B$2:$B$103,$J18,'Line Build'!$D$2:$D$103,"0")+SUMIFS('Line Build'!$H$2:$H$103,'Line Build'!$B$2:$B$103,$J18,'Line Build'!$D$2:$D$103,"1")+SUMIFS('Line Build'!$H$2:$H$103,'Line Build'!$B$2:$B$103,$J18,'Line Build'!$D$2:$D$103,"R") | G18: =SUMIFS('Line Build'!$H$2:$H$103,'Line Build'!$B$2:$B$103,$J18,'Line Build'!$D$2:$D$103,"0")+SUMIFS('Line Build'!$H$2:$H$103,'Line Build'!$B$2:$B$103,$J18,'Line Build'!$D$2:$D$103,"1")+SUMIFS('Line Build'!$H$2:$H$103,'Line Build'!$B$2:$B$103,$J18,'Line Build'!$D$2:$D$103,"R")+SUMIFS('Line Build'!$H$2:$H$103,'Line Build'!$B$2:$B$103,$J18,'Line Build'!$D$2:$D$103,"2") | J18: OFFSITE
B19: Soft costs | C19: =SUMIFS('Line Build'!$I$2:$I$103,'Line Build'!$B$2:$B$103,$J19,'Line Build'!$D$2:$D$103,"0") | D19: =SUMIFS('Line Build'!$I$2:$I$103,'Line Build'!$B$2:$B$103,$J19,'Line Build'!$D$2:$D$103,"0")+SUMIFS('Line Build'!$I$2:$I$103,'Line Build'!$B$2:$B$103,$J19,'Line Build'!$D$2:$D$103,"1") | E19: =SUMIFS('Line Build'!$I$2:$I$103,'Line Build'!$B$2:$B$103,$J19,'Line Build'!$D$2:$D$103,"0")+SUMIFS('Line Build'!$I$2:$I$103,'Line Build'!$B$2:$B$103,$J19,'Line Build'!$D$2:$D$103,"1")+SUMIFS('Line Build'!$I$2:$I$103,'Line Build'!$B$2:$B$103,$J19,'Line Build'!$D$2:$D$103,"R") | F19: =SUMIFS('Line Build'!$H$2:$H$103,'Line Build'!$B$2:$B$103,$J19,'Line Build'!$D$2:$D$103,"0")+SUMIFS('Line Build'!$H$2:$H$103,'Line Build'!$B$2:$B$103,$J19,'Line Build'!$D$2:$D$103,"1")+SUMIFS('Line Build'!$H$2:$H$103,'Line Build'!$B$2:$B$103,$J19,'Line Build'!$D$2:$D$103,"R") | G19: =SUMIFS('Line Build'!$H$2:$H$103,'Line Build'!$B$2:$B$103,$J19,'Line Build'!$D$2:$D$103,"0")+SUMIFS('Line Build'!$H$2:$H$103,'Line Build'!$B$2:$B$103,$J19,'Line Build'!$D$2:$D$103,"1")+SUMIFS('Line Build'!$H$2:$H$103,'Line Build'!$B$2:$B$103,$J19,'Line Build'!$D$2:$D$103,"R")+SUMIFS('Line Build'!$H$2:$H$103,'Line Build'!$B$2:$B$103,$J19,'Line Build'!$D$2:$D$103,"2") | J19: SOFT
B20: FF&E | C20: =SUMIFS('Line Build'!$I$2:$I$103,'Line Build'!$B$2:$B$103,$J20,'Line Build'!$D$2:$D$103,"0") | D20: =SUMIFS('Line Build'!$I$2:$I$103,'Line Build'!$B$2:$B$103,$J20,'Line Build'!$D$2:$D$103,"0")+SUMIFS('Line Build'!$I$2:$I$103,'Line Build'!$B$2:$B$103,$J20,'Line Build'!$D$2:$D$103,"1") | E20: =SUMIFS('Line Build'!$I$2:$I$103,'Line Build'!$B$2:$B$103,$J20,'Line Build'!$D$2:$D$103,"0")+SUMIFS('Line Build'!$I$2:$I$103,'Line Build'!$B$2:$B$103,$J20,'Line Build'!$D$2:$D$103,"1")+SUMIFS('Line Build'!$I$2:$I$103,'Line Build'!$B$2:$B$103,$J20,'Line Build'!$D$2:$D$103,"R") | F20: =SUMIFS('Line Build'!$H$2:$H$103,'Line Build'!$B$2:$B$103,$J20,'Line Build'!$D$2:$D$103,"0")+SUMIFS('Line Build'!$H$2:$H$103,'Line Build'!$B$2:$B$103,$J20,'Line Build'!$D$2:$D$103,"1")+SUMIFS('Line Build'!$H$2:$H$103,'Line Build'!$B$2:$B$103,$J20,'Line Build'!$D$2:$D$103,"R") | G20: =SUMIFS('Line Build'!$H$2:$H$103,'Line Build'!$B$2:$B$103,$J20,'Line Build'!$D$2:$D$103,"0")+SUMIFS('Line Build'!$H$2:$H$103,'Line Build'!$B$2:$B$103,$J20,'Line Build'!$D$2:$D$103,"1")+SUMIFS('Line Build'!$H$2:$H$103,'Line Build'!$B$2:$B$103,$J20,'Line Build'!$D$2:$D$103,"R")+SUMIFS('Line Build'!$H$2:$H$103,'Line Build'!$B$2:$B$103,$J20,'Line Build'!$D$2:$D$103,"2") | J20: FFE
B21: Escalation on trade cost | C21: =C17*$C$10 | D21: =D17*$C$10 | E21: =E17*$C$10 | F21: =F17*$C$10 | G21: =G17*$C$10
B22: General conditions | C22: =(C17+C21)*$C$6 | D22: =(D17+D21)*$C$6 | E22: =(E17+E21)*$C$6 | F22: =(F17+F21)*$C$6 | G22: =(G17+G21)*$C$6
B23: Overhead, profit & insurance | C23: =(C17+C21+C22)*$C$7 | D23: =(D17+D21+D22)*$C$7 | E23: =(E17+E21+E22)*$C$7 | F23: =(F17+F21+F22)*$C$7 | G23: =(G17+G21+G22)*$C$7
B24: Contractor contingency | C24: =(C17+C21+C22+C23)*$C$8 | D24: =(D17+D21+D22+D23)*$C$8 | E24: =(E17+E21+E22+E23)*$C$8 | F24: =(F17+F21+F22+F23)*$C$8 | G24: =(G17+G21+G22+G23)*$C$8
B25: Subtotal before owner contingency | C25: =C17+C18+C19+C20+C21+C22+C23+C24 | D25: =D17+D18+D19+D20+D21+D22+D23+D24 | E25: =E17+E18+E19+E20+E21+E22+E23+E24 | F25: =F17+F18+F19+F20+F21+F22+F23+F24 | G25: =G17+G18+G19+G20+G21+G22+G23+G24
B26: Owner contingency | C26: =C25*$C$9 | D26: =D25*$C$9 | E26: =E25*$C$9 | F26: =F25*$C$9 | G26: =G25*$C$9
B27: TOTAL CAPITAL COST | C27: =C25+C26 | D27: =D25+D26 | E27: =E25+E26 | F27: =F25+F26 | G27: =G25+G26
B29: Cost per SF — on 74,100 footprint | C29: =C27/$C$11 | D29: =D27/$C$11 | E29: =E27/$C$11 | F29: =F27/$C$11 | G29: =G27/$C$11
B30: Cost per SF — on all floor area | C30: =C27/$C$12 | D30: =D27/$C$12 | E30: =E27/$C$12 | F30: =F27/$C$12 | G30: =G27/$C$12
B31: Cost per capacity unit | C31: =C27/$C$13 | D31: =D27/$C$13 | E31: =E27/$C$13 | F31: =F27/$C$13 | G31: =G27/$C$13
B32: Step up from the scenario to its left | C32: ="—" | D32: =D27-BO27 | E32: =E27-BP27 | F32: =F27-BQ27 | G32: =G27-BR27
B34: MEMO — for comparison
B35: Master Development Budget v1, as filed | C35: 42555099 | G35: Contains the $5.22M paver error and ~2/3 of trades at zero quantity. Not a usable number.
B36: Same budget, paver error corrected only | C36: 35664970 | G36: What the filed schedule actually prices, before any missing scope is added back.
B37: Underwriting base case | C37: 45000000 | G37: Of which $12,280,860 — 27.3% — was explicitly unallocated scope on its own reconciliation line.
B38: Underwriting high case | C38: 65000000
B40: THE POINT | C40: =("Shell and code alone is "&TEXT(C27,"$#,##0")&". Adding what it takes to trade brings it to "&TEXT(D27,"$#,##0")&". The lift adds "&TEXT(E27-D27,"$#,##0")&".")
B42: WHAT EACH STEP BUYS
B43: • | C43: SHELL & CODE — the building exists and passes code, and nothing more. Structure, envelope, roof, full MEP, fire protection and alarm, egress, bathrooms to code, abatement, ADA, permits and licensing soft costs. No stage, no bars, no audio, no acoustic treatment. You cannot trade from here, but you can get a Certificate of Occupancy.
B44: • | C44: BASE — the cheapest room that legally opens. Full structure, full MEP, full life safety, acoustic treatment, ground-supported stage and towers, mezzanine, six bars, bathrooms to code, and removable theatre seating on the mezzanine for the classification. Finishes are sealed concrete and exposed painted structure. No roof decks, no restaurant or kitchen (a separate company runs it), no VIP lounge, no architectural lighting, no art.
B45: • | C45: BASE + LIFT — the same room, taller. With a ground-supported stage the lift no longer buys rigging capacity; it buys volume, LED headroom, sightlines and the feel of the room. Use the Roof Lift sheet to dial the height: 35-40 ft may get you most of it for materially less than 50.
B46: • | C46: ELEVATED — restores the full fit-out at the same scope: nine bars rather than six, tile and resilient flooring instead of sealed concrete, four-stop lifts, the full signage package, VIP lounge and a proper finish standard throughout.
B47: • | C47: PREMIUM — adds the things the concept does not need: roof decks and terraces, the restaurant, the $1.75M architectural lighting package, interior art and scenic, and the parking garage.
...

Sheet Cost-Down Options
B2: HOW TO GET THE NUMBER DOWN
B3: Ranked by size. Everything here is a construction-cost lever — scope, procurement, delivery method or tax.
B5: Lever | C5: Saving (low) | D5: Saving (high) | E5: Certainty | F5: Costs us | G5: What it is and what it takes
B6: Correct the paver unit-price error | C6: 6890129 | D6: 6890129 | E6: Certain | F6: Nothing | G6: CSI 075000 row 193: 1,592 SF at $3,312.50/SF where the lines above and below are $31/SF. Change one cell and the cascade through 9% OH&P, 10% contractor contingency and 10% owner contingency unwinds. This is not a saving so much as a correction — but it is the single largest number on this sheet and it costs nothing.
B7: Leave the roof at 20ft | C7: 15500000 | D7: 19000000 | E7: Certain | F7: A lot | G7: The Tier R delta, all-in. Capacity is unaffected — 7,440 works at either height, it is driven by floor area and egress. What you lose is the production ceiling: no full concert lighting rig, no flown stage, no aerial, limited LED, worse HVAC at volume. It also removes the entire premium-positioning argument. Decide this one on strategy, not on cost.
B8: Competitively bid every trade package | C8: 1600000 | D8: 3200000 | E8: High | F8: Time | G8: This is a Version 1 desktop estimate: Committed Costs $0, Invoices $0, Change Orders $0. Nothing has been bought. Three-bidding a $32M trade schedule in this market typically returns 5-10% against a first-pass estimate. Nothing else on this sheet is as reliable.
B9: NYC IDA / ICAP sales-tax exemption on materials | C9: 1100000 | D9: 1500000 | E9: Verify | F9: Application | G9: NYC industrial and commercial incentive programmes can exempt construction materials from the 8.875% sales tax. On a $32M trade schedule with roughly 45% materials content that is ~$1.3M. Requires an IDA application and eligibility confirmation — start it before buyout, not after. VERIFY eligibility with counsel.
B10: Owner-furnish major equipment direct | C10: 900000 | D10: 1400000 | E10: High | F10: Coordination | G10: Buying switchgear, HVAC plant, elevators and production systems direct avoids the 9% OH&P and 10% contractor contingency stacked on them inside the trade schedule — roughly 20% on ~$6M of equipment. You take the delivery and warranty risk in exchange.
B11: Early buyout of steel and switchgear | C11: 800000 | D11: 1600000 | E11: High | F11: Cash earlier | G11: Locks the two longest-lead, most escalation-exposed packages against the 10% escalation assumption. Con Ed switchgear lead times are also the single biggest schedule risk in the job, so this buys programme as well as price.
B12: Open-book GMP with shared savings | C12: 600000 | D12: 1300000 | E12: Medium | F12: Negotiation | G12: The filed structure is a fixed 9% overhead, profit and insurance plus a 10% contractor contingency the contractor keeps. An open-book GMP with a shared-savings split returns unspent contingency instead of leaving it on the table. Typically worth 2-4% of trade cost.
B13: Re-use the existing roof and electrical service | C13: 600000 | D13: 2500000 | E13: Verify | F13: Nothing | G13: The structural and MEP assessment is still PENDING. If the precast roof is sound and the existing service can be uprated rather than replaced, the 74,000 SF roof demo ($1.11M) and part of the $1.4M Con Ed scope come out. This is the highest-value item on the pending due-diligence list — get the assessment done before buyout.
B14: Outsource the kitchen and restaurant | C14: 400000 | D14: 600000 | E14: High | F14: Margin share | G14: MT I49 and I154. Removes the kitchen equipment, the $135k of kitchen plumbing roughing, the gas run, hood fire suppression, grease waste and the restaurant furniture. The operator funds their own fit-out. Bars stay ours either way.
B15: NYSERDA and Con Ed C&I incentives | C15: 200000 | D15: 600000 | E15: Verify | F15: Application | G15: HVAC plant and lighting on a build this size normally qualifies for New York State and utility efficiency incentives. Has to be applied for during design, not after installation. VERIFY current programme availability.
B16: Cut architectural lighting to a defensible number | C16: 1000000 | D16: 1000000 | E16: High | F16: Kerb appeal | G16: MT H313. A single unsupported $1,750,000 lump at 3.4x the performance-lighting budget. Take it to ~$750k and move some of it to production lighting where it earns.
B17: Stop taking contingency on contingency | C17: 220000 | D17: 220000 | E17: Certain | F17: Nothing | G17: The 10% owner contingency is calculated on a subtotal that already contains the contractor 10%. Base the owner contingency on the pre-contractor-contingency figure instead.
B18: Phased Certificate of Occupancy | C18: 0 | D18: 0 | E18: Medium | F18: Programme risk | G18: Open the main hall and complete the mezzanine, roof decks and VIP later. Defers rather than saves — and doing finish work in a live venue costs a premium (see Phase 2 Add-Backs). Use it for cash timing, not for savings.
B19: TOTAL — every lever taken | C19: =SUM(C6:C18) | D19: =SUM(D6:D18) | G19: Not additive in practice — the roof decision and the re-use decision overlap, and bidding may capture some of the same value as buyout.
B20: Excluding the roof decision | C20: =C19-C7 | D20: =D19-D7 | G20: What is available WITHOUT giving up the 50ft ceiling.
B22: CERTAINTY KEY
B23: Certain | C23: Arithmetic. The money is there the moment someone edits the cell or changes the calculation basis.
B24: High | C24: Standard market practice on a job this size. Would be surprising not to achieve it.
B25: Medium | C25: Achievable but depends on how the contract and programme are structured.
B26: Verify | C26: Real money, but conditional on eligibility or on a survey that has not been done yet. Do not put these in a board number until confirmed.

Sheet Phase 2 Add-Backs
B2: WHAT THE EXTRAS COST
B3: Everything outside Scenario 2. Cost now, cost later, and the premium for doing it in a building that is already open.
B5: Item | C5: Cost if built now | D5: Cost if added later | E5: Later premium | F5: Why the premium, and what it buys
B6: 50ft roof raise — all Tier R scope | C6: 15500000 | D6: =C6*E6 | E6: 1.6 | F6: Cannot realistically be done later at all. Raising a roof over a finished venue means gutting it: the room closes for a year, the rig and finishes come out, and every trade is re-mobilised. Treat this as now-or-never rather than as a phase.
B7: Roof terrace decks & membranes | C7: 512128 | D7: =C7*E7 | E7: 1.35 | F7: Structure and waterproofing are accessible now and awkward later. Crane access and roof loading are both easier before the building is occupied.
B8: Roof deck storefront & access doors | C8: 175000 | D8: =C8*E8 | E8: 1.3 | F8: Envelope penetrations in an operating building. Weather protection and out-of-hours working.
B9: LED video walls (upstage + overhead) | C9: 1500000 | D9: =C9*E9 | E9: 1 | F9: No premium — genuinely modular. Rigging steel must be in from day one, but the walls themselves drop in whenever. This is the cleanest deferral in the whole budget.
B10: Displays & distribution | C10: 200000 | D10: =C10*E10 | E10: 1 | F10: No premium. Rentable per show in the meantime.
B11: Architectural & exterior lighting | C11: 750000 | D11: =C11*E11 | E11: 1.2 | F11: Exterior work needs access equipment and possibly a sidewalk shed again. Interior architectural lighting means working at height over a finished floor.
B12: Restaurant & kitchen fit-out | C12: 215000 | D12: =C12*E12 | E12: 1.25 | F12: If outsourced this becomes the operator's capital and the premium is theirs, not ours. Only relevant if we build it.
B13: Restaurant, VIP and roof furniture | C13: 290000 | D13: =C13*E13 | E13: 1 | F13: No premium. Furniture is furniture.
B14: Interior art, decor and murals | C14: 250000 | D14: =C14*E14 | E14: 1.1 | F14: MT I55: "Can be done after". Correct — and it works better once the room is finished and you can see what it needs.
B15: Theatre GA seating (3,714 chairs) | C15: 92850 | D15: =C15*E15 | E15: 1 | F15: No premium. Rent until seated shows justify buying.
B16: Parking garage | C16: 2257500 | D16: =C16*E16 | E16: 1.15 | F16: Standalone off-site structure. Independent of the building programme — but confirm whose scope it is before pricing it at all.
B17: TOTAL | C17: =SUM(C6:C16) | D17: =SUM(D6:D16) | E17: =D17/C17 | F17: Blended premium for deferring everything.
B19: THE ONLY REAL DEADLINE
B20: • | C20: Two things must be decided before construction starts and cannot be revisited: the roof height, and the rigging steel.
B21: • | C21: Everything else on this sheet can wait. LED walls, displays, furniture, art, seating and the roof decks all carry little or no penalty for being added later — provided the STRUCTURE to hang and support them is built now. Steel is cheap while the building is open and ruinous afterwards.
B22: • | C22: So the cost-down strategy is: build all the structure, defer all the finish and all the kit.

Sheet Roof Lift
B2: THE ROOF LIFT
B3: Its own model, because it is the biggest single variable and it is now a DIAL, not a switch.
B5: With a ground-supported stage and mezzanine (Factory Town style) the roof carries no rigging load. Height now buys volume, sightlines, LED headroom and HVAC stratification — not tonnage. So the question stops being "50 ft or nothing" and becomes "how much height does the room need".
B6: INPUTS — edit the yellow cells
B7: Building footprint (SF, under roof) | E7: 74100 | G7: Your figure. The mezzanine sits INSIDE this — it does not change the envelope.
B8: Existing clear height (ft) | E8: 20 | G8: Per the underwriting: roof raise "~20 -> 50 ft".
B9: Target clear height (ft) | E9: 50 | G9: THE DIAL. Try 35-40: enough for a ground-supported tower system plus LED at 7,440 cap.
B10: Lift height (ft) | E10: =E9-E8 | G10: Target less existing.
B11: Perimeter (LF) | E11: =4*SQRT(E7) | G11: Approximated as a square footprint. Override with the real survey figure.
B12: Roof steel (lb/SF) | E12: 15 | G12: 15 with a ground-supported stage. Use 20+ ONLY if the roof must carry rigging.
B13: COST BUILD-UP — at the estimator's own unit rates
B14: Demolish existing roof, deck & framing | C14: =E7 | D14: SF | E14: =E7*15 | G14: File rate $15/SF. Your 74,100 SF footprint.
B15: Temporary roof during construction | C15: =E7 | D15: SF | E15: =E7*5 | G15: File rate $5/SF.
B16: New roof trusses, girders & columns | C16: =E7*E12/2000 | D16: TON | E16: =E7*E12/2000*6000 | G16: File rate $6,000/ton. NO rigging capacity — the stage stands on the slab.
B17: Fireproofing on new roof steel | C17: =E7 | D17: SF | E17: =E7*5 | G17: File rate $5/SF. NYC-required on new structural steel.
B18: New roof membrane | C18: =E7 | D18: SF | E18: =E7*35 | G18: File rate $35/SF.
B19: Masonry "bump up" facade | C19: =E11*E10 | D19: SF | E19: =E11*E10*35 | G19: File rate $35/SF. Scales directly with the lift height.
B20: Furring & sheathing at bump up | C20: =E11*E10 | D20: SF | E20: =E11*E10*20 | G20: File rate $20/SF. Scales with lift height.
B21: New column footings & excavation | C21: 40 | D21: EA | E21: =40*7500+E7*6.5 | G21: File rates: $7,500/EA footing, $6.50/SF excavation.
B22: TRADE SUBTOTAL — the lift | E22: =SUM(E14:E21) | G22: This total feeds the eight Tier R lines on Line Build. Markups are applied there.
B24: ROOFLIFTERS 2022 BUDGET RATE CARD (v1013.1.RL SE)
B25: A rate card, NOT a project quote — Stage 1 of Rooflifters own three-stage process, priced on height and area alone. Rates are "from" figures for NON-UNION projects. At 74,100 SF the card interpolates to $20.18/SF between the 50,000 SF ($25) and 75,000 SF ($20) bands. Two adjustments are mandatory before use: escalation from 2022, and a New York union / prevailing-wage premium. The card INCLUDES lift, structural steel, external metal siding enclosure, bracing, structural drawings and GC coordination. It EXCLUDES demolition (except roof separation), hoarding, fire separation, and all MEP work — which is more than half of the build-up above.
B26: Rate card $/SF at this area | E26: 20.18 | G26: Interpolated from the 2022 card. Non-union, "from" pricing.
B27: Base figure (2022, non-union) | E27: =E7*E26 | G27: Area x rate.
B28: Escalation 2022 -> construction | E28: 1.35 | G28: Your estimate was 30-40%. Five years at ~6%/yr.
B29: NYC union / prevailing wage premium | E29: 1.8 | G29: THE BIG UNKNOWN. Card is explicitly non-union. NYC structural work runs 1.5-2.2x. Get a union-basis figure from them.
B30: ADJUSTED ROOFLIFTERS SCOPE | E30: =E27*E28*E29 | G30: What the lifter would charge here.
B31: Excluded scope, still ours | E31: =E14+E15+E17+E18+E21+320000 | G31: Roof demo, temp roof, fireproofing, membrane, footings, hoarding — all excluded by the card.
B32: TOTAL ROOF LIFT PACKAGE | E32: =E30+E31 | G32: Compare against the build-up subtotal in E22.
B33: Build-up less Rooflifters route | E33: =E22-E32 | G33: Positive means the Rooflifters route is cheaper. Most of the saving comes from the enclosure being metal siding rather than masonry and furring — not from the steel.
B35: HEIGHT SENSITIVITY
B36: Change the target height in E9 and the whole model moves. Roughly:
B37: Target height | C37: Lift | D37: Indicative trade cost of the lift
B38: 30 ft | C38: 10 ft | D38: =$E$14+$E$15+$E$16+$E$17+$E$18+$E$21+($E$11*10*35)+($E$11*10*20)
B39: 35 ft | C39: 15 ft | D39: =$E$14+$E$15+$E$16+$E$17+$E$18+$E$21+($E$11*15*35)+($E$11*15*20)
B40: 40 ft | C40: 20 ft | D40: =$E$14+$E$15+$E$16+$E$17+$E$18+$E$21+($E$11*20*35)+($E$11*20*20)
B41: 45 ft | C41: 25 ft | D41: =$E$14+$E$15+$E$16+$E$17+$E$18+$E$21+($E$11*25*35)+($E$11*25*20)
B42: 50 ft | C42: 30 ft | D42: =$E$14+$E$15+$E$16+$E$17+$E$18+$E$21+($E$11*30*35)+($E$11*30*20)
B43: Only the facade and furring scale with height — the roof itself costs the same whether you lift it 10 ft or 30 ft.

Sheet Line Build
A1: Code | B1: Section | C1: Description | D1: Tier | E1: Rent/ Free | F1: Infinity room? | G1: As Filed | H1: Corrected | I1: Infinity $ | J1: Variance | K1: Basis / note
A2: 000 | B2: OFFSITE | C2: Parking garage — 260 spaces | D2: 2 | F2: N | G2: 2150000 | H2: 2150000 | I2: 0 | J2: =H2-G2 | K2: $8,269/space. NYC structured parking is $25-50k/space. MT: 'Eric Paying for this????' — confirm landlord vs tenant scope. Delete, or 4x. [OUT of an Infinity room: Off-site, and probably not our scope at all (MT I21).]
A3: 000 | B3: OFFSITE | C3: Escalation on off-site @5% | D3: 2 | F3: N | G3: 107500 | H3: 107500 | I3: 0 | J3: =H3-G3 | K3: Applied here but left blank on the building — see finding C-07. [OUT of an Infinity room: Follows the garage out.]
A4: 013000 | B4: TRADE | C4: Project requirements / general requirements | D4: 0 | F4: Y | G4: 1696000 | H4: 1696000 | I4: 1696000 | J4: =H4-G4 | K4: Project labour $900k, site safety+inspector $250k, field tech $200k, final clean $100k, rubbish $60k, protection $50k, cleanup $45k, portolets 60wk x $400, BIM, site office. MT F11: 'no idea what this is breakout?'
A5: 015800 | B5: TRADE | C5: Scaffolding, sidewalk bridge & hoarding | D5: 0 | F5: Y | G5: 0 | H5: 1500000 | I5: 1500000 | J5: =H5-G5 | K5: Filed at ZERO qty. File's own rates: sidewalk bridge $250k LS, roof protection $50k, erection safety $20k. MT F12: '1-2M depending' — MT's number used.
A6: 024100 | B6: TRADE | C6: Demolition — interior, walls, MEP, Caesarstone plant | D6: 0 | F6: Y | G6: 30408 | H6: 530408 | I6: 530408 | J6: =H6-G6 | K6: Filed total is $30,408 for gutting a countertop manufacturing plant. Most sub-lines at zero qty.
A7: 024100 | B7: TRADE | C7: Demolition — 74,000 SF precast concrete roof | D7: R | F7: Y | G7: 0 | H7: ='Roof Lift'!$E$14 | I7: ='Roof Lift'!$E$14 | J7: =H7-G7 | K7: DRIVEN BY THE ROOF LIFT SHEET. Qty 74,100 SF footprint, no price in the file. Marked 'Abatement by others'. $15/SF is the file's own rate. REPLACE WITH THE ROOF-LIFTER QUOTE.
A8: 033000 | B8: TRADE | C8: Concrete — raised slab 1,500 CY, patching, stairs | D8: 0 | F8: Y | G8: 0 | H8: 650000 | I8: 650000 | J8: =H8-G8 | K8: 1,500 CY raised slab on styrofoam over 20,314 SF incl. two ramps. Qty present in the dev budget, no unit price, $0 total. Separate from the mezzanine and stage footings below.
A9: 033000 | B9: TRADE | C9: Concrete — footings & excavation for new roof columns | D9: R | F9: Y | G9: 0 | H9: ='Roof Lift'!$E$21 | I9: ='Roof Lift'!$E$21 | J9: =H9-G9 | K9: 'Excavation related to New Columns at Music hall — Based on Footprint of New Roof' @ $6.50/SF, qty 0. Footings $7,500/EA, qty 0.
A10: 042000 | B10: TRADE | C10: Masonry — patch/repair, elevator towers, back wall | D10: 0 | F10: Y | G10: 530010 | H10: 530010 | I10: 530010 | J10: =H10-G10 | K10: One of the few divisions with real quantities.
A11: 042000 | B11: TRADE | C11: Masonry — brick facade at music hall 'bump up' | D11: R | F11: Y | G11: 0 | H11: ='Roof Lift'!$E$19 | I11: ='Roof Lift'!$E$19 | J11: =H11-G11 | K11: 'F&I Brick facade at music hall BUMP UP' @ $35/SF, qty 0. 30ft rise x perimeter.
A12: 033000 | B12: TRADE | C12: Mezzanine & stage — concrete footings and foundations (indoor) | D12: 1 | F12: Y | G12: 0 | H12: 350000 | I12: 350000 | J12: =H12-G12 | K12: GROUND-UP BUILD, HURRICANE SCOPE REMOVED. FT Infinity footers actually cost $826,986 (EDT base $615,642 + 34% change order $211,344) against a $600,000 whole-site allowance — but those are mass foundations resisting overturning and uplift on an OPEN-AIR stage at ~175 mph Miami-Dade design wind. An enclosed Brooklyn room has no wind load on an interior structure at all. Park Stage bought its foundations as separate trades for far less: rebar $82,400 (Miami Polish) + concrete footers $60,000 (Jorge Concrete) = $142,400. Carried at $350,000 for mezzanine and stage footings combined, poured into the slab.
A13: 055100 | B13: TRADE | C13: Mezzanine — structural steel framing, ground-supported | D13: 1 | F13: Y | G13: 0 | H13: 2000000 | I13: 2000000 | J13: =H13-G13 | K13: $6,000/ton, qty 0 in the dev budget. Ground-supported steel mezzanine INSIDE the existing 74,100 SF footprint: adds standing room and floor area without touching the envelope or the height. Reduced from $2.5M — the separate upper balcony goes with the four-level scheme.
A14: 033000 | B14: TRADE | C14: Mezzanine — concrete deck poured on metal deck | D14: 1 | F14: Y | G14: 0 | H14: 500000 | I14: 500000 | J14: =H14-G14 | K14: GROUND-UP BUILD. Dev budget line 'Concrete on Deck for Mezz of Music Hall with Platforms' @ $25/SF, QTY 0. ~20,000 SF of mezzanine deck. Poured deck rather than a lightweight system: better acoustic separation from the room below, and it carries dense standing load.
A15: 055100 | B15: TRADE | C15: Stage, deck & production towers — ground-supported (indoor) | D15: 1 | F15: Y | G15: 0 | H15: 1400000 | I15: 1400000 | J15: =H15-G15 | K15: BENCHMARKED TO FT INFINITY ACTUALS, NOT ITS BUDGET. Factory Town Infinity budgeted $2.0M for structure + deck and ACTUALLY SPENT $3,506,289 (MTN stage $2,400,815; EDT footers $615,642 + $211,344 change order; MTN VIP platforms $136,000; MTN FOH $92,020; decking $50,468) — a 75% overrun. Two deductions apply here: the open-air stage roof and crowd weather cover (the building already has a roof) and the Miami-Dade hurricane-rated mass foundations (an interior structure in Brooklyn carries no wind load). Indoor equivalent lands at $1.2-1.7M; carried at $1.4M. Your black-steel mounting quote of $1.0M plus FT actual VIP platforms $136,000 plus decking $50,468 = $1,186,468 reaches the same place independently.
A16: 055100 | B16: TRADE | C16: Structural steel — new roof trusses, girders, columns | D16: R | F16: Y | G16: 0 | H16: ='Roof Lift'!$E$16 | I16: ='Roof Lift'!$E$16 | J16: =H16-G16 | K16: DRIVEN BY THE ROOF LIFT SHEET. Now specced at 15 lb/SF, NOT 20 — with a ground-supported stage and mezzanine the roof carries only itself, snow and MEP. No 40-ton rigging capacity, no heavy transfer girders, no reinforced point-load nodes. REPLACE WITH THE ROOF-LIFTER QUOTE.
A17: 055100 | B17: TRADE | C17: Misc metals — stairs, railings, ladders, dunnage, lintels | D17: 0 | F17: Y | G17: 0 | H17: 400000 | I17: 400000 | J17: =H17-G17 | K17: Egress stairs $30k/floor, theatre railing $275/LF, roof-deck railing $500/LF, HVAC dunnage $20k/loc — all qty 0.
A18: 062000 | B18: TRADE | C18: Rough carpentry / OSHA protection | D18: 0 | F18: Y | G18: 0 | H18: 175000 | I18: 175000 | J18: =H18-G18 | K18: Roof cut-out safety $35k, footing trench safety $30k, mezz build-out safety — all qty 0.
A19: 064000 | B19: TRADE | C19: Millwork — 9 bars & back bars | D19: 1 | F19: part | G19: 0 | H19: 600000 | I19: 420000 | J19: =H19-G19 | K19: $900/LF x 9 bars (lobby, music hall L/R/rear, mezz L/R, VIP, restaurant, roof lobby), qty 0. MT I154: 'only build bars' — this is that scope. [Infinity room: reduced to $420,000 — Six bars rather than nine — the VIP, restaurant and roof-lobby bars go with their rooms.]
A20: 064000 | B20: TRADE | C20: Millwork — box office, coat, merch, BOH counters | D20: 1 | F20: part | G20: 0 | H20: 200000 | I20: 110000 | J20: =H20-G20 | K20: Box office $500/LF, coat closet $150/LF, merch $12k LS, bathroom counters $400/LF — all qty 0. [Infinity room: reduced to $110,000 — Box office and merch only. No coat check millwork, no decorative back-bar features.]
A21: 075000 | B21: TRADE | C21: Roofing — 3 terrace membranes | D21: 2 | F21: N | G21: 262112.5 | H21: 262112.5 | I21: 0 | J21: =H21-G21 | K21: 2nd floor, 3rd floor VIP, 3rd floor restaurant @ $32.50/SF. This is roof-DECK scope, not the lift. [OUT of an Infinity room: Roof decks are not part of an Infinity room.]
A22: 075000 | B22: TRADE | C22: Roofing — 3 terrace paver decks (CORRECTED) | D22: 2 | F22: N | G22: 5474163 | H22: 250015 | I22: 0 | J22: =H22-G22 | K22: AS FILED contains the $5,224,148 error: 3rd-floor VIP pavers at $3,312.50/SF vs $31/SF on the two neighbouring lines. Corrected to $31/SF. [OUT of an Infinity room: Roof decks are not part of an Infinity room.]
A23: 075000 | B23: TRADE | C23: Roofing — new roof membrane over raised structure | D23: R | F23: Y | G23: 0 | H23: ='Roof Lift'!$E$18 | I23: ='Roof Lift'!$E$18 | J23: =H23-G23 | K23: $35/SF over 74,000 SF. No line exists; 'Remove and replace roof at lower areas' @ $35/SF is qty 0.
A24: 075000 | B24: TRADE | C24: Roofing — temporary roof during construction | D24: R | F24: Y | G24: 0 | H24: ='Roof Lift'!$E$15 | I24: ='Roof Lift'!$E$15 | J24: =H24-G24 | K24: 'Temp roof above music hall' @ $5/SF, qty 0.
A25: 078100 | B25: TRADE | C25: Fireproofing — mezzanine & stage steel | D25: 0 | F25: Y | G25: 0 | H25: 200000 | I25: 200000 | J25: =H25-G25 | K25: NYC-required on new structural steel in assembly occupancy. $5/SF, qty 0.
A26: 078100 | B26: TRADE | C26: Fireproofing — new roof steel | D26: R | F26: Y | G26: 0 | H26: ='Roof Lift'!$E$17 | I26: ='Roof Lift'!$E$17 | J26: =H26-G26 | K26: 'Allow for fireproofing at New steel at Roof' @ $5/SF, qty 0.
A27: 081000 | B27: TRADE | C27: Doors, frames & hardware incl. acoustic | D27: 0 | F27: Y | G27: 0 | H27: 550000 | I27: 550000 | J27: =H27-G27 | K27: Egress and life-safety doors. Acoustic doors $6,500 EA / $10,000 pair — all qty 0.
A28: 083000 | B28: TRADE | C28: Special doors (Eliason) | D28: 1 | F28: Y | G28: 6000 | H28: 6000 | I28: 6000 | J28: =H28-G28 | K28: One of the only fully-priced lines in the file.
A29: 084100 | B29: TRADE | C29: Storefront & entry glazing | D29: 0 | F29: Y | G29: 0 | H29: 150000 | I29: 150000 | J29: =H29-G29 | K29: Main entry. $250/SF, qty 0.
A30: 084100 | B30: TRADE | C30: Storefront — roof deck & VIP lounge | D30: 2 | F30: N | G30: 0 | H30: 175000 | I30: 0 | J30: =H30-G30 | K30: Roof-deck doors, VIP interior storefront — qty 0. Phase with the decks. [OUT of an Infinity room: Serves the roof decks and VIP lounge — both out.]
A31: 088000 | B31: TRADE | C31: Glazing — mirrors, ballistic box office window | D31: 1 | F31: Y | G31: 0 | H31: 120000 | I31: 120000 | J31: =H31-G31 | K31: Ballistic box office $10k LOT, bar mirrors $35k LOT — qty 0.
A32: 092000 | B32: TRADE | C32: Drywall — perimeter, fire-rated, stage walls | D32: 0 | F32: Y | G32: 119664 | H32: 119664 | I32: 119664 | J32: =H32-G32 | K32: Quantities present for first floor. 2HR rated walls at stage and rear of music hall.
A33: 092000 | B33: TRADE | C33: Drywall — interior partitions, acoustic & fire-rated walls | D33: 0 | F33: Y | G33: 0 | H33: 800000 | I33: 800000 | J33: =H33-G33 | K33: 'Interior Sound/Fire rated walls at music hall, stair ways and elevator shafts' @ $20/SF, qty 0. BOH, green rooms, offices.
A34: 092000 | B34: TRADE | C34: Drywall — furring/sheathing at music hall 'bump up' | D34: R | F34: Y | G34: 0 | H34: ='Roof Lift'!$E$20 | I34: ='Roof Lift'!$E$20 | J34: =H34-G34 | K34: @ $20/SF, qty 0.
A35: 092300 | B35: TRADE | C35: Tile — restrooms, bars, kitchen | D35: 0 | F35: part | G35: 0 | H35: 250000 | I35: 140000 | J35: =H35-G35 | K35: 189 plumbing fixtures' worth of restroom tile at $30/SF, qty 0. [Infinity room: reduced to $140,000 — Restrooms only. Sealed concrete at bars and BOH.]
A36: 096000 | B36: TRADE | C36: Carpet / resilient flooring — BOH, offices, dressing | D36: 1 | F36: N | G36: 0 | H36: 150000 | I36: 0 | J36: =H36-G36 | K36: LVT at green rooms, carpet at office/production, VCT at box office — qty 0. [OUT of an Infinity room: Sealed concrete throughout except dressing rooms.]
A37: 096050 | B37: TRADE | C37: Floor preparation | D37: 0 | F37: Y | G37: 0 | H37: 25000 | I37: 25000 | J37: =H37-G37 | K37: $25k LS, qty 0.
A38: 096400 | B38: TRADE | C38: Wood flooring — stage T&G deck | D38: 1 | F38: Y | G38: 0 | H38: 120000 | I38: 120000 | J38: =H38-G38 | K38: 'F&I T&G Wood floor at Stage' @ $35/SF, qty 0.
A39: 099000 | B39: TRADE | C39: Painting & plaster | D39: 0 | F39: part | G39: 0 | H39: 320000 | I39: 200000 | J39: =H39-G39 | K39: $2.50/SF, qty 0. [Infinity room: reduced to $200,000 — Exposed painted structure. No plaster, no upgraded finishes.]
A40: 100000 | B40: TRADE | C40: Specialties — toilet partitions & accessories, extinguishers | D40: 0 | F40: Y | G40: 0 | H40: 220000 | I40: 220000 | J40: =H40-G40 | K40: 189 fixtures. Partitions $1,500 EA, accessories $7,500/set, extinguishers $350 EA — all qty 0.
...

Sheet Theater Seating
B2: THEATER SEATING — COMPLIANCE vs A BEAUTIFUL THEATER
B3: The seating is not furniture. It is what classifies the room, and the classification carries the licences.
B5: The room needs a theater use-classification to hold the liquor and cabaret licences, and the technical drawings have to show seating that supports it. That sets a FLOOR on what must be built. Everything above that floor is an aesthetic choice, not a licensing one — and the gap is large.
B7: INPUTS — confirm the seat count with counsel before relying on any of this
B8: Seats required for classification | E8: 720 | G8: PLACEHOLDER. YOUR COUNSEL MUST SET THIS. It drives everything below.
B9: Mezzanine seats available | E9: 720 | G9: 657 box chairs + 63 elevated, per FF&E schedule 301.
B10: Floor seats in the filed budget | E10: 3714 | G10: Matches the Wake test fit floor-seated figure at 7 SF/occupant.
B11: Removable chair, $/seat | E11: 25 | G11: MT H127: "can get cheaper ones for 25 a seat".
B12: Filed folding chair, $/seat | E12: 125 | G12: As budgeted in FF&E 301.
B13: Fixed theatre seat, $/seat | E13: 450 | G13: Upholstered, floor-mounted, standard grade. Premium runs $600-900.
B15: THREE WAYS TO DO IT
C16: 1. COMPLIANCE removable, mezzanine only | D16: 2. AS FILED floor folding + mezz boxes | E16: 3. BEAUTIFUL THEATER fixed, raked, upholstered
B17: Seats provided | C17: =$E$8 | D17: =$E$10+$E$9 | E17: =$E$10+$E$9
B18: Chairs / seats | C18: =$E$8*$E$11 | D18: =$E$10*$E$12+$E$9*300 | E18: =($E$10+$E$9)*$E$13
B19: Raked risers / tiering | C19: =0 | D19: =0 | E19: =($E$10+$E$9)*180
B20: Fixed mounting & floor prep | C20: =0 | D20: =0 | E20: =($E$10+$E$9)*45
B21: Aisle lighting, row & seat numbering | C21: =$E$8*8 | D21: =($E$10+$E$9)*8 | E21: =($E$10+$E$9)*22
B22: Sightline & seating design fees | C22: =15000 | D22: =25000 | E22: =140000
B23: Storage for removed seating | C23: =35000 | D23: =60000 | E23: =0
B24: TOTAL SEATING PACKAGE | C24: =SUM(C18:C23) | D24: =SUM(D18:D23) | E24: =SUM(E18:E23)
B25: Cost per seat provided | C25: =C24/C17 | D25: =D24/D17 | E25: =E24/E17
B26: Saving vs a beautiful theater | C26: =$E$24-C24 | D26: =$E$24-D24 | E26: =$E$24-E24
B28: READ THIS
B29: • | C29: Option 1 is the licensing floor: removable seating on the mezzanine, shown on the technical drawings, satisfying the classification — with the floor left as standing room, which is what an Infinity room wants anyway. Seats stack into storage on dance nights.
B30: • | C30: Option 2 is what is in the budget today. It seats the floor as well as the mezzanine at $125 a chair, and it is neither the cheapest compliant answer nor a real theater.
B31: • | C31: Option 3 is a genuine theater: fixed upholstered seats on raked tiering with designed sightlines. It is a different building, and on this concept it buys nothing the licence requires.
B32: • | C32: THE SEAT COUNT IS A PLACEHOLDER. What actually satisfies the NYC theater use-classification, the SLA and the cabaret licence is a legal question: the required count, whether seats must be fixed or may be removable, and whether the mezzanine alone is sufficient. Get that answer before anyone prices a chair.

Sheet Lease or Finance
B2: EQUIPMENT FINANCING — OPTIONAL, REFERENCE ONLY
B3: Kit in the Line Build that does not have to be bought outright. Nothing here changes the build cost — it changes WHEN you pay. Property-lease and landlord matters are deliberately excluded.
B5: FINANCING ASSUMPTIONS — edit the yellow cells
B6: Equipment lease rate, annual | C6: 0.09 | H6: Typical for AV/production gear on a 5-year lease with a $1 buyout.
B7: Equipment lease term, years | C7: 5 | H7: Own the asset at the end.
B8: Events per year (for rental comparisons) | C8: 85 | H8: Used only to convert per-event rental into an annual figure.
B10: FOUR MECHANISMS
B11: Equipment lease | C11: Fixed term, you own it at the end. Cheapest way to defer real CapEx. Best for audio, lighting, HVAC plant.
B12: Event rental | C12: Pay per show. Flexible, no commitment, and by far the most expensive per year if you use it often.
B13: Vendor-supplied | C13: A supplier funds the kit in exchange for exclusivity or volume. Zero CapEx, zero lease — costs margin instead.
B14: Third-party operator | C14: Someone else builds and runs the scope. Removes it from the budget entirely; you take rent or a percentage.
B16: Item | C16: CapEx if bought | D16: Mechanism | E16: Annual cost if not bought | F16: Term | G16: Own at end? | H16: Verdict / what it costs you
B17: House audio system (L-Acoustics) | C17: 2200000 | D17: Equipment lease | E17: =C17*$C$6/(1-(1+$C$6)^-5) | F17: 5 | G17: Yes | H17: MT I301. Payback on buying vs event rental is 2-7 months, so DO NOT event-rent it long term. A 5-year lease keeps the asset and defers the cash.
B18: Performance lighting rig | C18: 850000 | D18: Equipment lease | E18: =C18*$C$6/(1-(1+$C$6)^-5) | F18: 5 | G18: Yes | H18: MT I61/I305. Same logic as audio. Lease rather than rent show by show.
B19: LED video walls (upstage + overhead) | C19: 1500000 | D19: Event rental | E19: =C19*0.35 | F19: — | G19: No | H19: Already Tier 2. Rent per show until the calendar proves the spend. Genuinely the right one to rent — spec moves fast and it dates quickly.
B20: Displays & distribution | C20: 200000 | D20: Event rental | E20: =C20*0.35 | F20: — | G20: No | H20: MT I294: "We can do any display or distribution by renting." Agreed.
B21: HVAC plant — chillers / air handling | C21: 5300000 | D21: Equipment lease | E21: =C21*$C$6/(1-(1+$C$6)^-7) | F21: 7 | G21: Yes | H21: The largest single leasable item in the build. Energy-as-a-Service and equipment leasing are both routine for plant this size. Check NYSERDA and Con Ed C&I incentives before signing anything.
B22: POS terminals (76) | C22: 228000 | D22: Vendor-supplied | E22: =0 | F22: — | G22: No | H22: MT I50: "I can get someone to give it to us for free for using the venue." Standard deal — take it.
B23: Ice machines & walk-in coolers | C23: 90000 | D23: Vendor-supplied | E23: =0 | F23: — | G23: No | H23: Beverage distributors routinely supply coolers, draft systems and ice against a pouring agreement.
B24: Bar equipment — draft systems portion | C24: 200000 | D24: Vendor-supplied | E24: =0 | F24: — | G24: No | H24: Same pouring-rights mechanism. Negotiate before the equipment package is bought out.
B25: Kitchen equipment + kitchen roughing | C25: 215000 | D25: Third-party operator | E25: =0 | F25: — | G25: No | H25: MT I49/I154: outsource the kitchen. The operator funds their own equipment. Removes the scope AND the $135k of plumbing roughing.
B26: Restaurant fit-out & furniture | C26: 70000 | D26: Third-party operator | E26: =0 | F26: — | G26: No | H26: Goes with the kitchen. 769 covers becomes their capital, not ours.
B27: Theatre GA seating (3,714 chairs) | C27: 92850 | D27: Event rental | E27: =C27*0.35 | F27: — | G27: No | H27: Only needed for seated configurations. Rent per seated show rather than storing 3,714 chairs.
B28: Fork lift & scissor lift | C28: 60000 | D28: Event rental | E28: =C28*0.35 | F28: — | G28: No | H28: Already cut per MT I275. Rent for load-ins.
B29: TOTAL equipment CapEx that can be financed rather than bought | C29: =SUM(C17:C28) | E29: =SUM(E17:E28) | H29: Annual figure is what you pay instead. Leased items you still own at the end of the term.
B31: READ THIS FIRST
B32: • | C32: Financing does not make the building cheaper — it makes it cheaper TO START. Total cost over the life of the kit is higher than buying, always.
B33: • | C33: Vendor-supplied kit is paid for in margin, not cash. A pouring agreement that funds coolers and draft systems has a price per keg attached — get that priced before signing.
B34: • | C34: Rental figures use a 35%-of-purchase-price-per-year rule of thumb for regular use. For audio and lighting the Factory Town book shows the real number is far worse: buying pays back in 2-7 months, so lease those rather than renting them show by show.

Sheet Findings
B2: CONSTRUCTION FINDINGS REGISTER
B3: Every finding is sourced to a cell, quantity or unit price in the Master Development Budget. Revenue, operating and deal findings are excluded.
B5: ID | C5: CSI / tab | D5: Finding | E5: Impact | F5: Direction | G5: Evidence
B6: C-01 | C6: 075000 | D6: Paver line priced at 107x its neighbours | E6: -6890129 | F6: Overstated | G6: Row 193: 1,592 SF at $3,312.50/SF. Rows 192 and 194, same product, are $31/SF. $5,224,148 of trade cost, marked up through 9% OH&P, 10% contractor contingency and 10% owner contingency. Correct it and CSI 075000 falls from $5,736,276 to $512,128 — three terrace membranes and their pavers.
B7: C-02 | C7: 055100 / 024100 | D7: The 50ft roof raise is quantified at zero | E7: 11275395 | F7: Understated | G7: Every related line carries a unit price and QTY 0: demo of elevated roof area $15/SF; excavation for new columns $6.50/SF "Based on Footprint of New Roof"; footings $7,500/EA; brick facade at music hall "BUMP UP" $35/SF; roof trusses, girders and columns $6,000/ton; roof deck $4/SF; temp roof $5/SF; fireproofing new roof steel $5/SF; furring at "BUMP UP" $20/SF. The soft-cost tab DOES fund 13 borings 50ft deep "required for ST permit".
B8: C-03 | C8: 055100 | D8: Structural steel is $0 on an "Add Second Level" scope | E8: 3400000 | F8: Understated | G8: Mezzanine framing, upper balcony framing incl. balcony seating, stage lighting and AV support structure, stairs, railings, roof dunnage — all at $6,000/ton or $8/lb, all QTY 0. The FF&E schedule simultaneously buys 657 mezzanine box chairs.
B9: C-04 | C9: 260000 | D9: Electrical has switchboards and temp power only | E9: 4400000 | F9: Understated | G9: $558,750 total = two 2,500A switchboards ($390k), temp light and power ($156,250), firestopping ($12,500). QTY 0 on: general power and devices, kitchen circuits, stage power, mechanical power, VAV and exhaust fan power, panels and secondary distribution, new CT cabinet and transformer switches, combine existing services. MT F41 asked whether stages can plug in here — they cannot.
B10: C-05 | C10: 100500 | D10: Acoustic treatment is $0 | E10: 2000000 | F10: Understated | G10: Acoustical panels at music hall walls $40/SF QTY 0; K13 at underside of mezzanine, music hall ceilings and VIP $12/SF QTY 0; acoustical doors $6,500 EA / $10,000 pair QTY 0. Soft-cost acoustical engineering is a single $15,000 line. MT G53 confirms $15-25k is right for the FEE — the treatment is the gap.
B11: C-06 | C11: FF&E 309 | D11: LED video walls are a note, not a number | E11: 1500000 | F11: Understated | G11: "Upstage Video Wall" carries the note "$1,400/SF" with no quantity and no total. "Overhead Video Wall" is blank. At $1,400/SF an 1,800 SF upstage wall is $2.52M. The underwriting raised its own lighting and video line to $1.5M explicitly for "expanded LED wall coverage".
B12: C-07 | C12: 100 | D12: Escalation applied to the garage, left blank on the building | E12: 3182355 | F12: Understated | G12: Off-site: "Escalation (Calculated at 5%)" = $107,500. Building and Fit-Out: the same line exists and is BLANK. A single 5% pass on trade is ~$909k; compounding across a two-year build from 2027 is 10-15%.
B13: C-08 | C13: 201 / 024100 | D13: Abatement is $8,750 on a 1948 building | E13: 1000000 | F13: Understated | G13: Soft cost 201: 350 units at $25. Demolition schedules "Demo Pre-cast concrete roof, 74,000 SF" marked "Abatement by others" — and that demo line itself carries no price. Total demolition for a decommissioned Caesarstone plant is $30,408. MT G32: "this is super low".
B14: C-09 | C14: 210 / 260000 | D14: Con Ed fee is budgeted, the service upgrade is not | E14: 1400000 | F14: Understated | G14: Soft cost 210 note: "Service upgrade required. Vault located in street, new conduit and feeders from vault into MPOE electrical room. Only Con Ed costs carried." The physical work is QTY 0 in the trade schedule.
B15: C-10 | C15: various | D15: Twelve further divisions at zero quantity | E15: 4010000 | F15: Understated | G15: Concrete, millwork, bar and kitchen plumbing roughing, doors and hardware, tile and flooring, scaffolding and hoarding, fireproofing, painting, storefront and glazing, specialties, rough carpentry, sitework. Each carries populated unit prices against QTY 0. MT F12 puts scaffolding alone at $1-2M.
B16: C-11 | C16: 400 | D16: Contingency is stacked and thin | E16: 220000 | F16: Overstated | G16: A 10% contractor contingency sits inside Building and Fit-Out; the 10% owner contingency is then taken on a subtotal that already includes it. Combined contingency is 14.3% of total against a 25-35% norm for a 1948 conversion at this design stage with this much scope unpriced.
B17: P-01 | C17: FF&E 302 | D17: F&B equipment 40% below our own Brooklyn Paramount build | E17: 990000 | F17: Understated | G17: The sheet cites its own comp: "BPT: 26 POS / Prep Kitchen / 1 Walk-in Cooler $837K" = $32,192 per POS. 165 Randolph budgets $1,457,000 for 76 positions = $19,171 per POS. Kitchen equipment at $80,000 for 769 covers is the least credible line in the FF&E schedule.
... B19: P-03 | C19: FF&E 309 | D19: Three different numbers for one audio system | E19: 800000 | F19: Understated | G19: Dev budget $1,400,000 "Includes Theater / VIP / Restaurant & Roof Area". Underwriting $2,200,000 for the main room alone. The FF&E row's own benchmark note says $690k. Soft goods shows the same pattern: $200,000 budgeted against a $725,000 benchmark on the same row, with "CUTDOWN DRAPE @ MEZZ EDGE Not Included".
B20: P-04 | C20: 000 | D20: Parking garage at $8,269 per space | F20: Discrepancy | G20: $2,150,000 for 260 spaces. NYC structured parking is $25,000-50,000 per space — so either this is surface parking or the line is short by $4.3-10.8M. It appears in no sheet of the underwriting. MT I21: "Eric Paying for this????"
B21: P-05 | C21: 100 / 213 | D21: General conditions and PM do not match a 24-month build | E21: 680000 | F21: Understated | G21: Hidden GC tab totals $2,082,000 against $2,000,000 carried — an $82k break. Staff durations are inconsistent in the same sheet (60 units for PM, APM, engineer and three supers; 6 for exec, accountant and general super). The only duration in the file is 60 weeks of portable toilets, implying ~14 months. Owner PM is $520,000 = 1.2% of project against a 2-4% norm.
B22: P-06 | C22: 230000 / 142000 | D22: Three lines where the contractor is right and the underwriting was light | E22: -3521900 | F22: Overstated | G22: HVAC $5,300,000 vs $2,667,600 underwritten — the dev budget is correct for NYC assembly at 3.7M cu ft. Elevators $600,000 (2 cars x 4 stops) vs $200,000 for one 2-stop hydraulic. Plumbing 189 fixtures vs 100 assumed — the dev budget matches NYC code at 7,440. The underwriting was $3.5M short on these three.
B23: N-01 | C23: 230000 | D23: No heating line exists at all | E23: 815100 | F23: Understated | G23: MT F40: "Do we need heat?" Yes. HVAC is priced over 120,000 SF against a 135,953 SF building, and there is no heating scope whatsoever. The underwriting carries $815,100 for radiant tube on the correct reasoning that forced air fails at a 50ft ceiling.
B24: N-02 | C24: 210000 / 283100 | D24: Fire protection and alarm priced over the wrong area | E24: 214000 | F24: Understated | G24: Fire protection covers 122,300 SF and fire alarm 100,000 SF against a 135,953 SF building — short by 11% and 26% of area respectively. MT H429 asked about a double count between the Breakdown and Detail tabs: there is none, the two Breakdown lines sum exactly to the Detail tab's $400,000.
B25: R-01 | C25: basis | D25: $313/SF and $607/SF describe the same building | F25: Discrepancy | G25: Dev budget: $42,555,099 over 135,953 SF = $313/SF. Underwriting: $45,000,000 over 74,100 SF = $607/SF. Both correct, both will be read side by side. A reader who sees $313/SF against Brooklyn industrial comps of $394-554/SF concludes the build is cheap.
B26: R-02 | C26: reconciliation | D26: 27.3% of the underwriting CapEx was a plug | F26: Discrepancy | G26: The underwriting CapEx tab states it: hard costs $24,103,600, directed base $40,000,000, and a reconciliation line of $12,280,860 described as "line items not yet priced". The $45M was a target, not an estimate. The development budget is the first genuine bottom-up.
B27: G-01 | C27: governance | D27: The cost-control apparatus is an unwired template | F27: Discrepancy | G27: Project At-a-Glance and Project Summary rollups are broken with #REF!. Cost Report Date reads 2023-01-31 and the contingency log is dated March 2020 — from the project this template was copied from. The Risk Report is empty with $0 exposure. Committed Costs, Invoices and Change Orders are all $0, so nothing has been bought and this is a desktop estimate, not a validated bottom-up.
D28: NET IMPACT vs the filed budget | E28: =SUM(E6:E27) | G28: Overstatements are negative, understatements positive. This is an indicative net, not the scenario total — see Scenario Summary for the modelled numbers.
