Workbook

Sheet Budget Summary
A1: 165 Randolph St. Brooklyn NY
A2: Warehouse Conversion / Add Second Level & Roof Deck
A3: Theater GA Standing: 7,440
A4: Theater GA Seated: 5,954
A5: Eating & Drinking : 769
A6: VIP Lounge
A8: SF: | B8: 135, 953 | J8: =130000*600 -> 78000000
A9: 46272
A10: Version #: 1
A13: Construction Duration: 20 Months
A14: Expected Certificate of Occupancy: TBD
A15: Expected Frist Show:
A16: Project Completion:
D19: Budget Total | F19: 2023 | G19: 2024 | H19: 2025
A20: 000 | B20: OFF SITE COSTS
B21: Parking Garage - 260/spaces | D21: =86*25000 -> 2150000 | F21: 0 | G21: 0 | H21: 0
B22: Escalation (Calculated at 5%) | D22: =D21*0.05 -> 107500 | F22: 0 | G22: 0 | H22: 0
D23: =SUM(D21:D22) -> 2257500 | F23: 0 | G23: 0 | H23: 0
A24: 100 | B24: Building & Fit-Out Costs
B25: Trade Costs | D25: ='Building & Fit-outBudget Detail'!C49-'Building & Fit-outBudget Detail'!C47 -> 37945960 | F25: 0 | G25: 0 | H25: 0
B26: Trade Costs To Be Priced | D26: 12000000
B27: General Conditions and General Requirements | D27: 3141000 | F27: 0 | G27: 0 | H27: 0 | I27: 90 wks
B28: Overhead, Profit & Insurance (9% Combined) | D28: =SUM(D25:D27)*0.09 -> 4777826.4 | F28: 0 | G28: 0 | H28: 0
B29: Contractor Contingency 10% | D29: =SUM(D25:D28)*0.1 -> 5786478.6 | F29: 0 | G29: 0 | H29: 0
B30: Escalation (Calculated at 5%) | F30: 0 | G30: 0 | H30: 0
D31: =SUM(D25:D30) -> 63651265 | F31: 0 | G31: 0 | H31: 0 | I31: =D31/135953 -> 468.1858
A32: 200 | B32: Soft Costs
B33: Abatement | D33: ='Soft Cost & FF&E Budget Detail'!E16 -> 1483680 | F33: 0 | G33: 0 | H33: 0
B34: Feasibility Study | D34: ='Soft Cost & FF&E Budget Detail'!E21 -> 342000
B35: Architectural / Engineering / Consultant Fees | D35: ='Soft Cost & FF&E Budget Detail'!E38 -> 3526000 | F35: 0 | G35: 0 | H35: 0
B36: Site & Civil | D36: ='Soft Cost & FF&E Budget Detail'!E43 -> 10000 | F36: 0 | G36: 0 | H36: 0
B37: Traffic Engineering | D37: ='Soft Cost & FF&E Budget Detail'!E51 -> 10000
B38: Acousticsl Engineering | D38: ='Soft Cost & FF&E Budget Detail'!E58 -> 15000
B39: Geotechnical Engineering | D39: ='Soft Cost & FF&E Budget Detail'!E66 -> 150000
B40: Enviromental Studies | D40: ='Soft Cost & FF&E Budget Detail'!E71 -> 0
B41: Zoning/Permit Fees | D41: ='Soft Cost & FF&E Budget Detail'!E82 -> 628297.48 | F41: 0 | G41: 0 | H41: 0
B42: Utility Connection Fees | D42: ='Soft Cost & FF&E Budget Detail'!E90 -> 50000
B43: Attorney Fees | D43: ='Soft Cost & FF&E Budget Detail'!E98 -> 0
B44: Testing / Quality Control | D44: ='Soft Cost & FF&E Budget Detail'!E103 -> 50000 | F44: ='Soft Cost & FF&E Budget Detail'!E103 -> 50000 | G44: 0 | H44: 0
B45: Project Management (Live Nation) | D45: ='Soft Cost & FF&E Budget Detail'!E109 -> 520000 | F45: 0 | G45: 0 | H45: 0
...

Sheet Soft Cost & FF&E Budget Detail
A1: 165 Randolph St Brooklyn NY
A2: Scope : | B2: Warehouse Conversion / Add Second Level & Roof Decks
A3: Capacity: | B3: ##
A4: SF: | B4: 135953
A5: Date:
A6: Version: | B6: 1
A10: 200 | B10: SOFT COSTS
A11: 201 | B11: DESCRIPTION | C11: QTY | D11: UNIT PRICE | E11: BUDGET TOTAL | F11: NOTES
B12: Abatement
A13: 1 | B13: Pipe Insulation Abatement | C13: 190 | D13: 72 | E13: =C13*D13 -> 13680
A14: 2 | B14: Roof Abatement | C14: 70000 | D14: 21 | E14: =C14*D14 -> 1470000
B16: Total Abatement | E16: =SUM(E13:E15) -> 1483680
A17: 202 | B17: DESCRIPTION | C17: QTY | D17: UNIT PRICE | E17: BUDGET TOTAL | F17: NOTES
B18: Feasibility Study
A19: 1 | B19: Due Diligence & Feasibility Study | C19: 1 | D19: 342000 | E19: =C19*D19 -> 342000
B21: Total Feasibility Study | E21: =E19 -> 342000
A22: 203 | B22: DESCRIPTION | C22: QTY | D22: UNIT PRICE | E22: BUDGET TOTAL | F22: NOTES
B23: Architectural Fees
A24: 1 | B24: Conceptual & Brand Development | C24: 1 | D24: 45000 | E24: =C24*D24 -> 45000
A25: =A24+1 -> 2 | B25: Interior Design | C25: 1 | D25: 90000 | E25: =C25*D25 -> 90000
A26: =A25+1 -> 3 | B26: Architecture & Engineering | C26: 1 | D26: 3100000 | E26: =C26*D26 -> 3100000
A27: =A26+1 -> 4 | B27: Architecture | D27: 0 | E27: =C27*D27 -> 0 | F27: Carried in line #3
A28: =A27+1 -> 5 | B28: MEP Engineering | D28: 0 | E28: =C28*D28 -> 0 | F28: Carried in line #3
A29: =A28+1 -> 6 | B29: Structural Engineering | D29: 0 | E29: =C29*D29 -> 0 | F29: Carried in line #3
A30: =A29+1 -> 7 | B30: MEP Consultant | C30: 1 | D30: 30000 | E30: =C30*D30 -> 30000
A31: =A30+1 -> 8 | B31: Lighting Design (Bandit) | C31: 1 | D31: 51000 | E31: =C31*D31 -> 51000
A32: =A31+1 -> 9 | B32: Kitchen Equipment Design (TriMark) | C32: 1 | D32: 20000 | E32: =C32*D32 -> 20000
A33: =A32+1 -> 10 | B33: LV/AV Design | C33: 1 | D33: 35000 | E33: =C33*D33 -> 35000
A34: =A33+1 -> 11 | B34: Signage & Way Finding Design | C34: 1 | D34: 75000 | E34: =C34*D34 -> 75000
A35: =A34+1 -> 12 | B35: Renderings | C35: 1 | D35: 50000 | E35: =C35*D35 -> 50000
A36: =A35+1 -> 13 | B36: Reimbursables | C36: 1 | D36: 30000 | E36: =C36*D36 -> 30000
B38: Total Architectural Fees | E38: =SUM(E24:E37) -> 3526000
A39: 204 | B39: DESCRIPTION | C39: QTY | D39: UNIT PRICE | E39: BUDGET TOTAL | F39: NOTES
B40: Civil Engineering
A41: 1 | B41: Civil Engineering | C41: 1 | D41: 10000 | E41: =C41*D41 -> 10000 | F41: Exterior work: New Sidewalks, Street Work
B43: Total Civil Engineering | E43: =SUM(E41:E41) -> 10000
A44: 205 | B44: DESCRIPTION | C44: QTY | D44: UNIT PRICE | E44: BUDGET TOTAL | F44: NOTES
B45: Traffic Engineering
A46: 1 | B46: Traffic Engineering | C46: 1 | D46: 10000 | E46: =C46*D46 -> 10000 | F46: Verify w/ Traffic Consultant Report
A47: 2 | D47: 0 | E47: =C47*D47 -> 0
...

Sheet Building & Fit-outBudget Detail
A1: Venue
A2: Scope : | B2: ='Soft Cost & FF&E Budget Detail'!B2 -> Warehouse Conversion / Add Second Level & Roof Decks
A3: Capacity: | B3: 7440
A4: SF: | B4: ='Soft Cost & FF&E Budget Detail'!B4 -> 135953
A5: Date: | B5: 46281
A6: Version: | B6: ='Soft Cost & FF&E Budget Detail'!B6 -> 1
A9: 100 | B9: BUILDING & FIT-OUT COSTS
A10: CSI # | B10: TRADE | C10: BUDGET | D10: COST/SF | E10: NOTES
A11: 013000 | B11: PROJECT REQUIREMENTS | C11: ='Building & Fit-out Breakdown'!F27 -> 3034000 | D11: =C11/$B$4 -> 22.316536
A12: 015800 | B12: SCAFFOLDING & STAGING | C12: ='Building & Fit-out Breakdown'!F37 -> 6170000 | D12: =C12/$B$4 -> 45.383331
A13: 024100 | B13: DEMOLITION | C13: ='Building & Fit-out Breakdown'!F63 -> 1287817 | D13: =C13/$B$4 -> 9.4725162
A14: 033000 | B14: CONCRETE | C14: ='Building & Fit-out Breakdown'!F93 -> 177450 | D14: =C14/$B$4 -> 1.3052305
A15: 042000 | B15: MASONRY | C15: ='Building & Fit-out Breakdown'!F119 -> 530010 | D15: =C15/$B$4 -> 3.8984796
A16: 044000 | B16: STONE & CERAMICS | C16: ='Building & Fit-out Breakdown'!F127 -> 764340 | D16: =C16/$B$4 -> 5.62209
A17: 055100 | B17: STRUCTURAL STEEL & MISC METALS | C17: ='Building & Fit-out Breakdown'!F151 -> 0 | D17: =C17/$B$4 -> 0
A18: 061000 | B18: ROUGH CARPENTRY | C18: ='Building & Fit-out Breakdown'!F160 -> 0 | D18: =C18/$B$4 -> 0
A19: 064000 | B19: MILLWORK AND FURNITURE INSTALL | C19: ='Building & Fit-out Breakdown'!F182 -> 0 | D19: =C19/$B$4 -> 0
A20: 075000 | B20: ROOFING | C20: ='Building & Fit-out Breakdown'!F196 -> 2557428 | D20: =C20/$B$4 -> 18.811119
A21: 078100 | B21: FIREPROOFING | C21: ='Building & Fit-out Breakdown'!F204 -> 0 | D21: =C21/$B$4 -> 0
A22: 081000 | B22: DOORS, FRAMES & HARDWARE | C22: ='Building & Fit-out Breakdown'!F213 -> 0 | D22: =C22/$B$4 -> 0
A23: 083000 | B23: SPECIAL DOORS | C23: ='Building & Fit-out Breakdown'!F219 -> 76000 | D23: =C23/$B$4 -> 0.55901672
A24: 084100 | B24: STOREFRONT | C24: ='Building & Fit-out Breakdown'!F229 -> 0 | D24: =C24/$B$4 -> 0
A25: 088000 | B25: GLASS/GLAZING | C25: ='Building & Fit-out Breakdown'!F237 -> 0 | D25: =C25/$B$4 -> 0
A26: 092000 | B26: DRYWALL | C26: ='Building & Fit-out Breakdown'!F270 -> 119664 | D26: =C26/$B$4 -> 0.88018654
A27: 092300 | B27: TILE/BRICK TILE | C27: ='Building & Fit-out Breakdown'!F279 -> 0 | D27: =C27/$B$4 -> 0
A28: 096000 | B28: CARPET/RESILIENT FLOORING | C28: ='Building & Fit-out Breakdown'!F294 -> 765048 | D28: =C28/$B$4 -> 5.6272977
A29: 096050 | B29: FLOOR PREPARATION | C29: ='Building & Fit-out Breakdown'!F302 -> 515298 | D29: =C29/$B$4 -> 3.7902658
A30: 096400 | B30: WOOD FLOORING | C30: ='Building & Fit-out Breakdown'!F308 -> 373050 | D30: =C30/$B$4 -> 2.743963
A31: 099000 | B31: PAINTING/PLASTER | C31: ='Building & Fit-out Breakdown'!F316 -> 1091765 | D31: =C31/$B$4 -> 8.0304591
A32: 100000 | B32: SPECIALITIES | C32: ='Building & Fit-out Breakdown'!F328 -> 1548500 | D32: =C32/$B$4 -> 11.389966
A33: 100500 | B33: ACOUSTICAL PANELS/K13 | C33: ='Building & Fit-out Breakdown'!F334 -> 581802 | D33: =C33/$B$4 -> 4.2794348
A34: 101400 | B34: SIGNAGE | C34: ='Building & Fit-out Breakdown'!F341 -> 50000 | D34: =C34/$B$4 -> 0.36777416
A35: 120000 | B35: FF&E INSTALL | C35: ='Building & Fit-out Breakdown'!F346 -> 50000 | D35: =C35/$B$4 -> 0.36777416
A36: 114000 | B36: FOOD SERVICE AND BAR EQUIPMENT | C36: ='Building & Fit-out Breakdown'!F354 -> 50000 | D36: =C36/$B$4 -> 0.36777416
A37: 142000 | B37: ELEVATOR | C37: ='Building & Fit-out Breakdown'!F361 -> 480000 | D37: =C37/$B$4 -> 3.5306319
A38: 210000 | B38: FIRE PROTECTION | C38: ='Building & Fit-out Breakdown'!F371 -> 1334070 | D38: =C38/$B$4 -> 9.8127294
A39: 220000 | B39: PLUMBING | C39: ='Building & Fit-out Breakdown'!F412 -> 3717250 | D39: =C39/$B$4 -> 27.34217
A40: 230000 | B40: HVAC | C40: ='Building & Fit-out Breakdown'!F417 -> 5964390 | D40: =C40/$B$4 -> 43.87097
A41: 260000 | B41: ELECTRIC | C41: ='Building & Fit-out Breakdown'!F456 -> 5512336.8 | D41: =C41/$B$4 -> 40.5459
A42: 270000 | B42: LOW VOLTAGE CABLING | C42: ='Building & Fit-out Breakdown'!F464 -> 227500 | D42: =C42/$B$4 -> 1.6733724
...

Sheet Building & Fit-out Breakdown
A1: Venue
A2: Scope: | B2: ='Building & Fit-outBudget Detail'!B2 -> Warehouse Conversion / Add Second Level & Roof Decks
A3: Capacity: | B3: 7440
A4: SF: | B4: =3500+69722+53379+9352 -> 135953
A5: Date: | B5: ='Building & Fit-outBudget Detail'!B5 -> 46281
A6: Architect: | B6: Wake
A7: Version: | B7: ='Building & Fit-outBudget Detail'!B6 -> 1
A10: ITEM | B10: DESCRIPTION | C10: QTY | D10: UNIT | E10: UNIT PRICE | F10: TOTAL | G10: NOTES
A12: 013000 | B12: PROJECT REQUIREMENTS
A13: 1 | B13: BIM Set Up & Coordination | C13: 1 | D13: LS | E13: 30000 | F13: =C13*E13 -> 30000
A14: =A13+1 -> 2 | B14: Plans / Reprographics | C14: 1 | D14: LS | E14: 7500 | F14: =C14*E14 -> 7500
A15: =A14+1 -> 3 | B15: Site Office & Equipment | C15: 1 | D15: LS | E15: 12000 | F15: =C15*E15 -> 12000
A16: =A15+1 -> 4 | B16: Field Techonology | C16: 1 | D16: LS | E16: 200000 | F16: =C16*E16 -> 200000
A17: =A16+1 -> 5 | B17: Construction Signage | C17: 1 | D17: LS | E17: 4500 | F17: =C17*E17 -> 4500
A18: =A17+1 -> 6 | B18: Site Security | C18: 1 | D18: LS | E18: 13000 | F18: =C18*E18 -> 13000
A19: =A18+1 -> 7 | B19: Site Safety Plan / First Aid / TPP / FE's / Safety Inspector | C19: 1 | D19: LS | E19: 400000 | F19: =C19*E19 -> 400000
A20: =A19+1 -> 8 | B20: Portable Toilets | C20: 80 | D20: WK | E20: 400 | F20: =C20*E20 -> 32000
A21: =A20+1 -> 9 | B21: Clean up Materials | C21: 1 | D21: LS | E21: 65000 | F21: =C21*E21 -> 65000
A22: =A21+1 -> 10 | B22: Protection Materials | C22: 1 | D22: LS | E22: 50000 | F22: =C22*E22 -> 50000
A23: =A22+1 -> 11 | B23: Project Labor | C23: 1 | D23: LS | E23: 2000000 | F23: =C23*E23 -> 2000000
A24: =A23+1 -> 12 | B24: Project Rubbish Removals | C24: 1 | D24: LS | E24: 120000 | F24: =C24*E24 -> 120000
A25: =A24+1 -> 13 | B25: Final Clean | C25: 1 | D25: LS | E25: 100000 | F25: =C25*E25 -> 100000
A27: Sub Total | B27: =B12 -> PROJECT REQUIREMENTS | F27: =SUM(F11:F26) -> 3034000
A29: 015800 | B29: SCAFFOLDING & HOARDING
A30: 1 | B30: Install sidewalk bridge and scaffolding around building | C30: 1 | D30: LS | E30: 4000000 | F30: =E30*C30 -> 4000000 | I30: 500/LF bridge
C31: 1126 | D31: LF | E31: 500
C32: =(1126*6)*4 -> 27024 | D32: SF | E32: 75
A33: 2 | B33: Interior scaffolding | C33: 1 | D33: LS | E33: 2000000 | F33: =E33*C33 -> 2000000 | I33: $75/SF for scaffolding
A34: 3 | B34: Barricades | C34: 1 | D34: LS | E34: 150000 | F34: =E34*C34 -> 150000
B35: Site safety During Erection | C35: 1 | D35: LS | E35: 20000 | F35: =E35*C35 -> 20000
A36: 4
A37: Sub Total | B37: =B29 -> SCAFFOLDING & HOARDING | F37: =SUM(F28:F36) -> 6170000
A39: 024100 | B39: DEMOLITION
A40: 1 | B40: Demo existing CMU/masonry walls at new Entry/Lobby area | C40: 2500 | D40: SF | E40: 12 | F40: =C40*E40 -> 30000
A41: =A40+1 -> 2 | B41: Demo 8" CMU interior wall 20' tall | C41: 1975 | D41: SF | E41: 12 | F41: =C41*E41 -> 23700
A42: =A41+1 -> 3 | B42: Demo 8" CMU interior wall 12' tall | C42: =628*12 -> 7536 | D42: SF | E42: 12 | F42: =C42*E42 -> 90432
A43: =A42+1 -> 4 | B43: Demo office area partitions, ceilings, doors, flooring MEP's, (CMU walls line above) | C43: 6825 | D43: SF | E43: 5 | F43: =C43*E43 -> 34125
A44: =A43+1 -> 5 | B44: Demo existing exterior roll up doors | C44: 8 | D44: EA | E44: 5000 | F44: =C44*E44 -> 40000
A45: =A44+1 -> 6 | B45: Demo existing exterior doors | C45: 7 | D45: EA | E45: 250 | F45: =C45*E45 -> 1750
A46: =A45+1 -> 7 | B46: Demo existing windows 1'x10' | C46: 34 | D46: EA | E46: 300 | F46: =C46*E46 -> 10200
...

Sheet General Conditions
B3: Exec | C3: 10 | D3: 9200 | E3: =C3*D3 -> 92000
B4: PM | C4: 90 | D4: 6400 | E4: =C4*D4 -> 576000
B5: APM | C5: 90 | D5: 4600 | E5: =C5*D5 -> 414000
B6: Engineer | C6: 90 | D6: 3900 | E6: =C6*D6 -> 351000
B7: Accoutnant | C7: 10 | D7: 2800 | E7: =C7*D7 -> 28000
E8: =C8*D8 -> 0
B9: Super | C9: 90 | D9: 6000 | E9: =C9*D9 -> 540000
B10: Super | C10: 90 | D10: 6000 | E10: =C10*D10 -> 540000
B11: Super | C11: 90 | D11: 6000 | E11: =C11*D11 -> 540000
B12: General Super | C12: 10 | D12: 6000 | E12: =C12*D12 -> 60000
E13: =SUM(E3:E12) -> 3141000

Sheet Project At-a-Glance
B8: Cost Report Date: | C8: 44957 | F8: Venue Capacity: | G8: TBD
B9: Project Name: | F9: Landlord Work Start Date: | G9: TBD
B10: Location: | F10: LNE Work Start Date: | G10: TBD
B11: Address: | F11: Certificate of Occupancy: | G11: TBD
B12: Project Number: | F12: First Show Date: | G12: TBD
B13: Budget: | C13: =C25 -> #REF! | F13: Project Completion Date: | G13: TBD
B14: Venue EVP: | C14: TBD | F14: Project Manager: | G14: TBD
B17: Description | C17: Budget | D17: Committed Costs Total | E17: Costs to Date Total | F17: Remaining Estimate | G17: Estimated Final Cost | H17: Budget vs EFC Variance
D18: Total | E18: Total
B19: ='Project Detail'!D4 -> Building Costs | C19: ='Project Summary '!C9 -> 63651265 | D19: ='Project Summary '!D9 -> 0 | E19: ='Project Summary '!E9 -> 0 | F19: ='Project Summary '!F9 -> 63651265 | G19: ='Project Summary '!G9 -> 63651265 | H19: ='Project Summary '!H9 -> 0
B20: ='Project Detail'!D33 -> Soft Costs | C20: ='Project Summary '!C15 -> #REF! | D20: ='Project Summary '!D15 -> 0 | E20: ='Project Summary '!E15 -> 0 | F20: ='Project Summary '!F15 -> #REF! | G20: ='Project Summary '!G15 -> #REF! | H20: ='Project Summary '!H15 -> #REF!
B21: FF&E Costs | C21: ='Project Summary '!C27 -> #REF! | D21: ='Project Summary '!D27 -> 0 | E21: ='Project Summary '!E27 -> 0 | F21: ='Project Summary '!F27 -> #REF! | G21: ='Project Summary '!G27 -> #REF! | H21: ='Project Summary '!H27 -> #REF!
B23: ='Project Summary '!B29 -> Sub-Total | C23: =SUM(C19:C21) -> #REF! | D23: =SUM(D19:D21) -> 0 | E23: =SUM(E19:E21) -> 0 | F23: =SUM(F19:F21) -> #REF! | G23: =SUM(G19:G21) -> #REF! | H23: =SUM(H19:H21) -> #REF!
B24: Total Contingency | C24: ='Project Summary '!C30 -> 8098599.2 | F24: =Contingency!G9 -> 8098599.2 | G24: =Contingency!G9 -> 8098599.2 | H24: =C24-G24 -> 0
B25: TOTAL | C25: =SUM(C23:C24) -> #REF! | D25: =SUM(D23:D24) -> 0 | E25: =SUM(E23:E24) -> 0 | F25: =SUM(F23:F24) -> #REF! | G25: =SUM(G23:G24) -> #REF! | H25: =SUM(H23:H24) -> #REF!
B28: Risk Summary
B29: Risk Report Total | D29: ='Risk Report'!G15 -> 0
B30: Remaining Contingency | D30: ='Risk Report'!G19 -> 8098599.2
B31: Exposure | D31: ='Risk Report'!G23 -> 0
B32: Estimated Final Cost (Including Risk Items) | D32: =G25+D31 -> #REF!

Sheet Project Summary 
B2: Description | C2: Budget | D2: Committed Costs | E2: Costs to Date | F2: Remaining Estimate | G2: Estimated Final Cost | H2: Budget vs EFC Variance
D3: Total | E3: Total
B4: ='Project Detail'!D4 -> Building Costs
B5: ='Project Detail'!D5 -> Building & Fit-Out Costs | C5: ='Project Detail'!F10 -> 63651265 | D5: ='Project Detail'!G10 -> 0 | E5: ='Project Detail'!K10 -> 0 | F5: ='Project Detail'!L10 -> 63651265 | G5: ='Project Detail'!M10 -> 63651265 | H5: ='Project Detail'!N10 -> 0
B6: ='Project Detail'!D11 -> Secondary Contractors | C6: ='Project Detail'!F16 -> 0 | D6: ='Project Detail'!G16 -> 0 | E6: ='Project Detail'!K16 -> 0 | F6: ='Project Detail'!L16 -> 0 | G6: ='Project Detail'!M16 -> 0 | H6: ='Project Detail'!N16 -> 0
B7: ='Project Detail'!D17 -> Miscellaneous | C7: ='Project Detail'!F22 -> 0 | D7: ='Project Detail'!G22 -> 0 | E7: ='Project Detail'!K22 -> 0 | F7: ='Project Detail'!L22 -> 0 | G7: ='Project Detail'!M22 -> 0 | H7: ='Project Detail'!N22 -> 0
B8: ='Project Detail'!D23 -> 0 | C8: ='Project Detail'!F28 -> 0 | D8: ='Project Detail'!G28 -> 0 | E8: ='Project Detail'!K28 -> 0 | F8: ='Project Detail'!L28 -> 0 | G8: ='Project Detail'!M28 -> 0 | H8: ='Project Detail'!N28 -> 0
B9: Building Costs Total | C9: =SUM(C5:C8) -> 63651265 | D9: =SUM(D5:D8) -> 0 | E9: =SUM(E5:E8) -> 0 | F9: =SUM(F5:F8) -> 63651265 | G9: =SUM(G5:G8) -> 63651265 | H9: =SUM(H5:H8) -> 0
B11: ='Project Detail'!D33 -> Soft Costs
B12: ='Project Detail'!D34 -> Project Management | C12: ='Project Detail'!F39 -> #REF! | D12: ='Project Detail'!G39 -> 0 | E12: ='Project Detail'!K39 -> 0 | F12: ='Project Detail'!L39 -> #REF! | G12: ='Project Detail'!M39 -> #REF! | H12: ='Project Detail'!N39 -> #REF!
B13: ='Project Detail'!D40 -> Architectural Fees | C13: ='Project Detail'!F45 -> 3526000 | D13: ='Project Detail'!G45 -> 0 | E13: ='Project Detail'!K45 -> 0 | F13: ='Project Detail'!L45 -> 0 | G13: ='Project Detail'!M45 -> 0 | H13: ='Project Detail'!N45 -> 3526000
B14: ='Project Detail'!D46 -> Design, Engineering & Misc. | C14: ='Project Detail'!F57 -> #REF! | D14: ='Project Detail'!G57 -> 0 | E14: ='Project Detail'!K57 -> 0 | F14: ='Project Detail'!L57 -> 0 | G14: ='Project Detail'!M57 -> 0 | H14: ='Project Detail'!N57 -> #REF!
B15: Soft Costs Total | C15: =SUM(C12:C14) -> #REF! | D15: =SUM(D12:D14) -> 0 | E15: =SUM(E12:E14) -> 0 | F15: =SUM(F12:F14) -> #REF! | G15: =SUM(G12:G14) -> #REF! | H15: =SUM(H12:H14) -> #REF!
B17: ='Project Detail'!D62 -> FF&E Costs
B18: ='Project Detail'!D63 -> Seating | C18: ='Project Detail'!F82 -> #REF! | D18: ='Project Detail'!G82 -> 0 | E18: ='Project Detail'!K82 -> 0 | F18: ='Project Detail'!L82 -> #REF! | G18: ='Project Detail'!M82 -> #REF! | H18: ='Project Detail'!N82 -> #REF!
B19: ='Project Detail'!D83 -> Concessions | C19: ='Project Detail'!F88 -> #REF! | D19: ='Project Detail'!G88 -> 0 | E19: ='Project Detail'!K88 -> 0 | F19: ='Project Detail'!L88 -> 0 | G19: ='Project Detail'!M88 -> 0 | H19: ='Project Detail'!N88 -> #REF!
B20: ='Project Detail'!D89 -> Phone & Data Systems | C20: ='Project Detail'!F92 -> 420000 | D20: ='Project Detail'!G92 -> 0 | E20: ='Project Detail'!K92 -> 0 | F20: ='Project Detail'!L92 -> 420000 | G20: ='Project Detail'!M92 -> 420000 | H20: ='Project Detail'!N92 -> 0
B21: ='Project Detail'!D93 -> Office Furniture | C21: ='Project Detail'!F99 -> 65000 | D21: ='Project Detail'!G99 -> 0 | E21: ='Project Detail'!K99 -> 0 | F21: ='Project Detail'!L99 -> 0 | G21: ='Project Detail'!M99 -> 0 | H21: ='Project Detail'!N99 -> 65000
B22: ='Project Detail'!D100 -> Signage/Graphics | C22: ='Project Detail'!F118 -> 0 | D22: ='Project Detail'!G118 -> 0 | E22: ='Project Detail'!K118 -> 0 | F22: ='Project Detail'!L118 -> 0 | G22: ='Project Detail'!M118 -> 0 | H22: ='Project Detail'!N118 -> 0
B23: ='Project Detail'!D119 -> Administration | C23: ='Project Detail'!F130 -> 93000 | D23: ='Project Detail'!G130 -> 0 | E23: ='Project Detail'!K130 -> 0 | F23: ='Project Detail'!L130 -> 0 | G23: ='Project Detail'!M130 -> 0 | H23: ='Project Detail'!N130 -> 93000
B24: ='Project Detail'!D131 -> Facility | C24: ='Project Detail'!F138 -> 0 | D24: ='Project Detail'!G138 -> 0 | E24: ='Project Detail'!K138 -> 0 | F24: ='Project Detail'!L138 -> 0 | G24: ='Project Detail'!M138 -> 0 | H24: ='Project Detail'!N138 -> 0
B25: ='Project Detail'!D139 -> Operations | C25: ='Project Detail'!F150 -> 0 | D25: ='Project Detail'!G150 -> 0 | E25: ='Project Detail'!K150 -> 0 | F25: ='Project Detail'!L150 -> 0 | G25: ='Project Detail'!M150 -> 0 | H25: ='Project Detail'!N150 -> 0
B26: ='Project Detail'!D151 -> Production | C26: ='Project Detail'!F166 -> 4128500 | D26: ='Project Detail'!G166 -> 0 | E26: ='Project Detail'!K166 -> 0 | F26: ='Project Detail'!L166 -> 0 | G26: ='Project Detail'!M166 -> 0 | H26: ='Project Detail'!N166 -> 4128500
B27: FF&E Costs Total | C27: =SUM(C18:C26) -> #REF! | D27: =SUM(D18:D26) -> 0 | E27: =SUM(E18:E26) -> 0 | F27: =SUM(F18:F26) -> #REF! | G27: =SUM(G18:G26) -> #REF! | H27: =SUM(H18:H26) -> #REF!
B29: Sub-Total | C29: =+C9+C15+C27 -> #REF! | D29: =+D9+D15+D27 -> 0 | E29: =+E9+E15+E27 -> 0 | F29: =+F9+F15+F27 -> #REF! | G29: =+G9+G15+G27 -> #REF! | H29: =+H9+H15+H27 -> #REF!
B30: Contingency | C30: ='Project Detail'!F170 -> 8098599.2 | F30: =Contingency!G9 -> 8098599.2 | G30: =Contingency!G9 -> 8098599.2 | H30: =C30-G30 -> 0
B31: GRAND TOTAL | C31: =SUM(C29:C30) -> #REF! | D31: =SUM(D29:D30) -> 0 | E31: =SUM(E29:E30) -> 0 | F31: =SUM(F29:F30) -> #REF! | G31: =SUM(G29:G30) -> #REF! | H31: =SUM(H29:H30) -> #REF!

Sheet Project Detail
B2: Code | C2: Cost Code | D2: Vendor | E2: Description | F2: Budget | G2: Committed Costs | H2: Change Orders | I2: Costs to Date (Gross) | J2: Retention | K2: Costs to Date | L2: Remaining Estimate | M2: Estimated Final Cost | N2: Budget vs EFC Variance | O2: Notes | Q2: Remaining to Invoice | S2: P11-21 (Fcst) | T2: P12-21 (Fcst) | U2: Q4-21 TOTAL (Fcst) | W2: P01-22 (Fcst) | X2: P02-22 (Fcst) | Y2: P03-22 (Fcst) | Z2: Q1-22 TOTAL (Fcst) | AB2: Q4-21/Q1-22 TOTAL | AD2: Remaining to Allocate
B4: 100 | D4: Building Costs
B5: 101 | D5: Building & Fit-Out Costs
B6: 101-1 | D6: General Contractor | F6: ='Budget Summary'!D31 -> 63651265 | G6: =SUMIF('Committed Costs '!C:C,B6,'Committed Costs '!G:G) -> 0 | H6: =SUMIF('Change Orders'!F:F,'Project Detail'!B6,'Change Orders'!E:E) -> 0 | I6: =SUMIF(Invoices!B:B,B6,Invoices!G:G) -> 0 | J6: 0 | K6: =I6-J6 -> 0 | L6: =+M6-G6 -> 63651265 | M6: =IF((F6+H6)>G6,F6+H6,G6) -> 63651265 | N6: =F6-M6 -> 0
B7: 101-2 | F7: 0 | G7: =SUMIF('Committed Costs '!C:C,B7,'Committed Costs '!G:G) -> 0 | H7: =SUMIF('Change Orders'!F:F,'Project Detail'!B7,'Change Orders'!E:E) -> 0 | I7: =SUMIF(Invoices!B:B,B7,Invoices!G:G) -> 0 | J7: 0 | K7: =I7-J7 -> 0 | L7: =+M7-G7 -> 0 | M7: =IF((F7+H7)>G7,F7+H7,G7) -> 0 | N7: =F7-M7 -> 0
B8: 101-3 | F8: 0 | G8: =SUMIF('Committed Costs '!C:C,B8,'Committed Costs '!G:G) -> 0 | H8: =SUMIF('Change Orders'!F:F,'Project Detail'!B8,'Change Orders'!E:E) -> 0 | I8: =SUMIF(Invoices!B:B,B8,Invoices!G:G) -> 0 | J8: 0 | K8: =I8-J8 -> 0 | L8: =+M8-G8 -> 0 | M8: =IF((F8+H8)>G8,F8+H8,G8) -> 0 | N8: =F8-M8 -> 0
B9: 101-4 | F9: 0 | G9: =SUMIF('Committed Costs '!C:C,B9,'Committed Costs '!G:G) -> 0 | H9: =SUMIF('Change Orders'!F:F,'Project Detail'!B9,'Change Orders'!E:E) -> 0 | I9: =SUMIF(Invoices!B:B,B9,Invoices!G:G) -> 0 | J9: 0 | K9: =I9-J9 -> 0 | L9: =+M9-G9 -> 0 | M9: =IF((F9+H9)>G9,F9+H9,G9) -> 0 | N9: =F9-M9 -> 0 | Q9: =M9-K9 -> 0 | U9: =S9+T9 -> 0 | Z9: =W9+X9+Y9 -> 0 | AB9: =U9+Z9 -> 0 | AD9: =Q9-AB9 -> 0
C10: 101 | E10: Total Building & Fit-Out Costs | F10: =SUM(F6:F9) -> 63651265 | G10: =SUM(G6:G9) -> 0 | H10: =SUM(H6:H9) -> 0 | I10: =SUM(I6:I9) -> 0 | J10: =SUM(J6:J9) -> 0 | K10: =SUM(K6:K9) -> 0 | L10: =SUM(L6:L9) -> 63651265 | M10: =SUM(M6:M9) -> 63651265 | N10: =SUM(N6:N9) -> 0 | Q10: =Q9 -> 0 | S10: =S9 -> 0 | T10: =T9 -> 0 | U10: =U9 -> 0 | W10: =W9 -> 0 | X10: =X9 -> 0 | Y10: =Y9 -> 0 | Z10: =Z9 -> 0 | AB10: =AB9 -> 0 | AD10: =AD9 -> 0
B11: 102 | D11: Secondary Contractors
B12: 102-1 | F12: 0 | G12: =SUMIF('Committed Costs '!C:C,B12,'Committed Costs '!G:G) -> 0 | H12: =SUMIF('Change Orders'!F:F,'Project Detail'!B12,'Change Orders'!E:E) -> 0 | I12: =SUMIF(Invoices!B:B,B12,Invoices!G:G) -> 0 | J12: 0 | K12: =I12-J12 -> 0 | L12: =+M12-G12 -> 0 | M12: =IF((F12+H12)>G12,F12+H12,G12) -> 0 | N12: =F12-M12 -> 0
B13: 102-2 | F13: 0 | G13: =SUMIF('Committed Costs '!C:C,B13,'Committed Costs '!G:G) -> 0 | H13: =SUMIF('Change Orders'!F:F,'Project Detail'!B13,'Change Orders'!E:E) -> 0 | I13: =SUMIF(Invoices!B:B,B13,Invoices!G:G) -> 0 | J13: 0 | K13: =I13-J13 -> 0 | L13: =+M13-G13 -> 0 | M13: =IF((F13+H13)>G13,F13+H13,G13) -> 0 | N13: =F13-M13 -> 0
B14: 102-3 | F14: 0 | G14: =SUMIF('Committed Costs '!C:C,B14,'Committed Costs '!G:G) -> 0 | H14: =SUMIF('Change Orders'!F:F,'Project Detail'!B14,'Change Orders'!E:E) -> 0 | I14: =SUMIF(Invoices!B:B,B14,Invoices!G:G) -> 0 | J14: 0 | K14: =I14-J14 -> 0 | L14: =+M14-G14 -> 0 | M14: =IF((F14+H14)>G14,F14+H14,G14) -> 0 | N14: =F14-M14 -> 0
B15: 102-4 | F15: 0 | G15: =SUMIF('Committed Costs '!C:C,B15,'Committed Costs '!G:G) -> 0 | H15: =SUMIF('Change Orders'!F:F,'Project Detail'!B15,'Change Orders'!E:E) -> 0 | I15: =SUMIF(Invoices!B:B,B15,Invoices!G:G) -> 0 | J15: 0 | K15: =I15-J15 -> 0 | L15: =+M15-G15 -> 0 | M15: =IF((F15+H15)>G15,F15+H15,G15) -> 0 | N15: =F15-M15 -> 0 | Q15: =M15-K15 -> 0 | U15: =S15+T15 -> 0 | Z15: =W15+X15+Y15 -> 0 | AB15: =U15+Z15 -> 0 | AD15: =Q15-AB15 -> 0
C16: 102 | E16: Total Secondary Contractors | F16: =SUM(F12:F15) -> 0 | G16: =SUM(G12:G15) -> 0 | H16: =SUM(H12:H15) -> 0 | I16: =SUM(I12:I15) -> 0 | J16: =SUM(J12:J15) -> 0 | K16: =SUM(K12:K15) -> 0 | L16: =SUM(L12:L15) -> 0 | M16: =SUM(M12:M15) -> 0 | N16: =SUM(N12:N15) -> 0 | Q16: =Q15 -> 0 | S16: =S15 -> 0 | T16: =T15 -> 0 | U16: =U15 -> 0 | W16: =W15 -> 0 | X16: =X15 -> 0 | Y16: =Y15 -> 0 | Z16: =Z15 -> 0 | AB16: =AB15 -> 0 | AD16: =AD15 -> 0
B17: 103 | D17: Miscellaneous
B18: 103-1 | F18: 0 | G18: =SUMIF('Committed Costs '!C:C,B18,'Committed Costs '!G:G) -> 0 | H18: =SUMIF('Change Orders'!F:F,'Project Detail'!B18,'Change Orders'!E:E) -> 0 | I18: =SUMIF(Invoices!B:B,B18,Invoices!G:G) -> 0 | J18: 0 | K18: =I18-J18 -> 0 | L18: =+M18-G18 -> 0 | M18: =IF((F18+H18)>G18,F18+H18,G18) -> 0 | N18: =F18-M18 -> 0
B19: 103-2 | F19: 0 | G19: =SUMIF('Committed Costs '!C:C,B19,'Committed Costs '!G:G) -> 0 | H19: =SUMIF('Change Orders'!F:F,'Project Detail'!B19,'Change Orders'!E:E) -> 0 | I19: =SUMIF(Invoices!B:B,B19,Invoices!G:G) -> 0 | J19: 0 | K19: =I19-J19 -> 0 | L19: =+M19-G19 -> 0 | M19: =IF((F19+H19)>G19,F19+H19,G19) -> 0 | N19: =F19-M19 -> 0
B20: 103-3 | F20: 0 | G20: =SUMIF('Committed Costs '!C:C,B20,'Committed Costs '!G:G) -> 0 | H20: =SUMIF('Change Orders'!F:F,'Project Detail'!B20,'Change Orders'!E:E) -> 0 | I20: =SUMIF(Invoices!B:B,B20,Invoices!G:G) -> 0 | J20: 0 | K20: =I20-J20 -> 0 | L20: =+M20-G20 -> 0 | M20: =IF((F20+H20)>G20,F20+H20,G20) -> 0 | N20: =F20-M20 -> 0
B21: 103-4 | F21: 0 | G21: =SUMIF('Committed Costs '!C:C,B21,'Committed Costs '!G:G) -> 0 | H21: =SUMIF('Change Orders'!F:F,'Project Detail'!B21,'Change Orders'!E:E) -> 0 | I21: =SUMIF(Invoices!B:B,B21,Invoices!G:G) -> 0 | J21: 0 | K21: =I21-J21 -> 0 | L21: =+M21-G21 -> 0 | M21: =IF((F21+H21)>G21,F21+H21,G21) -> 0 | N21: =F21-M21 -> 0 | Q21: =M21-K21 -> 0 | U21: =S21+T21 -> 0 | Z21: =W21+X21+Y21 -> 0 | AB21: =U21+Z21 -> 0 | AD21: =Q21-AB21 -> 0
C22: 103 | E22: Total Mics. | F22: =SUM(F18:F21) -> 0 | G22: =SUM(G18:G21) -> 0 | H22: =SUM(H18:H21) -> 0 | I22: =SUM(I18:I21) -> 0 | J22: =SUM(J18:J21) -> 0 | K22: =SUM(K18:K21) -> 0 | L22: =SUM(L18:L21) -> 0 | M22: =SUM(M18:M21) -> 0 | N22: =SUM(N18:N21) -> 0 | Q22: =Q21 -> 0 | S22: =S21 -> 0 | T22: =T21 -> 0 | U22: =U21 -> 0 | W22: =W21 -> 0 | X22: =X21 -> 0 | Y22: =Y21 -> 0 | Z22: =Z21 -> 0 | AB22: =AB21 -> 0 | AD22: =AD21 -> 0
B23: 104
B24: 104-1 | F24: 0 | G24: =SUMIF('Committed Costs '!C:C,B24,'Committed Costs '!G:G) -> 0 | H24: =SUMIF('Change Orders'!F:F,'Project Detail'!B24,'Change Orders'!E:E) -> 0 | I24: =SUMIF(Invoices!B:B,B24,Invoices!G:G) -> 0 | J24: 0 | K24: =I24-J24 -> 0 | L24: =+M24-G24 -> 0 | M24: =K24 -> 0 | N24: =F24-M24 -> 0
B25: 104-2 | F25: 0 | G25: =SUMIF('Committed Costs '!C:C,B25,'Committed Costs '!G:G) -> 0 | H25: =SUMIF('Change Orders'!F:F,'Project Detail'!B25,'Change Orders'!E:E) -> 0 | I25: =SUMIF(Invoices!B:B,B25,Invoices!G:G) -> 0 | J25: 0 | K25: =I25-J25 -> 0 | L25: =+M25-G25 -> 0 | M25: =IF((F25+H25)>G25,F25+H25,G25) -> 0 | N25: =F25-M25 -> 0
B26: 104-3 | F26: 0 | G26: =SUMIF('Committed Costs '!C:C,B26,'Committed Costs '!G:G) -> 0 | H26: =SUMIF('Change Orders'!F:F,'Project Detail'!B26,'Change Orders'!E:E) -> 0 | I26: =SUMIF(Invoices!B:B,B26,Invoices!G:G) -> 0 | J26: 0 | K26: =I26-J26 -> 0 | L26: =+M26-G26 -> 0 | M26: =IF((F26+H26)>G26,F26+H26,G26) -> 0 | N26: =F26-M26 -> 0
B27: 104-4 | F27: 0 | G27: =SUMIF('Committed Costs '!C:C,B27,'Committed Costs '!G:G) -> 0 | H27: =SUMIF('Change Orders'!F:F,'Project Detail'!B27,'Change Orders'!E:E) -> 0 | I27: =SUMIF(Invoices!B:B,B27,Invoices!G:G) -> 0 | J27: 0 | K27: =I27-J27 -> 0 | L27: =+M27-G27 -> 0 | M27: =IF((F27+H27)>G27,F27+H27,G27) -> 0 | N27: =F27-M27 -> 0 | Q27: =M27-K27 -> 0 | U27: =S27+T27 -> 0 | Z27: =W27+X27+Y27 -> 0 | AB27: =U27+Z27 -> 0 | AD27: =Q27-AB27 -> 0
C28: 104 | E28: Total | F28: =SUM(F24:F27) -> 0 | G28: =SUM(G24:G27) -> 0 | H28: =SUM(H24:H27) -> 0 | I28: =SUM(I24:I27) -> 0 | J28: =SUM(J24:J27) -> 0 | K28: =SUM(K24:K27) -> 0 | L28: =SUM(L24:L27) -> 0 | M28: =SUM(M24:M27) -> 0 | N28: =SUM(N24:N27) -> 0 | Q28: =Q27 -> 0 | S28: =S27 -> 0 | T28: =T27 -> 0 | U28: =U27 -> 0 | W28: =W27 -> 0 | X28: =X27 -> 0 | Y28: =Y27 -> 0 | Z28: =Z27 -> 0 | AB28: =AB27 -> 0 | AD28: =AD27 -> 0
E30: TOTAL BUILDING COSTS | F30: =SUM(F10,F16,F22,F28) -> 63651265 | G30: =SUM(G10,G16,G22,G28) -> 0 | H30: =SUM(H10,H16,H22,H28) -> 0 | I30: =SUM(I10,I16,I22,I28) -> 0 | J30: =SUM(J10,J16,J22,J28) -> 0 | K30: =SUM(K10,K16,K22,K28) -> 0 | L30: =SUM(L10,L16,L22,L28) -> 63651265 | M30: =SUM(M10,M16,M22,M28) -> 63651265 | N30: =SUM(N10,N16,N22,N28) -> 0 | Q30: =SUM(Q10,Q16,Q22,Q28) -> 0 | S30: =SUM(S10,S16,S22,S28) -> 0 | T30: =SUM(T10,T16,T22,T28) -> 0 | U30: =SUM(U10,U16,U22,U28) -> 0 | W30: =SUM(W10,W16,W22,W28) -> 0 | X30: =SUM(X10,X16,X22,X28) -> 0 | Y30: =SUM(Y10,Y16,Y22,Y28) -> 0 | Z30: =SUM(Z10,Z16,Z22,Z28) -> 0 | AB30: =SUM(AB10,AB16,AB22,AB28) -> 0 | AD30: =SUM(AD10,AD16,AD22,AD28) -> 0
B33: 200 | D33: Soft Costs
B34: 201 | D34: Project Management
B35: 201-1 | D35: LNE | E35: Project Management | F35: ='Budget Summary'!D45 -> 520000 | G35: =SUMIF('Committed Costs '!C:C,B35,'Committed Costs '!G:G) -> 0 | H35: =SUMIF('Change Orders'!F:F,'Project Detail'!B35,'Change Orders'!E:E) -> 0 | I35: =SUMIF(Invoices!B:B,B35,Invoices!G:G) -> 0 | J35: 0 | K35: =I35-J35 -> 0 | L35: =+M35-G35 -> 0 | M35: =G35 -> 0 | N35: =F35-M35 -> 520000 | Q35: =M35-K35 -> 0 | U35: =S35+T35 -> 0 | Z35: =W35+X35+Y35 -> 0 | AB35: =U35+Z35 -> 0 | AD35: =Q35-AB35 -> 0
B36: 201-2 | D36: TBD | E36: Project Management (3rd Party) | F36: ='Budget Summary'!#REF! -> #REF! | G36: =SUMIF('Committed Costs '!C:C,B36,'Committed Costs '!G:G) -> 0 | H36: =SUMIF('Change Orders'!F:F,'Project Detail'!B36,'Change Orders'!E:E) -> 0 | I36: =SUMIF(Invoices!B:B,B36,Invoices!G:G) -> 0 | J36: 0 | K36: =I36-J36 -> 0 | L36: =+M36-G36 -> #REF! | M36: =IF((F36+H36)>G36,F36+H36,G36) -> #REF! | N36: =F36-M36 -> #REF!
B37: 201-3 | F37: 0 | G37: =SUMIF('Committed Costs '!C:C,B37,'Committed Costs '!G:G) -> 0 | H37: =SUMIF('Change Orders'!F:F,'Project Detail'!B37,'Change Orders'!E:E) -> 0 | I37: =SUMIF(Invoices!B:B,B37,Invoices!G:G) -> 0 | J37: 0 | K37: =I37-J37 -> 0 | L37: =+M37-G37 -> 0 | M37: =IF((F37+H37)>G37,F37+H37,G37) -> 0 | N37: =F37-M37 -> 0
B38: 201-4 | F38: 0 | G38: =SUMIF('Committed Costs '!C:C,B38,'Committed Costs '!G:G) -> 0 | H38: =SUMIF('Change Orders'!F:F,'Project Detail'!B38,'Change Orders'!E:E) -> 0 | I38: =SUMIF(Invoices!B:B,B38,Invoices!G:G) -> 0 | J38: 0 | K38: =I38-J38 -> 0 | L38: =+M38-G38 -> 0 | M38: =IF((F38+H38)>G38,F38+H38,G38) -> 0 | N38: =F38-M38 -> 0
C39: 201 | E39: Total Project Management | F39: =SUM(F35:F38) -> #REF! | G39: =SUM(G35:G38) -> 0 | H39: =SUM(H35:H38) -> 0 | I39: =SUM(I35:I38) -> 0 | J39: =SUM(J35:J38) -> 0 | K39: =SUM(K35:K38) -> 0 | L39: =SUM(L35:L38) -> #REF! | M39: =SUM(M35:M38) -> #REF! | N39: =SUM(N35:N38) -> #REF! | Q39: =Q35 -> 0 | S39: =S35 -> 0 | T39: =T35 -> 0 | U39: =U35 -> 0 | W39: =W35 -> 0 | X39: =X35 -> 0 | Y39: =Y35 -> 0 | Z39: =Z35 -> 0 | AB39: =AB35 -> 0 | AD39: =AD35 -> 0
B40: 202 | D40: Architectural Fees
B41: 202-1 | D41: TBD | E41: Architectural Fees | F41: ='Budget Summary'!D35 -> 3526000 | G41: =SUMIF('Committed Costs '!C:C,B41,'Committed Costs '!G:G) -> 0 | H41: =SUMIF('Change Orders'!F:F,'Project Detail'!B41,'Change Orders'!E:E) -> 0 | I41: =SUMIF(Invoices!B:B,B41,Invoices!G:G) -> 0 | J41: 0 | K41: =I41-J41 -> 0 | L41: =+M41-G41 -> 0 | M41: =G41 -> 0 | N41: =F41-M41 -> 3526000 | Q41: =M41-K41 -> 0 | U41: =S41+T41 -> 0 | Z41: =W41+X41+Y41 -> 0 | AB41: =U41+Z41 -> 0 | AD41: =Q41-AB41 -> 0
B42: 202-2 | F42: 0 | G42: =SUMIF('Committed Costs '!C:C,B42,'Committed Costs '!G:G) -> 0 | H42: =SUMIF('Change Orders'!F:F,'Project Detail'!B42,'Change Orders'!E:E) -> 0 | I42: =SUMIF(Invoices!B:B,B42,Invoices!G:G) -> 0 | J42: 0 | K42: =I42-J42 -> 0 | L42: =+M42-G42 -> 0 | M42: =IF((F42+H42)>G42,F42+H42,G42) -> 0 | N42: =F42-M42 -> 0 | Q42: =M42-K42 -> 0 | U42: =S42+T42 -> 0 | Z42: =W42+X42+Y42 -> 0 | AB42: =U42+Z42 -> 0 | AD42: =Q42-AB42 -> 0
B43: 202-3 | F43: 0 | G43: =SUMIF('Committed Costs '!C:C,B43,'Committed Costs '!G:G) -> 0 | H43: =SUMIF('Change Orders'!F:F,'Project Detail'!B43,'Change Orders'!E:E) -> 0 | I43: =SUMIF(Invoices!B:B,B43,Invoices!G:G) -> 0 | J43: 0 | K43: =I43-J43 -> 0 | L43: =+M43-G43 -> 0 | M43: 0 | N43: =F43-M43 -> 0 | Q43: =M43-K43 -> 0 | U43: =S43+T43 -> 0 | Z43: =W43+X43+Y43 -> 0 | AB43: =U43+Z43 -> 0 | AD43: =Q43-AB43 -> 0
B44: 202-4 | F44: 0 | G44: =SUMIF('Committed Costs '!C:C,B44,'Committed Costs '!G:G) -> 0 | H44: =SUMIF('Change Orders'!F:F,'Project Detail'!B44,'Change Orders'!E:E) -> 0 | I44: =SUMIF(Invoices!B:B,B44,Invoices!G:G) -> 0 | J44: 0 | K44: =I44-J44 -> 0 | L44: =+M44-G44 -> 0 | M44: =IF((F44+H44)>G44,F44+H44,G44) -> 0 | N44: =F44-M44 -> 0
C45: 202 | E45: Total Architectural Fees | F45: =SUM(F41:F44) -> 3526000 | G45: =SUM(G41:G44) -> 0 | H45: =SUM(H41:H44) -> 0 | I45: =SUM(I41:I44) -> 0 | J45: =SUM(J41:J44) -> 0 | K45: =SUM(K41:K44) -> 0 | L45: =SUM(L41:L44) -> 0 | M45: =SUM(M41:M44) -> 0 | N45: =SUM(N41:N44) -> 3526000 | Q45: =SUM(Q41:Q43) -> 0 | S45: =SUM(S41:S43) -> 0 | T45: =SUM(T41:T43) -> 0 | U45: =SUM(U41:U43) -> 0 | W45: =SUM(W41:W43) -> 0 | X45: =SUM(X41:X43) -> 0 | Y45: =SUM(Y41:Y43) -> 0 | Z45: =SUM(Z41:Z43) -> 0 | AB45: =SUM(AB41:AB43) -> 0 | AD45: =SUM(AD41:AD43) -> 0
...

Sheet Committed Costs 
B2: Committed Costs
B3: Executed Date | C3: Cost Code | D3: Vendor | E3: Description | F3: P.O. Number | G3: Contract Value | H3: Notes
F9: Total Commitments | G9: =SUBTOTAL(9,G4:G6) -> 0
G10: =G9='Project At-a-Glance'!D25 -> TRUE

Sheet Invoices
B2: Invoices
B3: Cost Code | C3: Vendor | D3: Description | E3: Invoice # | F3: Invoice Date | G3: Invoice Amount | H3: GL Period | I3: Notes | J3: Payment Status
B5: 2022 Invoices
F10: March Invoices Total | G10: =SUBTOTAL(9,G6:G9) -> 0
F13: INVOICES GRAND TOTAL | G13: =SUM(G10) -> 0
G14: =G13='Project At-a-Glance'!E25 -> TRUE

Sheet Change Orders
B2: Date Issued | C2: C.O. Number | D2: Vendor | E2: Amount | F2: Cost Code | G2: Description | H2: Notes
D29: Total Change Orders | E29: =SUM(E3:E28) -> 0

Sheet Contingency
B2: Date | C2: Cost Code | D2: Vendor | E2: Description | F2: Amount Applied | G2: Remaining Balance | H2: Notes
B4: March 2020 Contingency | J4: Contingency
B5: 43921 | C5: N/A | D5: N/A | E5: Initial Contingency Amount | F5: 0 | G5: =+J5-F5 -> 8098599.2 | J5: ='Project Detail'!F170 -> 8098599.2
E6: March Contingency Totals | F6: =SUBTOTAL(9,F5) -> 0 | G6: =G5 -> 8098599.2
E9: CONTINGENCY TOTALS | F9: =SUM(F6) -> 0 | G9: =G6 -> 8098599.2

Sheet Risk Report
A1: Risk Report
A3: Requestor | C3: Item | E3: High | G3: Expected Settlement Value | I3: Low | K3: Notes
A4: Project Team
A5: Project Team
A6: Project Team
A7: Project Team
A8: Project Team
A9: Project Team
A10: Project Team
A11: Project Team
A12: Project Team
A13: Project Team
A14: Project Team
E15: =SUM(E4:E14) -> 0 | G15: =SUM(G4:G14) -> 0 | I15: =SUM(I4:I14) -> 0
C19: Current Sources (as of 01/31/2023) | E19: Remaining Contingency | G19: =Contingency!G9 -> 8098599.2
E21: Contingency Balance | G21: =G19-G15 -> 8098599.2
E23: Exposure | G23: =IF(G15>G19,G19-G15,0) -> 0
C26: *Sources reflect over budget items pending resolution.
